Workbook

Sheet Instructions 
B2: Instructions to be followed to complete the Data Collection Template
B3: This form is intended to be filled out by each farmer involved in the Test Case (TC) and aims at collecting information that will be used for assessing the impacts of Digital agriculture technology solutions (DATSs). Please read carefully the following instructions. - We kindly ask you to be as accurate as possible in providing the data and monitor them periodically as these will be the input for performance assessment. - Please ensure you keep track of the data requested and regularly check its availability. It's crucial that these values align for both user and non-user parcels. If they differ, kindly notify us promptly via email at the provided contact details. - The data included in the template have been carefully chosen based on their link with the DATSs used in your TC and they were further customised following your feedback. If some of the data cannot be applicable/available to your TC, please enter ‘n.a.’ in the corresponding cell and provide a comment explaining why they are not applicable. Additionally, in case some of the data cannot be collected due to some problems you may encounter during the season, please inform us promptly by writing an e-mail to the contact details provided below. - In order to obtain the assessment of the impacts of DATS, it is necessary to provide data for the farm(s) using DATS and for the one without. According to the QuantiFarm project proposal, each parcel using DATSs is associated with a comparable non-DATs parcel (in terms of size, geographical area, production, etc.). - Recall that: - the term DATS refers to the combinations or set of technological solutions implemented within the TC; For any doubts or clarifications, please do not hesitate to contact us at the following email address: francesco.parigi@polimi.it and andrea.bianchi@polimi.it (cc: dmoniz@consulai.com) This form is intended to be filled out by each farmer involved in the Test Case (TC) and aims at collecting information that will be used for assessing the impacts of Digital agriculture technology solutions (DATSs).
B5: Table of abbreviations
B6: - | C6: number (1, 2, 3, …)
B7: € | C7: euro
B8: cm3 | C8: cubic centimetre
B9: dm3 | C9: cubic decimetre
B10: g | C10: grams
B11: h | C11: hour
B12: ha | C12: hectare
B13: K | C13: potassium
B14: k€ | C14: kiloeuro (€ 1,000)
B15: kg | C15: kilograms
B16: kWh | C16: kilowatt-hour
B17: l | C17: litre
... B27: y | C27: year

Sheet General Information
B2: Question | C2: Unit of measure | D2: Value
A3: parcelInformation | B3: TC Number | C3: n | D3: 6 | E3: testcaseNumber | N3: D3 | O3: =CONCATENATE("""",N3,"""",":","""",LOWER(A3),"_",LOWER(E3),"""") -> "D3":"parcelinformation_testcasenumber"
A4: parcelInformation | B4: TC Leader | C4: - | E4: testcaseLeader | N4: D4 | O4: =CONCATENATE("""",N4,"""",":","""",LOWER(A4),"_",LOWER(E4),"""") -> "D4":"parcelinformation_testcaseleader"
B5: FARM DATA | N5: D5 | O5: =CONCATENATE("""",N5,"""",":","""",LOWER(A5),"_",LOWER(E5),"""") -> "D5":"_"
A6: parcelInformation | B6: Type of output/product | C6: - | D6: Crop | E6: cultivationType | N6: D6 | O6: =CONCATENATE("""",N6,"""",":","""",LOWER(A6),"_",LOWER(E6),"""") -> "D6":"parcelinformation_cultivationtype"
A7: parcelInformation | B7: Crop | C7: - | D7: Onion | E7: productType | N7: D7 | O7: =CONCATENATE("""",N7,"""",":","""",LOWER(A7),"_",LOWER(E7),"""") -> "D7":"parcelinformation_producttype"
A8: parcelInformation | B8: Animal | E8: productType | N8: D8 | O8: =CONCATENATE("""",N8,"""",":","""",LOWER(A8),"_",LOWER(E8),"""") -> "D8":"parcelinformation_producttype"
A9: parcelInformation | B9: Start of the growing/production season | C9: (gg/mm/yyyy) | E9: startMonth | N9: D9 | O9: =CONCATENATE("""",N9,"""",":","""",LOWER(A9),"_",LOWER(E9),"""") -> "D9":"parcelinformation_startmonth"
A10: parcelInformation | B10: End of the growing/production season | C10: (gg/mm/yyyy) | E10: endMonth | N10: D10 | O10: =CONCATENATE("""",N10,"""",":","""",LOWER(A10),"_",LOWER(E10),"""") -> "D10":"parcelinformation_endmonth"
A11: parcelInformation | B11: Biogeographical region | C11: - | E11: biogeographicalRegion | N11: D11 | O11: =CONCATENATE("""",N11,"""",":","""",LOWER(A11),"_",LOWER(E11),"""") -> "D11":"parcelinformation_biogeographicalregion"
A12: parcelInformation | B12: Total farm size | C12: ha | E12: totalFarmSize | N12: D12 | O12: =CONCATENATE("""",N12,"""",":","""",LOWER(A12),"_",LOWER(E12),"""") -> "D12":"parcelinformation_totalfarmsize"
A13: parcelInformation | B13: Number of comparison(s) | C13: n | E13: numberOfComparisons | N13: D13 | O13: =CONCATENATE("""",N13,"""",":","""",LOWER(A13),"_",LOWER(E13),"""") -> "D13":"parcelinformation_numberofcomparisons"
A14: parcelInformation | B14: Number of employees | C14: n | E14: numberOfEmployees | N14: D14 | O14: =CONCATENATE("""",N14,"""",":","""",LOWER(A14),"_",LOWER(E14),"""") -> "D14":"parcelinformation_numberofemployees"
A15: parcelInformation | B15: Number of full-time employees | C15: n | E15: numberofFullTimeEmployees | N15: D15 | O15: =CONCATENATE("""",N15,"""",":","""",LOWER(A15),"_",LOWER(E15),"""") -> "D15":"parcelinformation_numberoffulltimeemployees"
A16: parcelInformation | B16: Number of seasonal employees | C16: n | E16: numberOfSeasonalEmployees | N16: D16 | O16: =CONCATENATE("""",N16,"""",":","""",LOWER(A16),"_",LOWER(E16),"""") -> "D16":"parcelinformation_numberofseasonalemployees"
N17: D17 | O17: =CONCATENATE("""",N17,"""",":","""",LOWER(A17),"_",LOWER(E17),"""") -> "D17":"_"
B18: DATSs 1 DATA | G18: DATSs 2 DATA | K18: DATSs n DATA | N18: D18 | O18: =CONCATENATE("""",N18,"""",":","""",LOWER(A18),"_",LOWER(E18),"""") -> "D18":"_"
B19: Question | C19: Unit of measure | D19: Value | G19: Question | H19: Unit of measure | I19: Value | K19: Question | L19: Unit of measure | M19: Value | N19: D19 | O19: =CONCATENATE("""",N19,"""",":","""",LOWER(A19),"_",LOWER(E19),"""") -> "D19":"_"
A20: datsInformation | B20: Initial investment for DATSs | C20: € | D20: 0 | E20: datsInitialInvestmentCosts | G20: Initial investment for DATSs | H20: € | K20: Initial investment for DATSs | L20: € | N20: D20 | O20: =CONCATENATE("""",N20,"""",":","""",LOWER(A20),"_",LOWER(E20),"""") -> "D20":"datsinformation_datsinitialinvestmentcosts"
A21: datsInformation | B21: Expected life span of each DATSs | C21: y | D21: 1 | E21: datsExpectedLifespan | G21: Expected life span of each DATSs | H21: y | K21: Expected life span of each DATSs | L21: y | N21: D21 | O21: =CONCATENATE("""",N21,"""",":","""",LOWER(A21),"_",LOWER(E21),"""") -> "D21":"datsinformation_datsexpectedlifespan"
A22: datsInformation | B22: Time to install and make DATSs operational | C22: h | D22: 1 | E22: datsInstallationTime | G22: Time to install and make DATSs operational | H22: h | K22: Time to install and make DATSs operational | L22: h | N22: D22 | O22: =CONCATENATE("""",N22,"""",":","""",LOWER(A22),"_",LOWER(E22),"""") -> "D22":"datsinformation_datsinstallationtime"
A23: datsInformation | B23: DATs maintenance costs | C23: €/y | D23: 0 | E23: datsMaintenanceCosts | G23: DATs maintenance costs | H23: €/y | K23: DATs maintenance costs | L23: €/y | N23: D23 | O23: =CONCATENATE("""",N23,"""",":","""",LOWER(A23),"_",LOWER(E23),"""") -> "D23":"datsinformation_datsmaintenancecosts"
A24: datsInformation | B24: DATS annual fees | C24: €/y | D24: 300 | E24: datsAnnualFees | G24: DATS annual fees | H24: €/y | K24: DATS annual fees | L24: €/y | N24: D24 | O24: =CONCATENATE("""",N24,"""",":","""",LOWER(A24),"_",LOWER(E24),"""") -> "D24":"datsinformation_datsannualfees"
A25: datsInformation | B25: Training hours for the use of the DATSs in a year | C25: h | D25: 2 | E25: datsTrainingTime | G25: Training hours for the use of the DATSs in a year | H25: h | K25: Training hours for the use of the DATSs in a year | L25: h | N25: D25 | O25: =CONCATENATE("""",N25,"""",":","""",LOWER(A25),"_",LOWER(E25),"""") -> "D25":"datsinformation_datstrainingtime"
A26: datsInformation | B26: Number of people involved in the training | C26: n | D26: 2 | E26: datsTrainers | G26: Number of people involved in the training | H26: n | K26: Number of people involved in the training | L26: n | N26: D26 | O26: =CONCATENATE("""",N26,"""",":","""",LOWER(A26),"_",LOWER(E26),"""") -> "D26":"datsinformation_datstrainers"
A27: datsInformation | B27: Cost of training service by external people (advisor, DATS providers, ...) | C27: €/y | D27: 0 | E27: datsTrainingCosts | G27: Cost of training service by external people (advisor, DATS providers, ...) | H27: €/y | K27: Cost of training service by external people (advisor, DATS providers, ...) | L27: €/y | N27: D27 | O27: =CONCATENATE("""",N27,"""",":","""",LOWER(A27),"_",LOWER(E27),"""") -> "D27":"datsinformation_datstrainingcosts"
A28: datsInformation | B28: DATSs name | C28: - | D28: QMS Water Software | E28: datsName | G28: DATSs name | H28: - | K28: DATSs name | L28: - | N28: D28 | O28: =CONCATENATE("""",N28,"""",":","""",LOWER(A28),"_",LOWER(E28),"""") -> "D28":"datsinformation_datsname"
N29: D29 | O29: =CONCATENATE("""",N29,"""",":","""",LOWER(A29),"_",LOWER(E29),"""") -> "D29":"_"
B30: MARKET DATA FOR DATSs USER | G30: MARKET DATA FOR NON-DATSs USER | N30: D30 | O30: =CONCATENATE("""",N30,"""",":","""",LOWER(A30),"_",LOWER(E30),"""") -> "D30":"_"
B31: Question | C31: Unit of measure | D31: Value | G31: Question | H31: Unit of measure | I31: Value | N31: D31 | O31: =CONCATENATE("""",N31,"""",":","""",LOWER(A31),"_",LOWER(E31),"""") -> "D31":"_"
A32: marketinformation | B32: Water price | C32: €/m3 | D32: 0 | E32: waterPrice | G32: Water price | H32: €/m3 | I32: 0 | N32: D32 | O32: =CONCATENATE("""",N32,"""",":","""",LOWER(A32),"_",LOWER(E32),"""") -> "D32":"marketinformation_waterprice"
A33: marketinformation | B33: Fuel price | C33: €/l | D33: 1.18 | E33: fuelPrice | G33: Fuel price | H33: €/l | I33: 1.18 | N33: D33 | O33: =CONCATENATE("""",N33,"""",":","""",LOWER(A33),"_",LOWER(E33),"""") -> "D33":"marketinformation_fuelprice"
A34: marketinformation | B34: Number of fuel for greehnouse temperature control price | C34: n | E34: n_fuel_for_greenhouse | G34: Number of fuel for greehnouse temperature control price | H34: n | N34: D34 | O34: =CONCATENATE("""",N34,"""",":","""",LOWER(A34),"_",LOWER(E34),"""") -> "D34":"marketinformation_n_fuel_for_greenhouse"
A35: fuelfortemperaturecontrolinformation | B35: Fuel 1 for greehnouse temperature control price | C35: €/m3 | E35: productPrice_0 | G35: Fuel 1 for greehnouse temperature control price | H35: €/m3 | N35: D35 | O35: =CONCATENATE("""",N35,"""",":","""",LOWER(A35),"_",LOWER(E35),"""") -> "D35":"fuelfortemperaturecontrolinformation_productprice_0"
A36: fuelfortemperaturecontrolinformation | B36: Fuel 2 for greehnouse temperature control price | C36: €/m3 | E36: productPrice_1 | G36: Fuel 2 for greehnouse temperature control price | H36: €/m3 | N36: D36 | O36: =CONCATENATE("""",N36,"""",":","""",LOWER(A36),"_",LOWER(E36),"""") -> "D36":"fuelfortemperaturecontrolinformation_productprice_1"
A37: fuelfortemperaturecontrolinformation | B37: Fuel 3 for greehnouse temperature control price | C37: €/m3 | E37: productPrice_2 | G37: Fuel 3 for greehnouse temperature control price | H37: €/m4 | N37: D37 | O37: =CONCATENATE("""",N37,"""",":","""",LOWER(A37),"_",LOWER(E37),"""") -> "D37":"fuelfortemperaturecontrolinformation_productprice_2"
A38: marketinformation | B38: Electricity price | C38: €/kWh | D38: 0.15 | E38: electricityPrice | G38: Electricity price | H38: €/kWh | I38: 0.15 | N38: D38 | O38: =CONCATENATE("""",N38,"""",":","""",LOWER(A38),"_",LOWER(E38),"""") -> "D38":"marketinformation_electricityprice"
A39: marketinformation | B39: Average salary (farmer and emloyees) | C39: €/h | D39: 50 | E39: averageSalary | G39: Average salary (farmer and emloyees) | H39: €/h | I39: 50 | N39: D39 | O39: =CONCATENATE("""",N39,"""",":","""",LOWER(A39),"_",LOWER(E39),"""") -> "D39":"marketinformation_averagesalary"
A40: marketinformation | B40: Average professional salary (agronomist, veterinary, ...) | C40: €/h | D40: 100 | E40: averageProfessionalSalary | G40: Average professional salary (agronomist, veterinary, ...) | H40: €/h | I40: 100 | N40: D40 | O40: =CONCATENATE("""",N40,"""",":","""",LOWER(A40),"_",LOWER(E40),"""") -> "D40":"marketinformation_averageprofessionalsalary"
A41: marketinformation | B41: Sold product market price | C41: €/t | D41: 170 | E41: productMarketPrice | G41: Sold product market price | H41: €/t | I41: 170 | N41: D41 | O41: =CONCATENATE("""",N41,"""",":","""",LOWER(A41),"_",LOWER(E41),"""") -> "D41":"marketinformation_productmarketprice"
...

Sheet Parcel 1 with DATSs
AG1: yes
G2: PARCEL WITH DATSs | AG2: no
C4: Identification | D4: Parcel Name | E4: Onions - DAT
B8: Information about the TC
B9: # | C9: data | D9: u.m. | E9: value | G9: Notes
A10: parcelInformation | B10: 1 | C10: Parcel dimension | D10: ha | E10: parcelDimension | F10: G10 | G10: 4.1 | J10: =CONCATENATE("""",F10,"""",":","""","parcelassessmentwithdats_",LOWER($A10),"_",LOWER($E10),"""") -> "G10":"parcelassessmentwithdats_parcelinformation_parceldimension"
A11: parcelInformation | B11: 2 | C11: Number of plants/trees | D11: n | E11: numberOfPlants | F11: G11 | J11: =CONCATENATE("""",F11,"""",":","""","parcelassessmentwithdats_",LOWER($A11),"_",LOWER($E11),"""") -> "G11":"parcelassessmentwithdats_parcelinformation_numberofplants"
A12: parcelInformation | B12: 3 | C12: Sand content in the soil | D12: % | E12: soilFractionSand | F12: G12 | G12: 37 | J12: =CONCATENATE("""",F12,"""",":","""","parcelassessmentwithdats_",LOWER($A12),"_",LOWER($E12),"""") -> "G12":"parcelassessmentwithdats_parcelinformation_soilfractionsand"
A13: parcelInformation | B13: 4 | C13: Clay content in the soil | D13: % | E13: soilFractionClay | F13: G13 | G13: 22 | J13: =CONCATENATE("""",F13,"""",":","""","parcelassessmentwithdats_",LOWER($A13),"_",LOWER($E13),"""") -> "G13":"parcelassessmentwithdats_parcelinformation_soilfractionclay"
A14: parcelInformation | B14: 5 | C14: Silt content in the soil | D14: % | E14: soilFractionSilt | F14: G14 | G14: 31 | J14: =CONCATENATE("""",F14,"""",":","""","parcelassessmentwithdats_",LOWER($A14),"_",LOWER($E14),"""") -> "G14":"parcelassessmentwithdats_parcelinformation_soilfractionsilt"
A15: parcelInformation | B15: 6 | C15: Soil Bulk Density | D15: g/cm3 | E15: bulkDensity | F15: G15 | J15: =CONCATENATE("""",F15,"""",":","""","parcelassessmentwithdats_",LOWER($A15),"_",LOWER($E15),"""") -> "G15":"parcelassessmentwithdats_parcelinformation_bulkdensity"
A16: parcelInformation | B16: 7 | C16: Soil Organic Carbon | D16: % | E16: soilOrganicCarbon | F16: G16 | G16: 1 | J16: =CONCATENATE("""",F16,"""",":","""","parcelassessmentwithdats_",LOWER($A16),"_",LOWER($E16),"""") -> "G16":"parcelassessmentwithdats_parcelinformation_soilorganiccarbon"
A17: parcelInformation | B17: 8 | C17: Number of animals | D17: n | E17: numberOfAnimals | F17: G17 | J17: =CONCATENATE("""",F17,"""",":","""","parcelassessmentwithdats_",LOWER($A17),"_",LOWER($E17),"""") -> "G17":"parcelassessmentwithdats_parcelinformation_numberofanimals"
A18: parcelInformation | B18: 9 | C18: Livestock units per hectare | D18: LSU/ha | E18: livestockUnits | F18: G18 | J18: =CONCATENATE("""",F18,"""",":","""","parcelassessmentwithdats_",LOWER($A18),"_",LOWER($E18),"""") -> "G18":"parcelassessmentwithdats_parcelinformation_livestockunits"
A19: parcelInformation | B19: 10 | C19: Number of beehives | D19: n | E19: numberOfBeehives | F19: G19 | J19: =CONCATENATE("""",F19,"""",":","""","parcelassessmentwithdats_",LOWER($A19),"_",LOWER($E19),"""") -> "G19":"parcelassessmentwithdats_parcelinformation_numberofbeehives"
A20: parcelInformation | B20: 11 | C20: Area under aquaculture | D20: m2 | E20: aquacultureArea | F20: G20 | J20: =CONCATENATE("""",F20,"""",":","""","parcelassessmentwithdats_",LOWER($A20),"_",LOWER($E20),"""") -> "G20":"parcelassessmentwithdats_parcelinformation_aquaculturearea"
F21: G21 | J21: =CONCATENATE("""",F21,"""",":","""","parcelassessmentwithdats_",LOWER($A21),"_",LOWER($E21),"""") -> "G21":"parcelassessmentwithdats__"
B22: WATER | F22: G22 | G22: Year 1 | J22: =CONCATENATE("""",F22,"""",":","""","parcelassessmentwithdats_",LOWER($A22),"_",LOWER($E22),"""") -> "G22":"parcelassessmentwithdats__"
B23: # | C23: data | D23: u.m. | F23: G23 | G23: With DATSs | H23: Notes | J23: =CONCATENATE("""",F23,"""",":","""","parcelassessmentwithdats_",LOWER($A23),"_",LOWER($E23),"""") -> "G23":"parcelassessmentwithdats__"
A24: waterUsageInformation | B24: 12 | C24: Irrigation | D24: m3 | E24: waterUsageForIrrigation | F24: G24 | G24: 936 | J24: =CONCATENATE("""",F24,"""",":","""","parcelassessmentwithdats_",LOWER($A24),"_",LOWER($E24),"""") -> "G24":"parcelassessmentwithdats_waterusageinformation_waterusageforirrigation"
A25: waterUsageInformation | B25: 13 | C25: Fertigation | D25: m3 | E25: waterUsageForFertigation | F25: G25 | G25: 370 | J25: =CONCATENATE("""",F25,"""",":","""","parcelassessmentwithdats_",LOWER($A25),"_",LOWER($E25),"""") -> "G25":"parcelassessmentwithdats_waterusageinformation_waterusageforfertigation"
A26: waterUsageInformation | B26: 14 | C26: Pest dilution | D26: m3 | E26: waterUsageForPestDilution | F26: G26 | J26: =CONCATENATE("""",F26,"""",":","""","parcelassessmentwithdats_",LOWER($A26),"_",LOWER($E26),"""") -> "G26":"parcelassessmentwithdats_waterusageinformation_waterusageforpestdilution"
A27: waterUsageInformation | B27: 15 | C27: Cleaning | D27: m3 | E27: waterUsageForCleaning | F27: G27 | J27: =CONCATENATE("""",F27,"""",":","""","parcelassessmentwithdats_",LOWER($A27),"_",LOWER($E27),"""") -> "G27":"parcelassessmentwithdats_waterusageinformation_waterusageforcleaning"
A28: waterUsageInformation | B28: 16 | C28: Drinking | D28: m3 | E28: waterUsageForDrinking | F28: G28 | J28: =CONCATENATE("""",F28,"""",":","""","parcelassessmentwithdats_",LOWER($A28),"_",LOWER($E28),"""") -> "G28":"parcelassessmentwithdats_waterusageinformation_waterusagefordrinking"
A29: waterUsageInformation | B29: 17 | C29: Total water used | D29: m3 | E29: totalWaterUsage | F29: G29 | G29: 1306 | J29: =CONCATENATE("""",F29,"""",":","""","parcelassessmentwithdats_",LOWER($A29),"_",LOWER($E29),"""") -> "G29":"parcelassessmentwithdats_waterusageinformation_totalwaterusage"
F30: G30 | J30: =CONCATENATE("""",F30,"""",":","""","parcelassessmentwithdats_",LOWER($A30),"_",LOWER($E30),"""") -> "G30":"parcelassessmentwithdats__"
B31: FUEL | F31: G31 | G31: Year 1 | J31: =CONCATENATE("""",F31,"""",":","""","parcelassessmentwithdats_",LOWER($A31),"_",LOWER($E31),"""") -> "G31":"parcelassessmentwithdats__"
B32: # | C32: data | D32: u.m. | F32: G32 | G32: With DATSs | H32: Notes | J32: =CONCATENATE("""",F32,"""",":","""","parcelassessmentwithdats_",LOWER($A32),"_",LOWER($E32),"""") -> "G32":"parcelassessmentwithdats__"
A33: fuelUsageInformation | B33: 18 | C33: Fertilisation | D33: l | E33: fuelUsageForFertilisation | F33: G33 | J33: =CONCATENATE("""",F33,"""",":","""","parcelassessmentwithdats_",LOWER($A33),"_",LOWER($E33),"""") -> "G33":"parcelassessmentwithdats_fuelusageinformation_fuelusageforfertilisation"
A34: fuelUsageInformation | B34: 19 | C34: Pesticides | D34: l | E34: fuelUsageForPesticides | F34: G34 | J34: =CONCATENATE("""",F34,"""",":","""","parcelassessmentwithdats_",LOWER($A34),"_",LOWER($E34),"""") -> "G34":"parcelassessmentwithdats_fuelusageinformation_fuelusageforpesticides"
A35: fuelUsageInformation | B35: 20 | C35: Irrigation | D35: l | E35: fuelUsageForIrrigation | F35: G35 | J35: =CONCATENATE("""",F35,"""",":","""","parcelassessmentwithdats_",LOWER($A35),"_",LOWER($E35),"""") -> "G35":"parcelassessmentwithdats_fuelusageinformation_fuelusageforirrigation"
A36: fuelUsageInformation | B36: 21 | C36: Sowing / Planting | D36: l | E36: fuelUsageForSowing | F36: G36 | J36: =CONCATENATE("""",F36,"""",":","""","parcelassessmentwithdats_",LOWER($A36),"_",LOWER($E36),"""") -> "G36":"parcelassessmentwithdats_fuelusageinformation_fuelusageforsowing"
A37: fuelUsageInformation | B37: 22 | C37: Temperature and Humidity Control | D37: l | E37: fuelUsageForPruning | F37: G37 | J37: =CONCATENATE("""",F37,"""",":","""","parcelassessmentwithdats_",LOWER($A37),"_",LOWER($E37),"""") -> "G37":"parcelassessmentwithdats_fuelusageinformation_fuelusageforpruning"
A38: fuelUsageInformation | B38: 23 | C38: Pruning | D38: l | E38: fuelUsageForTemperatureHumidityControl | F38: G38 | J38: =CONCATENATE("""",F38,"""",":","""","parcelassessmentwithdats_",LOWER($A38),"_",LOWER($E38),"""") -> "G38":"parcelassessmentwithdats_fuelusageinformation_fuelusagefortemperaturehumiditycontrol"
A39: fuelUsageInformation | B39: 24 | C39: Beehives visits | D39: l | E39: fuelUsageForBeehivesVisits | F39: G39 | J39: =CONCATENATE("""",F39,"""",":","""","parcelassessmentwithdats_",LOWER($A39),"_",LOWER($E39),"""") -> "G39":"parcelassessmentwithdats_fuelusageinformation_fuelusageforbeehivesvisits"
A40: fuelUsageInformation | B40: 25 | C40: Transporting oysters to the laboratory | D40: l | E40: fuelUsageForTransportingOysters | F40: G40 | J40: =CONCATENATE("""",F40,"""",":","""","parcelassessmentwithdats_",LOWER($A40),"_",LOWER($E40),"""") -> "G40":"parcelassessmentwithdats_fuelusageinformation_fuelusagefortransportingoysters"
A41: fuelUsageInformation | B41: 26 | C41: Milking | D41: l | E41: fuelUsageForMilking | F41: G41 | J41: =CONCATENATE("""",F41,"""",":","""","parcelassessmentwithdats_",LOWER($A41),"_",LOWER($E41),"""") -> "G41":"parcelassessmentwithdats_fuelusageinformation_fuelusageformilking"
A42: fuelUsageInformation | B42: 27 | C42: Feeding | D42: l | E42: fuelUsageForFeeding | F42: G42 | J42: =CONCATENATE("""",F42,"""",":","""","parcelassessmentwithdats_",LOWER($A42),"_",LOWER($E42),"""") -> "G42":"parcelassessmentwithdats_fuelusageinformation_fuelusageforfeeding"
A43: fuelUsageInformation | B43: 28 | C43: Total fuel used | D43: l | E43: totalFuelUsage | F43: G43 | G43: 0 | J43: =CONCATENATE("""",F43,"""",":","""","parcelassessmentwithdats_",LOWER($A43),"_",LOWER($E43),"""") -> "G43":"parcelassessmentwithdats_fuelusageinformation_totalfuelusage"
F44: G44 | J44: =CONCATENATE("""",F44,"""",":","""","parcelassessmentwithdats_",LOWER($A44),"_",LOWER($E44),"""") -> "G44":"parcelassessmentwithdats__"
...

Sheet Parcel 1 without DATSs
BA1: yes
H2: PARCEL WITHOUT DATSs | BA2: no
C4: Identification | D4: Parcel Name | E4: Onions - NO DAT
B8: Information about the TC
B9: # | C9: data | D9: u.m. | H9: Notes
A10: parcelInformation | B10: 1 | C10: Parcel dimension | D10: ha | E10: parcelDimension | F10: H10 | H10: 4.1 | K10: =CONCATENATE("""",F10,"""",":","""","parcelassessmentwithdats_",LOWER($A10),"_",LOWER($E10),"""") -> "H10":"parcelassessmentwithdats_parcelinformation_parceldimension"
A11: parcelInformation | B11: 2 | C11: Number of plants/trees | D11: n | E11: numberOfPlants | F11: H11 | K11: =CONCATENATE("""",F11,"""",":","""","parcelassessmentwithdats_",LOWER($A11),"_",LOWER($E11),"""") -> "H11":"parcelassessmentwithdats_parcelinformation_numberofplants"
A12: parcelInformation | B12: 3 | C12: Sand content in the soil | D12: % | E12: soilFractionSand | F12: H12 | H12: 37 | K12: =CONCATENATE("""",F12,"""",":","""","parcelassessmentwithdats_",LOWER($A12),"_",LOWER($E12),"""") -> "H12":"parcelassessmentwithdats_parcelinformation_soilfractionsand"
A13: parcelInformation | B13: 4 | C13: Clay content in the soil | D13: % | E13: soilFractionClay | F13: H13 | H13: 22 | K13: =CONCATENATE("""",F13,"""",":","""","parcelassessmentwithdats_",LOWER($A13),"_",LOWER($E13),"""") -> "H13":"parcelassessmentwithdats_parcelinformation_soilfractionclay"
A14: parcelInformation | B14: 5 | C14: Silt content in the soil | D14: % | E14: soilFractionSilt | F14: H14 | H14: 31 | K14: =CONCATENATE("""",F14,"""",":","""","parcelassessmentwithdats_",LOWER($A14),"_",LOWER($E14),"""") -> "H14":"parcelassessmentwithdats_parcelinformation_soilfractionsilt"
A15: parcelInformation | B15: 6 | C15: Soil Bulk Density | D15: g/cm3 | E15: bulkDensity | F15: H15 | K15: =CONCATENATE("""",F15,"""",":","""","parcelassessmentwithdats_",LOWER($A15),"_",LOWER($E15),"""") -> "H15":"parcelassessmentwithdats_parcelinformation_bulkdensity"
A16: parcelInformation | B16: 7 | C16: Soil Organic Carbon | D16: % | E16: soilOrganicCarbon | F16: H16 | H16: 1 | K16: =CONCATENATE("""",F16,"""",":","""","parcelassessmentwithdats_",LOWER($A16),"_",LOWER($E16),"""") -> "H16":"parcelassessmentwithdats_parcelinformation_soilorganiccarbon"
A17: parcelInformation | B17: 8 | C17: Number of animals | D17: n | E17: numberOfAnimals | F17: H17 | K17: =CONCATENATE("""",F17,"""",":","""","parcelassessmentwithdats_",LOWER($A17),"_",LOWER($E17),"""") -> "H17":"parcelassessmentwithdats_parcelinformation_numberofanimals"
A18: parcelInformation | B18: 9 | C18: Livestock units per hectare | D18: LSU/ha | E18: livestockUnits | F18: H18 | K18: =CONCATENATE("""",F18,"""",":","""","parcelassessmentwithdats_",LOWER($A18),"_",LOWER($E18),"""") -> "H18":"parcelassessmentwithdats_parcelinformation_livestockunits"
A19: parcelInformation | B19: 10 | C19: Number of beehives | D19: n | E19: numberOfBeehives | F19: H19 | K19: =CONCATENATE("""",F19,"""",":","""","parcelassessmentwithdats_",LOWER($A19),"_",LOWER($E19),"""") -> "H19":"parcelassessmentwithdats_parcelinformation_numberofbeehives"
A20: parcelInformation | B20: 11 | C20: Area under aquaculture | D20: m2 | E20: aquacultureArea | F20: H20 | K20: =CONCATENATE("""",F20,"""",":","""","parcelassessmentwithdats_",LOWER($A20),"_",LOWER($E20),"""") -> "H20":"parcelassessmentwithdats_parcelinformation_aquaculturearea"
F21: H21 | K21: =CONCATENATE("""",F21,"""",":","""","parcelassessmentwithdats_",LOWER($A21),"_",LOWER($E21),"""") -> "H21":"parcelassessmentwithdats__"
B22: WATER | F22: H22 | H22: Year 1 | K22: =CONCATENATE("""",F22,"""",":","""","parcelassessmentwithdats_",LOWER($A22),"_",LOWER($E22),"""") -> "H22":"parcelassessmentwithdats__"
B23: # | C23: data | D23: u.m. | F23: H23 | H23: Without DATSs | I23: Notes | K23: =CONCATENATE("""",F23,"""",":","""","parcelassessmentwithdats_",LOWER($A23),"_",LOWER($E23),"""") -> "H23":"parcelassessmentwithdats__"
A24: waterUsageInformation | B24: 12 | C24: Irrigation | D24: m3 | E24: waterUsageForIrrigation | F24: H24 | H24: 2619 | K24: =CONCATENATE("""",F24,"""",":","""","parcelassessmentwithdats_",LOWER($A24),"_",LOWER($E24),"""") -> "H24":"parcelassessmentwithdats_waterusageinformation_waterusageforirrigation"
A25: waterUsageInformation | B25: 13 | C25: Fertigation | D25: m3 | E25: waterUsageForFertigation | F25: H25 | H25: 1023 | K25: =CONCATENATE("""",F25,"""",":","""","parcelassessmentwithdats_",LOWER($A25),"_",LOWER($E25),"""") -> "H25":"parcelassessmentwithdats_waterusageinformation_waterusageforfertigation"
A26: waterUsageInformation | B26: 14 | C26: Pest dilution | D26: m3 | E26: waterUsageForPestDilution | F26: H26 | K26: =CONCATENATE("""",F26,"""",":","""","parcelassessmentwithdats_",LOWER($A26),"_",LOWER($E26),"""") -> "H26":"parcelassessmentwithdats_waterusageinformation_waterusageforpestdilution"
A27: waterUsageInformation | B27: 15 | C27: Cleaning | D27: m3 | E27: waterUsageForCleaning | F27: H27 | K27: =CONCATENATE("""",F27,"""",":","""","parcelassessmentwithdats_",LOWER($A27),"_",LOWER($E27),"""") -> "H27":"parcelassessmentwithdats_waterusageinformation_waterusageforcleaning"
A28: waterUsageInformation | B28: 16 | C28: Drinking | D28: m3 | E28: waterUsageForDrinking | F28: H28 | K28: =CONCATENATE("""",F28,"""",":","""","parcelassessmentwithdats_",LOWER($A28),"_",LOWER($E28),"""") -> "H28":"parcelassessmentwithdats_waterusageinformation_waterusagefordrinking"
A29: waterUsageInformation | B29: 17 | C29: or Total water used | D29: m3 | E29: totalWaterUsage | F29: H29 | H29: 3642 | K29: =CONCATENATE("""",F29,"""",":","""","parcelassessmentwithdats_",LOWER($A29),"_",LOWER($E29),"""") -> "H29":"parcelassessmentwithdats_waterusageinformation_totalwaterusage"
F30: H30 | K30: =CONCATENATE("""",F30,"""",":","""","parcelassessmentwithdats_",LOWER($A30),"_",LOWER($E30),"""") -> "H30":"parcelassessmentwithdats__"
B31: FUEL | F31: H31 | H31: Year 1 | K31: =CONCATENATE("""",F31,"""",":","""","parcelassessmentwithdats_",LOWER($A31),"_",LOWER($E31),"""") -> "H31":"parcelassessmentwithdats__"
B32: # | C32: data | D32: u.m. | F32: H32 | H32: Without DATSs | I32: Notes | K32: =CONCATENATE("""",F32,"""",":","""","parcelassessmentwithdats_",LOWER($A32),"_",LOWER($E32),"""") -> "H32":"parcelassessmentwithdats__"
A33: fuelUsageInformation | B33: 18 | C33: Fertilisation | D33: l | E33: fuelUsageForFertilisation | F33: H33 | K33: =CONCATENATE("""",F33,"""",":","""","parcelassessmentwithdats_",LOWER($A33),"_",LOWER($E33),"""") -> "H33":"parcelassessmentwithdats_fuelusageinformation_fuelusageforfertilisation"
A34: fuelUsageInformation | B34: 19 | C34: Pesticides | D34: l | E34: fuelUsageForPesticides | F34: H34 | K34: =CONCATENATE("""",F34,"""",":","""","parcelassessmentwithdats_",LOWER($A34),"_",LOWER($E34),"""") -> "H34":"parcelassessmentwithdats_fuelusageinformation_fuelusageforpesticides"
A35: fuelUsageInformation | B35: 20 | C35: Irrigation | D35: l | E35: fuelUsageForIrrigation | F35: H35 | K35: =CONCATENATE("""",F35,"""",":","""","parcelassessmentwithdats_",LOWER($A35),"_",LOWER($E35),"""") -> "H35":"parcelassessmentwithdats_fuelusageinformation_fuelusageforirrigation"
A36: fuelUsageInformation | B36: 21 | C36: Sowing / Planting | D36: l | E36: fuelUsageForSowing | F36: H36 | K36: =CONCATENATE("""",F36,"""",":","""","parcelassessmentwithdats_",LOWER($A36),"_",LOWER($E36),"""") -> "H36":"parcelassessmentwithdats_fuelusageinformation_fuelusageforsowing"
A37: fuelUsageInformation | B37: 22 | C37: Temperature and Humidity Control | D37: l | E37: fuelUsageForPruning | F37: H37 | K37: =CONCATENATE("""",F37,"""",":","""","parcelassessmentwithdats_",LOWER($A37),"_",LOWER($E37),"""") -> "H37":"parcelassessmentwithdats_fuelusageinformation_fuelusageforpruning"
A38: fuelUsageInformation | B38: 23 | C38: Pruning | D38: l | E38: fuelUsageForTemperatureHumidityControl | F38: H38 | K38: =CONCATENATE("""",F38,"""",":","""","parcelassessmentwithdats_",LOWER($A38),"_",LOWER($E38),"""") -> "H38":"parcelassessmentwithdats_fuelusageinformation_fuelusagefortemperaturehumiditycontrol"
A39: fuelUsageInformation | B39: 24 | C39: Beehives visits | D39: l | E39: fuelUsageForBeehivesVisits | F39: H39 | K39: =CONCATENATE("""",F39,"""",":","""","parcelassessmentwithdats_",LOWER($A39),"_",LOWER($E39),"""") -> "H39":"parcelassessmentwithdats_fuelusageinformation_fuelusageforbeehivesvisits"
A40: fuelUsageInformation | B40: 25 | C40: Transporting oysters to the laboratory | D40: l | E40: fuelUsageForTransportingOysters | F40: H40 | K40: =CONCATENATE("""",F40,"""",":","""","parcelassessmentwithdats_",LOWER($A40),"_",LOWER($E40),"""") -> "H40":"parcelassessmentwithdats_fuelusageinformation_fuelusagefortransportingoysters"
A41: fuelUsageInformation | B41: 26 | C41: Milking | D41: l | E41: fuelUsageForMilking | F41: H41 | K41: =CONCATENATE("""",F41,"""",":","""","parcelassessmentwithdats_",LOWER($A41),"_",LOWER($E41),"""") -> "H41":"parcelassessmentwithdats_fuelusageinformation_fuelusageformilking"
A42: fuelUsageInformation | B42: 27 | C42: Feeding | D42: l | E42: fuelUsageForFeeding | F42: H42 | K42: =CONCATENATE("""",F42,"""",":","""","parcelassessmentwithdats_",LOWER($A42),"_",LOWER($E42),"""") -> "H42":"parcelassessmentwithdats_fuelusageinformation_fuelusageforfeeding"
A43: fuelUsageInformation | B43: 28 | C43: or Total fuel used | D43: l | E43: totalFuelUsage | F43: H43 | K43: =CONCATENATE("""",F43,"""",":","""","parcelassessmentwithdats_",LOWER($A43),"_",LOWER($E43),"""") -> "H43":"parcelassessmentwithdats_fuelusageinformation_totalfuelusage"
F44: H44 | K44: =CONCATENATE("""",F44,"""",":","""","parcelassessmentwithdats_",LOWER($A44),"_",LOWER($E44),"""") -> "H44":"parcelassessmentwithdats__"
...

Sheet Cost-revenue DATS
A1: COST ANALYSIS
A2: INPUT | B2: INDICATOR | C2: SCENARIO | D2: UoM | E2: TOTAL | F2: FORMULAS
A3: WATER | B3: Cost of water | C3: With DATs | D3: =IFERROR(VLOOKUP('General Information'!$D$6, Validations!$L$2:$M$8, 2,FALSE), "") -> €/ha | E3: =('Parcel 1 with DATSs'!G29*'General Information'!D32)/(IF('General Information'!D6="crop",'Parcel 1 with DATSs'!G10,IF('General Information'!D6="milk",'Parcel 1 with DATSs'!G251,IF('General Information'!D6="meat",'Parcel 1 with DATSs'!G252,IF('General Information'!D6="animal",'Parcel 1 with DATSs'!G253,IF('General Information'!D6="oyster",'Parcel 1 with DATSs'!G254,IF('General Information'!D6="honey",'Parcel 1 with DATSs'!G255,'Parcel 1 with DATSs'!G256))))))) -> 0 | F3: IF(Total water used>0; (Total water used * water price)/Parcel dimension; Sum(water Irrigation+ water Fertigation + water Pest dilution + …) * water price) | G3: =CONCATENATE("cost revenue dats","_",$A$1,"_",A3,"_",B3) -> cost revenue dats_COST ANALYSIS_WATER _Cost of water | H3: E3
A4: FUEL | B4: Cost of fuel | C4: With DATs | D4: =IFERROR(VLOOKUP('General Information'!$D$6, Validations!$L$2:$M$8, 2,FALSE), "") -> €/ha | E4: ='Parcel 1 with DATSs'!G43*'General Information'!D33/(IF('General Information'!D6="crop",'Parcel 1 with DATSs'!G10,IF('General Information'!D6="milk",'Parcel 1 with DATSs'!G251,IF('General Information'!D6="meat",'Parcel 1 with DATSs'!G252,IF('General Information'!D6="animal",'Parcel 1 with DATSs'!G253,IF('General Information'!D6="oyster",'Parcel 1 with DATSs'!G254,IF('General Information'!D6="honey",'Parcel 1 with DATSs'!G255,'Parcel 1 with DATSs'!G256))))))) -> 0 | F4: IF(Total fuel used>0; (Total fuel used*fuel price)/Parcel dimension; sum(Fertilisation+Pesticides +Irrigation+Sowing_Planting+Pruning+…) * fuel price) | G4: =CONCATENATE("cost revenue dats","_",$A$1,"_",A4,"_",B4) -> cost revenue dats_COST ANALYSIS_FUEL _Cost of fuel | H4: E4
A5: ELECTRICITY | B5: Cost of electricity | C5: With DATs | D5: =IFERROR(VLOOKUP('General Information'!$D$6, Validations!$L$2:$M$8, 2,FALSE), "") -> €/ha | E5: ='Parcel 1 with DATSs'!G62*'General Information'!D38/(IF('General Information'!D6="crop",'Parcel 1 with DATSs'!G10,IF('General Information'!D6="milk",'Parcel 1 with DATSs'!G251,IF('General Information'!D6="meat",'Parcel 1 with DATSs'!G252,IF('General Information'!D6="animal",'Parcel 1 with DATSs'!G253,IF('General Information'!D6="oyster",'Parcel 1 with DATSs'!G254,IF('General Information'!D6="honey",'Parcel 1 with DATSs'!G255,'Parcel 1 with DATSs'!G256))))))) -> 2.5609756 | F5: IF(Total electricity used > 0; (Total electricity used* electricity price)/Parcel dimension; Sum(irrigation,…) *electricity price) | G5: =CONCATENATE("cost revenue dats","_",$A$1,"_",A5,"_",B5) -> cost revenue dats_COST ANALYSIS_ELECTRICITY_Cost of electricity | H5: E5
A6: PESTICIDE | B6: Cost for pesticide | C6: With DATs | D6: =IFERROR(VLOOKUP('General Information'!$D$6, Validations!$L$2:$M$8, 2,FALSE), "") -> €/ha | E6: =('Parcel 1 with DATSs'!G67*'Parcel 1 with DATSs'!G68*'General Information'!D43)+ ('Parcel 1 with DATSs'!G70*'Parcel 1 with DATSs'!G71*'General Information'!D44)+ ('Parcel 1 with DATSs'!G73*'Parcel 1 with DATSs'!G74*'General Information'!D45)+ ('Parcel 1 with DATSs'!G76*'Parcel 1 with DATSs'!G77*'General Information'!D46)+ ('Parcel 1 with DATSs'!G79*'Parcel 1 with DATSs'!G80*'General Information'!D47)+ ('Parcel 1 with DATSs'!G82*'Parcel 1 with DATSs'!G83*'General Information'!D48)+ ('Parcel 1 with DATSs'!G85*'Parcel 1 with DATSs'!G86*'General Information'!D49)+ ('Parcel 1 with DATSs'!G88*'Parcel 1 with DATSs'!G89*'General Information'!D50)+ ('Parcel 1 with DATSs'!G91*'Parcel 1 with DATSs'!G92*'General Information'!D51)+ ('Parcel 1 with DATSs'!G94*'Parcel 1 with DATSs'!G95*'General Information'!D52) -> 0 | F6: [(N. of treatements of pesticide 1*Amount of pesticide 1*pesticide 1 price)+(N. of treatements of pesticide 2 *Amount of pesticide 2 used *pesticide 2 price) + (N. of treatements of pesticide 3 *Amount of pesticide 3 used *pesticide 3 price (€/kg)] | G6: =CONCATENATE("cost revenue dats","_",$A$1,"_",A6,"_",B6) -> cost revenue dats_COST ANALYSIS_PESTICIDE _Cost for pesticide | H6: E6
A7: FERTILISER | B7: Cost of fertiliser | C7: With DATs | D7: =IFERROR(VLOOKUP('General Information'!$D$6, Validations!$L$2:$M$8, 2,FALSE), "") -> €/ha | E7: =('Parcel 1 with DATSs'!G101*'Parcel 1 with DATSs'!G102*'General Information'!D54)+ ('Parcel 1 with DATSs'!G108*'Parcel 1 with DATSs'!G109*'General Information'!D55)+ ('Parcel 1 with DATSs'!G115*'Parcel 1 with DATSs'!G116*'General Information'!D56)+ ('Parcel 1 with DATSs'!G122*'Parcel 1 with DATSs'!G123*'General Information'!D57)+ ('Parcel 1 with DATSs'!G129*'Parcel 1 with DATSs'!G130*'General Information'!D58)+ ('Parcel 1 with DATSs'!G136*'Parcel 1 with DATSs'!G137*'General Information'!D59)+ ('Parcel 1 with DATSs'!G143*'Parcel 1 with DATSs'!G144*'General Information'!D60)+ ('Parcel 1 with DATSs'!G150*'Parcel 1 with DATSs'!G151*'General Information'!D61)+ ('Parcel 1 with DATSs'!G157*'Parcel 1 with DATSs'!G158*'General Information'!D62)+ ('Parcel 1 with DATSs'!G164*'Parcel 1 with DATSs'!G165*'General Information'!D63) -> 1371.47 | F7: ((Amount of fertilisers 1 used *Number of fertilizer 1 applications *Fertilisers 1 price) + (Amount of fertilisers 2 used *Number of fertilizer 2 applications *Fertilisers 2 price) + (Amount of fertilisers 3 used *Number of fertilizer 3 applications *Fertilisers 3 price) | G7: =CONCATENATE("cost revenue dats","_",$A$1,"_",A7,"_",B7) -> cost revenue dats_COST ANALYSIS_FERTILISER_Cost of fertiliser | H7: E7
A8: FEED | B8: Cost of feed | C8: With DATs | D8: =IFERROR(VLOOKUP('General Information'!$D$6, Validations!$L$2:$M$8, 2,FALSE), "") -> €/ha | E8: =(('General Information'!D65*'Parcel 1 with DATSs'!G173)+('General Information'!D66*'Parcel 1 with DATSs'!G175)+('General Information'!D69*'Parcel 1 with DATSs'!G177))/(IF('General Information'!D6="crop",'Parcel 1 with DATSs'!G10,IF('General Information'!D6="milk",'Parcel 1 with DATSs'!G251,IF('General Information'!D6="meat",'Parcel 1 with DATSs'!G252,IF('General Information'!D6="animal",'Parcel 1 with DATSs'!G253,IF('General Information'!D6="oyster",'Parcel 1 with DATSs'!G254,IF('General Information'!D6="honey",'Parcel 1 with DATSs'!G255,'Parcel 1 with DATSs'!G256))))))) -> 0 | F8: (Amount of feed 1 * Feed 1 price) + (Amount of feed 2 * Feed 2 price) + … /animal | G8: =CONCATENATE("cost revenue dats","_",$A$1,"_",A8,"_",B8) -> cost revenue dats_COST ANALYSIS_FEED_Cost of feed | H8: E8
A9: DRUGS | B9: Cost of drugs | C9: With DATs | D9: =IFERROR(VLOOKUP('General Information'!$D$6, Validations!$L$2:$M$8, 2,FALSE), "") -> €/ha | E9: =(('General Information'!D71*'Parcel 1 with DATSs'!G186)+('General Information'!D72*'Parcel 1 with DATSs'!G188)+('General Information'!D73*'Parcel 1 with DATSs'!G190))/(IF('General Information'!D6="crop",'Parcel 1 with DATSs'!G10,IF('General Information'!D6="milk",'Parcel 1 with DATSs'!G251,IF('General Information'!D6="meat",'Parcel 1 with DATSs'!G252,IF('General Information'!D6="animal",'Parcel 1 with DATSs'!G253,IF('General Information'!D6="oyster",'Parcel 1 with DATSs'!G254,IF('General Information'!D6="honey",'Parcel 1 with DATSs'!G255,'Parcel 1 with DATSs'!G256))))))) -> 0 | F9: (Amount of drugs 1 * Feed 1 price) + (Amount of drugs 2 * Feed 2 price) + … /animal or beehives or pieces | G9: =CONCATENATE("cost revenue dats","_",$A$1,"_",A9,"_",B9) -> cost revenue dats_COST ANALYSIS_DRUGS _ Cost of drugs | H9: E9
A10: LABOUR | B10: Cost of labour for irrigation | C10: With DATs | D10: =IFERROR(VLOOKUP('General Information'!$D$6, Validations!$L$2:$M$8, 2,FALSE), "") -> €/ha | E10: ='Parcel 1 with DATSs'!G194*'General Information'!D39/'Parcel 1 with DATSs'!G10 -> 134.14634 | F10: number of hours for irrigation activities*Average salary /Parcel dimension | G10: =CONCATENATE("cost revenue dats","_",$A$1,"_",A10,"_",B10) -> cost revenue dats_COST ANALYSIS_LABOUR_Cost of labour for irrigation | H10: E10
A11: LABOUR | B11: Cost of labour for pesticide application | C11: With DATs | D11: =IFERROR(VLOOKUP('General Information'!$D$6, Validations!$L$2:$M$8, 2,FALSE), "") -> €/ha | E11: ='Parcel 1 with DATSs'!G195*'General Information'!D39/'Parcel 1 with DATSs'!G10 -> 0 | F11: number of hours for pesticide activities *Average salary /Parcel dimension | G11: =CONCATENATE("cost revenue dats","_",$A$1,"_",A11,"_",B11) -> cost revenue dats_COST ANALYSIS_LABOUR_Cost of labour for pesticide application | H11: E11
A12: LABOUR | B12: Cost of labour for fertilisation | C12: With DATs | D12: =IFERROR(VLOOKUP('General Information'!$D$6, Validations!$L$2:$M$8, 2,FALSE), "") -> €/ha | E12: ='Parcel 1 with DATSs'!G196*'General Information'!D39/'Parcel 1 with DATSs'!G10 -> 0 | F12: number of hours for fertilisation activities * Average salary /Parcel dimension | G12: =CONCATENATE("cost revenue dats","_",$A$1,"_",A12,"_",B12) -> cost revenue dats_COST ANALYSIS_LABOUR_Cost of labour for fertilisation | H12: E12
A13: LABOUR | B13: Cost of labour for sowing_planting | C13: With DATs | D13: =IFERROR(VLOOKUP('General Information'!$D$6, Validations!$L$2:$M$8, 2,FALSE), "") -> €/ha | E13: ='Parcel 1 with DATSs'!G197*'General Information'!D39/'Parcel 1 with DATSs'!G10 -> 0 | F13: number of hours for sowing_planting activities * Average salary /Parcel dimension | G13: =CONCATENATE("cost revenue dats","_",$A$1,"_",A13,"_",B13) -> cost revenue dats_COST ANALYSIS_LABOUR_Cost of labour for sowing_planting | H13: E13
A14: LABOUR | B14: Cost of labour for pruning | C14: With DATs | D14: =IFERROR(VLOOKUP('General Information'!$D$6, Validations!$L$2:$M$8, 2,FALSE), "") -> €/ha | E14: ='Parcel 1 with DATSs'!G198*'General Information'!D39/'Parcel 1 with DATSs'!G10 -> 0 | F14: number of hours for pruning activities *Average salary /Parcel dimension | G14: =CONCATENATE("cost revenue dats","_",$A$1,"_",A14,"_",B14) -> cost revenue dats_COST ANALYSIS_LABOUR_Cost of labour for pruning | H14: E14
A15: LABOUR | B15: Cost of labour for field visits | C15: With DATs | D15: =IFERROR(VLOOKUP('General Information'!$D$6, Validations!$L$2:$M$8, 2,FALSE), "") -> €/ha | E15: ='Parcel 1 with DATSs'!G199*'General Information'!D39/'Parcel 1 with DATSs'!G10 -> 0 | F15: number of hours for field visits activities * Average professional salary /Parcel dimension | G15: =CONCATENATE("cost revenue dats","_",$A$1,"_",A15,"_",B15) -> cost revenue dats_COST ANALYSIS_LABOUR_Cost of labour for field visits | H15: E15
A16: LABOUR | B16: Cost of labour for greenhouse maintenance | C16: With DATs | D16: =IFERROR(VLOOKUP('General Information'!$D$6, Validations!$L$2:$M$8, 2,FALSE), "") -> €/ha | E16: ='Parcel 1 with DATSs'!G200*'General Information'!D39/'Parcel 1 with DATSs'!G10 -> 0 | F16: number of hours for greenhouse management *Average salary /Parcel dimension | G16: =CONCATENATE("cost revenue dats","_",$A$1,"_",A16,"_",B16) -> cost revenue dats_COST ANALYSIS_LABOUR_Cost of labour for greenhouse maintenance | H16: E16
A17: LABOUR | B17: Cost of labour for tracking the quantity of grain available in the silo | C17: With DATs | D17: =IFERROR(VLOOKUP('General Information'!$D$6, Validations!$L$2:$M$8, 2,FALSE), "") -> €/ha | E17: ='Parcel 1 with DATSs'!G201*'General Information'!D39/'Parcel 1 with DATSs'!G256 -> #DIV/0! | F17: number of hours for tracking the quantity of grain available in the silo *Average salary | G17: =CONCATENATE("cost revenue dats","_",$A$1,"_",A17,"_",B17) -> cost revenue dats_COST ANALYSIS_LABOUR_Cost of labour for tracking the quantity of grain available in the silo | H17: E17
A18: LABOUR | B18: Cost of labour for assessing product quality | C18: With DATs | D18: =IFERROR(VLOOKUP('General Information'!$D$6, Validations!$L$2:$M$8, 2,FALSE), "") -> €/ha | E18: ='Parcel 1 with DATSs'!G202*'General Information'!D39/(IF('General Information'!D6="crop",'Parcel 1 with DATSs'!G10,IF('General Information'!D6="milk",'Parcel 1 with DATSs'!G251,IF('General Information'!D6="meat",'Parcel 1 with DATSs'!G252,IF('General Information'!D6="animal",'Parcel 1 with DATSs'!G253,IF('General Information'!D6="oyster",'Parcel 1 with DATSs'!G254,IF('General Information'!D6="honey",'Parcel 1 with DATSs'!G255,'Parcel 1 with DATSs'!G256))))))) -> 0 | F18: number of hours for assessing grain quality *Average salary | G18: =CONCATENATE("cost revenue dats","_",$A$1,"_",A18,"_",B18) -> cost revenue dats_COST ANALYSIS_LABOUR_Cost of labour for assessing product quality | H18: E18
A19: LABOUR | B19: Cost of labour for controlling purchase and sale prices and quantities | C19: With DATs | D19: =IFERROR(VLOOKUP('General Information'!$D$6, Validations!$L$2:$M$8, 2,FALSE), "") -> €/ha | E19: ='Parcel 1 with DATSs'!G203*'General Information'!D39/(IF('General Information'!D6="crop",'Parcel 1 with DATSs'!G10,IF('General Information'!D6="milk",'Parcel 1 with DATSs'!G251,IF('General Information'!D6="meat",'Parcel 1 with DATSs'!G252,IF('General Information'!D6="animal",'Parcel 1 with DATSs'!G253, IF('General Information'!D6="oyster",'Parcel 1 with DATSs'!G254,IF('General Information'!D6="honey",'Parcel 1 with DATSs'!G255,'Parcel 1 with DATSs'!G256))))))) -> 0 | F19: number of hours for controlling purchase and sale prices and quantities *Average salary | G19: =CONCATENATE("cost revenue dats","_",$A$1,"_",A19,"_",B19) -> cost revenue dats_COST ANALYSIS_LABOUR_Cost of labour for controlling purchase and sale prices and quantities | H19: E19
A20: LABOUR | B20: Cost of labour for organise logistics | C20: With DATs | D20: =IFERROR(VLOOKUP('General Information'!$D$6, Validations!$L$2:$M$8, 2,FALSE), "") -> €/ha | E20: ='Parcel 1 with DATSs'!G204*'General Information'!D39/(IF('General Information'!D6="crop",'Parcel 1 with DATSs'!G10,IF('General Information'!D6="milk",'Parcel 1 with DATSs'!G251,IF('General Information'!D6="meat",'Parcel 1 with DATSs'!G252,IF('General Information'!D6="animal",'Parcel 1 with DATSs'!G253, IF('General Information'!D6="oyster",'Parcel 1 with DATSs'!G254,IF('General Information'!D6="honey",'Parcel 1 with DATSs'!G255,'Parcel 1 with DATSs'!G256))))))) -> 0 | F20: number of hours for organise logistics *Average salary | G20: =CONCATENATE("cost revenue dats","_",$A$1,"_",A20,"_",B20) -> cost revenue dats_COST ANALYSIS_LABOUR_Cost of labour for organise logistics | H20: E20
A21: LABOUR | B21: Cost of labour for cleaning | C21: With DATs | D21: =IFERROR(VLOOKUP('General Information'!$D$6, Validations!$L$2:$M$8, 2,FALSE), "") -> €/ha | E21: ='Parcel 1 with DATSs'!G205*'General Information'!D39/(IF('General Information'!D6="crop",'Parcel 1 with DATSs'!G10,IF('General Information'!D6="milk",'Parcel 1 with DATSs'!G251,IF('General Information'!D6="meat",'Parcel 1 with DATSs'!G252,IF('General Information'!D6="animal",'Parcel 1 with DATSs'!G253, IF('General Information'!D6="oyster",'Parcel 1 with DATSs'!G254,IF('General Information'!D6="honey",'Parcel 1 with DATSs'!G255,'Parcel 1 with DATSs'!G256))))))) -> 0 | F21: number of hours for cleaning *Average salary /animal | G21: =CONCATENATE("cost revenue dats","_",$A$1,"_",A21,"_",B21) -> cost revenue dats_COST ANALYSIS_LABOUR_Cost of labour for cleaning | H21: E21
A22: LABOUR | B22: Cost of labour for stable visits | C22: With DATs | D22: =IFERROR(VLOOKUP('General Information'!$D$6, Validations!$L$2:$M$8, 2,FALSE), "") -> €/ha | E22: ='Parcel 1 with DATSs'!G206*'General Information'!D39/(IF('General Information'!D6="crop",'Parcel 1 with DATSs'!G10,IF('General Information'!D6="milk",'Parcel 1 with DATSs'!G251,IF('General Information'!D6="meat",'Parcel 1 with DATSs'!G252,IF('General Information'!D6="animal",'Parcel 1 with DATSs'!G253, IF('General Information'!D6="oyster",'Parcel 1 with DATSs'!G254,IF('General Information'!D6="honey",'Parcel 1 with DATSs'!G255,'Parcel 1 with DATSs'!G256))))))) -> 0 | F22: number of hours for stable visits*Average professional salary /animal | G22: =CONCATENATE("cost revenue dats","_",$A$1,"_",A22,"_",B22) -> cost revenue dats_COST ANALYSIS_LABOUR_Cost of labour for stable visits | H22: E22
A23: LABOUR | B23: Cost of labour for heat detection | C23: With DATs | D23: =IFERROR(VLOOKUP('General Information'!$D$6, Validations!$L$2:$M$8, 2,FALSE), "") -> €/ha | E23: ='Parcel 1 with DATSs'!G207*'General Information'!D39/(IF('General Information'!D6="crop",'Parcel 1 with DATSs'!G10,IF('General Information'!D6="milk",'Parcel 1 with DATSs'!G251,IF('General Information'!D6="meat",'Parcel 1 with DATSs'!G252,IF('General Information'!D6="animal",'Parcel 1 with DATSs'!G253, IF('General Information'!D6="oyster",'Parcel 1 with DATSs'!G254,IF('General Information'!D6="honey",'Parcel 1 with DATSs'!G255,'Parcel 1 with DATSs'!G256))))))) -> 0 | F23: number of hours for heat detection *Average salary /animal | G23: =CONCATENATE("cost revenue dats","_",$A$1,"_",A23,"_",B23) -> cost revenue dats_COST ANALYSIS_LABOUR_Cost of labour for heat detection | H23: E23
A24: LABOUR | B24: Cost of labour for calving detection | C24: With DATs | D24: =IFERROR(VLOOKUP('General Information'!$D$6, Validations!$L$2:$M$8, 2,FALSE), "") -> €/ha | E24: ='Parcel 1 with DATSs'!G208*'General Information'!D39/(IF('General Information'!D6="crop",'Parcel 1 with DATSs'!G10,IF('General Information'!D6="milk",'Parcel 1 with DATSs'!G251,IF('General Information'!D6="meat",'Parcel 1 with DATSs'!G252,IF('General Information'!D6="animal",'Parcel 1 with DATSs'!G253, IF('General Information'!D6="oyster",'Parcel 1 with DATSs'!G254,IF('General Information'!D6="honey",'Parcel 1 with DATSs'!G255,'Parcel 1 with DATSs'!G256))))))) -> 0 | F24: number of hours for calving detection *Average salary /animal | G24: =CONCATENATE("cost revenue dats","_",$A$1,"_",A24,"_",B24) -> cost revenue dats_COST ANALYSIS_LABOUR_Cost of labour for calving detection | H24: E24
A25: LABOUR | B25: Cost of labour for pigsty management | C25: With DATs | D25: =IFERROR(VLOOKUP('General Information'!$D$6, Validations!$L$2:$M$8, 2,FALSE), "") -> €/ha | E25: ='Parcel 1 with DATSs'!G209*'General Information'!D39/(IF('General Information'!D6="crop",'Parcel 1 with DATSs'!G10,IF('General Information'!D6="milk",'Parcel 1 with DATSs'!G251,IF('General Information'!D6="meat",'Parcel 1 with DATSs'!G252,IF('General Information'!D6="animal",'Parcel 1 with DATSs'!G253, IF('General Information'!D6="oyster",'Parcel 1 with DATSs'!G254,IF('General Information'!D6="honey",'Parcel 1 with DATSs'!G255,'Parcel 1 with DATSs'!G256))))))) -> 0 | F25: number of hours for pigsty management*Average salary /animal | G25: =CONCATENATE("cost revenue dats","_",$A$1,"_",A25,"_",B25) -> cost revenue dats_COST ANALYSIS_LABOUR_Cost of labour for pigsty management | H25: E25
A26: LABOUR | B26: Cost of milking | C26: With DATs | D26: =IFERROR(VLOOKUP('General Information'!$D$6, Validations!$L$2:$M$8, 2,FALSE), "") -> €/ha | E26: ='Parcel 1 with DATSs'!G210*'General Information'!D39/(IF('General Information'!D6="crop",'Parcel 1 with DATSs'!G10,IF('General Information'!D6="milk",'Parcel 1 with DATSs'!G251,IF('General Information'!D6="meat",'Parcel 1 with DATSs'!G252,IF('General Information'!D6="animal",'Parcel 1 with DATSs'!G253, IF('General Information'!D6="oyster",'Parcel 1 with DATSs'!G254,IF('General Information'!D6="honey",'Parcel 1 with DATSs'!G255,'Parcel 1 with DATSs'!G256))))))) -> 0 | F26: number of hours for milking *Average salary /animal | G26: =CONCATENATE("cost revenue dats","_",$A$1,"_",A26,"_",B26) -> cost revenue dats_COST ANALYSIS_LABOUR_Cost of milking | H26: E26
A27: LABOUR | B27: Cost of labour for (milk) quality assessment | C27: With DATs | D27: =IFERROR(VLOOKUP('General Information'!$D$6, Validations!$L$2:$M$8, 2,FALSE), "") -> €/ha | E27: ='Parcel 1 with DATSs'!G211*'General Information'!D39/(IF('General Information'!D6="crop",'Parcel 1 with DATSs'!G10,IF('General Information'!D6="milk",'Parcel 1 with DATSs'!G251,IF('General Information'!D6="meat",'Parcel 1 with DATSs'!G252,IF('General Information'!D6="animal",'Parcel 1 with DATSs'!G253, IF('General Information'!D6="oyster",'Parcel 1 with DATSs'!G254,IF('General Information'!D6="honey",'Parcel 1 with DATSs'!G255,'Parcel 1 with DATSs'!G256))))))) -> 0 | F27: number of hours for (milk) quality assessment*Average salary /animal | G27: =CONCATENATE("cost revenue dats","_",$A$1,"_",A27,"_",B27) -> cost revenue dats_COST ANALYSIS_LABOUR_Cost of labour for (milk) quality assessment | H27: E27
A28: LABOUR | B28: Cost of labour for feeding | C28: With DATs | D28: =IFERROR(VLOOKUP('General Information'!$D$6, Validations!$L$2:$M$8, 2,FALSE), "") -> €/ha | E28: ='Parcel 1 with DATSs'!G212*'General Information'!D39/(IF('General Information'!D6="crop",'Parcel 1 with DATSs'!G10,IF('General Information'!D6="milk",'Parcel 1 with DATSs'!G251,IF('General Information'!D6="meat",'Parcel 1 with DATSs'!G252,IF('General Information'!D6="animal",'Parcel 1 with DATSs'!G253, IF('General Information'!D6="oyster",'Parcel 1 with DATSs'!G254,IF('General Information'!D6="honey",'Parcel 1 with DATSs'!G255,'Parcel 1 with DATSs'!G256))))))) -> 0 | F28: number of hours for feeding *Average salary /animal | G28: =CONCATENATE("cost revenue dats","_",$A$1,"_",A28,"_",B28) -> cost revenue dats_COST ANALYSIS_LABOUR_Cost of labour for feeding | H28: E28
A29: LABOUR | B29: Cost of labour for beehives visits | C29: With DATs | D29: =IFERROR(VLOOKUP('General Information'!$D$6, Validations!$L$2:$M$8, 2,FALSE), "") -> €/ha | E29: ='Parcel 1 with DATSs'!G213*'General Information'!D39/'Parcel 1 with DATSs'!G255 -> #DIV/0! | F29: number of hours for beehives visits *Average salary / beehive | G29: =CONCATENATE("cost revenue dats","_",$A$1,"_",A29,"_",B29) -> cost revenue dats_COST ANALYSIS_LABOUR_Cost of labour for beehives visits | H29: E29
A30: LABOUR | B30: Cost of labour for sampling of oysters | C30: With DATs | D30: =IFERROR(VLOOKUP('General Information'!$D$6, Validations!$L$2:$M$8, 2,FALSE), "") -> €/ha | E30: ='Parcel 1 with DATSs'!G214*'General Information'!D39/'Parcel 1 with DATSs'!G254 -> #DIV/0! | F30: number of hours for sampling of oysters* Average salary /piece | G30: =CONCATENATE("cost revenue dats","_",$A$1,"_",A30,"_",B30) -> cost revenue dats_COST ANALYSIS_LABOUR_Cost of labour for sampling of oysters | H30: E30
A31: LABOUR | B31: Cost of labour for transporting oysters to the laboratory | C31: With DATs | D31: =IFERROR(VLOOKUP('General Information'!$D$6, Validations!$L$2:$M$8, 2,FALSE), "") -> €/ha | E31: ='Parcel 1 with DATSs'!G215*'General Information'!D39/'Parcel 1 with DATSs'!G254 -> #DIV/0! | F31: number of hours for transporting oysters to the laboratory*Average salary /piece | G31: =CONCATENATE("cost revenue dats","_",$A$1,"_",A31,"_",B31) -> cost revenue dats_COST ANALYSIS_LABOUR_Cost of labour for transporting oysters to the laboratory | H31: E31
A32: LABOUR | B32: Cost of labour for harvesting | C32: With DATs | D32: =IFERROR(VLOOKUP('General Information'!$D$6, Validations!$L$2:$M$8, 2,FALSE), "") -> €/ha | E32: ='Parcel 1 with DATSs'!G216*'General Information'!$D$39/(IF('General Information'!D6="crop",'Parcel 1 with DATSs'!G10,IF('General Information'!D6="milk",'Parcel 1 with DATSs'!G251,IF('General Information'!D6="meat",'Parcel 1 with DATSs'!G252,IF('General Information'!D6="animal",'Parcel 1 with DATSs'!G253, IF('General Information'!D6="oyster",'Parcel 1 with DATSs'!G254,IF('General Information'!D6="honey",'Parcel 1 with DATSs'!G255,'Parcel 1 with DATSs'!G256))))))) -> 0 | F32: number of hours for harvesting oyster*Average salary /piece | G32: =CONCATENATE("cost revenue dats","_",$A$1,"_",A32,"_",B32) -> cost revenue dats_COST ANALYSIS_LABOUR_Cost of labour for harvesting | H32: E32
A33: LABOUR | B33: Cost of labour for storage | C33: With DATs | D33: =IFERROR(VLOOKUP('General Information'!$D$6, Validations!$L$2:$M$8, 2,FALSE), "") -> €/ha | E33: ='Parcel 1 with DATSs'!G217*'General Information'!D39/(IF('General Information'!D6="crop",'Parcel 1 with DATSs'!G10,IF('General Information'!D6="milk",'Parcel 1 with DATSs'!G251,IF('General Information'!D6="meat",'Parcel 1 with DATSs'!G252,IF('General Information'!D6="animal",'Parcel 1 with DATSs'!G253, IF('General Information'!D6="oyster",'Parcel 1 with DATSs'!G254,IF('General Information'!D6="honey",'Parcel 1 with DATSs'!G255,'Parcel 1 with DATSs'!G256))))))) -> 0 | F33: number of hours for storage *Average salary /piece | G33: =CONCATENATE("cost revenue dats","_",$A$1,"_",A33,"_",B33) -> cost revenue dats_COST ANALYSIS_LABOUR_Cost of labour for storage | H33: E33
A34: LABOUR | B34: Cost of administrative activities, data collection, etc. | C34: With DATs | D34: =IFERROR(VLOOKUP('General Information'!$D$6, Validations!$L$2:$M$8, 2,FALSE), "") -> €/ha | E34: ='Parcel 1 with DATSs'!G218*'General Information'!$D$39/(IF('General Information'!D6="crop",'Parcel 1 with DATSs'!G10,IF('General Information'!D6="milk",'Parcel 1 with DATSs'!G251,IF('General Information'!D6="meat",'Parcel 1 with DATSs'!G252,IF('General Information'!D6="animal",'Parcel 1 with DATSs'!G253, IF('General Information'!D6="oyster",'Parcel 1 with DATSs'!G254,IF('General Information'!D6="honey",'Parcel 1 with DATSs'!G255,'Parcel 1 with DATSs'!G256))))))) -> 0 | F34: number of hours foradministrative activities *Average salary /parcel dimension or animal or beehives or pieces | G34: =CONCATENATE("cost revenue dats","_",$A$1,"_",A34,"_",B34) -> cost revenue dats_COST ANALYSIS_LABOUR_Cost of administrative activities, data collection, etc. | H34: E34
A35: COST | B35: TOT Cost | C35: With DATs | D35: =IFERROR(VLOOKUP('General Information'!$D$6, Validations!$L$2:$M$8, 2,FALSE), "") -> €/ha | E35: =_xlfn.AGGREGATE(9,6,E3:E34) -> 1508.1773 | F35: Sum(Cost of labour for irrigation + Cost of labour for fertilisation + … /parcel dimension or animal or beehives or pieces | G35: =CONCATENATE("cost revenue dats","_",$A$1,"_",A35,"_",B35) -> cost revenue dats_COST ANALYSIS_COST_TOT Cost | H35: E35
A36: DATSs | B36: Cost of DATSs | C36: With DATs | D36: =IFERROR(VLOOKUP('General Information'!$D$6, Validations!$L$2:$M$8, 2,FALSE), "") -> €/ha | E36: =(('General Information'!D23+'General Information'!D24)+('General Information'!I23+'General Information'!I24)+('General Information'!M23+'General Information'!M24))/(IF('General Information'!D6="crop",'Parcel 1 with DATSs'!G10,IF('General Information'!D6="milk",'Parcel 1 with DATSs'!G251,IF('General Information'!D6="meat",'Parcel 1 with DATSs'!G252,IF('General Information'!D6="animal",'Parcel 1 with DATSs'!G253, IF('General Information'!D6="oyster",'Parcel 1 with DATSs'!G254,IF('General Information'!D6="honey",'Parcel 1 with DATSs'!G255,'Parcel 1 with DATSs'!G256))))))) -> 73.170732 | F36: DAT maintenance + (Training hours*salary) /parcel dimension or animal or beehives or pieces | G36: =CONCATENATE("cost revenue dats","_",$A$1,"_",A36,"_",B36) -> cost revenue dats_COST ANALYSIS_DATSs_Cost of DATSs | H36: E36
A37: DATSs | B37: Cost of Training | C37: With DATs | D37: =IFERROR(VLOOKUP('General Information'!$D$6, Validations!$L$2:$M$8, 2,FALSE), "") -> €/ha | E37: ='General Information'!D27/(IF('General Information'!D6="crop",'Parcel 1 with DATSs'!G10,IF('General Information'!D6="milk",'Parcel 1 with DATSs'!G251,IF('General Information'!D6="meat",'Parcel 1 with DATSs'!G252,IF('General Information'!D6="animal",'Parcel 1 with DATSs'!G253, IF('General Information'!D6="oyster",'Parcel 1 with DATSs'!G254,IF('General Information'!D6="honey",'Parcel 1 with DATSs'!G255,'Parcel 1 with DATSs'!G256))))))) -> 0 | F37: Costs of external persons being paid to train employees on the use of DAT /parcel dimension or animal or beehives or pieces | G37: =CONCATENATE("cost revenue dats","_",$A$1,"_",A37,"_",B37) -> cost revenue dats_COST ANALYSIS_DATSs_Cost of Training | H37: E37
A39: REVENUES ANALYSIS
A40: CATEGORY | B40: INDICATOR | C40: SCENARIO | D40: UoM | E40: TOTAL | F40: FORMULAS
