Workbook

Sheet Instructions 
B2: Instructions to be followed to complete the Data Collection Template
B3: This form is intended to be filled out by each farmer involved in the Test Case (TC) and aims at collecting information that will be used for assessing the impacts of Digital agriculture technology solutions (DATSs). Please read carefully the following instructions. - We kindly ask you to be as accurate as possible in providing the data and monitor them periodically as these will be the input for performance assessment. - Please ensure you keep track of the data requested and regularly check its availability. It's crucial that these values align for both user and non-user parcels. If they differ, kindly notify us promptly via email at the provided contact details. - The data included in the template have been carefully chosen based on their link with the DATSs used in your TC and they were further customised following your feedback. If some of the data cannot be applicable/available to your TC, please enter ‘n.a.’ in the corresponding cell and provide a comment explaining why they are not applicable. Additionally, in case some of the data cannot be collected due to some problems you may encounter during the season, please inform us promptly by writing an e-mail to the contact details provided below. - In order to obtain the assessment of the impacts of DATS, it is necessary to provide data for the farm(s) using DATS and for the one without. According to the QuantiFarm project proposal, each parcel using DATSs is associated with a comparable non-DATs parcel (in terms of size, geographical area, production, etc.). - Recall that: - the term DATS refers to the combinations or set of technological solutions implemented within the TC; For any doubts or clarifications, please do not hesitate to contact us at the following email address: francesco.parigi@polimi.it and andrea.bianchi@polimi.it (cc: dmoniz@consulai.com) This form is intended to be filled out by each farmer involved in the Test Case (TC) and aims at collecting information that will be used for assessing the impacts of Digital agriculture technology solutions (DATSs).
B5: Table of abbreviations
B6: - | C6: number (1, 2, 3, …)
B7: € | C7: euro
B8: cm3 | C8: cubic centimetre
B9: dm3 | C9: cubic decimetre
B10: g | C10: grams
B11: h | C11: hour
B12: ha | C12: hectare
B13: K | C13: potassium
B14: k€ | C14: kiloeuro (€ 1,000)
B15: kg | C15: kilograms
B16: kWh | C16: kilowatt-hour
B17: l | C17: litre
... B27: y | C27: year

Sheet General Information
A2: Ivaylo Parent | B2: Jack Naming | E2: Question | F2: Unit of measure | G2: Value
B3: testcaseNumber | C3: =CONCATENATE("""",D3,"""",":","""",LOWER(A3),"_",LOWER(B3),"""") -> "G3":"_testcasenumber" | D3: G3 | E3: TC Number | F3: n
B4: testcaseLeader | C4: =CONCATENATE("""",D4,"""",":","""",LOWER(A4),"_",LOWER(B4),"""") -> "G4":"_testcaseleader" | D4: G4 | E4: TC Leader | F4: -
C5: =CONCATENATE("""",D5,"""",":","""",LOWER(A5),"_",LOWER(B5),"""") -> "G5":"_" | D5: G5 | E5: FARM DATA
A6: parcelInformation | B6: cultivationType | C6: =CONCATENATE("""",D6,"""",":","""",LOWER(A6),"_",LOWER(B6),"""") -> "G6":"parcelinformation_cultivationtype" | D6: G6 | E6: Type of output/product | F6: - | G6: Milk
A7: parcelInformation | B7: productType | C7: =CONCATENATE("""",D7,"""",":","""",LOWER(A7),"_",LOWER(B7),"""") -> "G7":"parcelinformation_producttype" | D7: G7 | E7: Crop | F7: - | G7: Apple | H7: of parcel per comparison per year
A8: parcelInformation | B8: productType | C8: =CONCATENATE("""",D8,"""",":","""",LOWER(A8),"_",LOWER(B8),"""") -> "G8":"parcelinformation_producttype" | D8: G8 | E8: Animal | H8: of parcel per comparison per year
A9: parcelInformation | B9: startMonth | C9: =CONCATENATE("""",D9,"""",":","""",LOWER(A9),"_",LOWER(B9),"""") -> "G9":"parcelinformation_startmonth" | D9: G9 | E9: Start of the growing/production season | F9: (gg/mm/yyyy) | H9: of parcel per comparison per year
A10: parcelInformation | B10: endMonth | C10: =CONCATENATE("""",D10,"""",":","""",LOWER(A10),"_",LOWER(B10),"""") -> "G10":"parcelinformation_endmonth" | D10: G10 | E10: End of the growing/production season | F10: (gg/mm/yyyy) | H10: of parcel per comparison per year
A11: parcelInformation | B11: biogeographicalRegion | C11: =CONCATENATE("""",D11,"""",":","""",LOWER(A11),"_",LOWER(B11),"""") -> "G11":"parcelinformation_biogeographicalregion" | D11: G11 | E11: Biogeographical region | F11: - | G11: 1
A12: parcelInformation | B12: totalFarmSize | C12: =CONCATENATE("""",D12,"""",":","""",LOWER(A12),"_",LOWER(B12),"""") -> "G12":"parcelinformation_totalfarmsize" | D12: G12 | E12: Total farm size | F12: ha | G12: 1
A13: parcelInformation | B13: numberOfComparisons | C13: =CONCATENATE("""",D13,"""",":","""",LOWER(A13),"_",LOWER(B13),"""") -> "G13":"parcelinformation_numberofcomparisons" | D13: G13 | E13: Number of comparison(s) | F13: n | G13: 1
A14: parcelInformation | B14: numberOfEmployees | C14: =CONCATENATE("""",D14,"""",":","""",LOWER(A14),"_",LOWER(B14),"""") -> "G14":"parcelinformation_numberofemployees" | D14: G14 | E14: Number of employees | F14: n | G14: 1 | H14: of parcel per comparison per year
A15: parcelInformation | B15: numberofFullTimeEmployees | C15: =CONCATENATE("""",D15,"""",":","""",LOWER(A15),"_",LOWER(B15),"""") -> "G15":"parcelinformation_numberoffulltimeemployees" | D15: G15 | E15: Number of full-time employees | F15: n | G15: 1 | H15: of parcel per comparison per year
A16: parcelInformation | B16: numberOfSeasonalEmployees | C16: =CONCATENATE("""",D16,"""",":","""",LOWER(A16),"_",LOWER(B16),"""") -> "G16":"parcelinformation_numberofseasonalemployees" | D16: G16 | E16: Number of seasonal employees | F16: n | G16: 1 | H16: of parcel per comparison per year
C17: =CONCATENATE("""",D17,"""",":","""",LOWER(A17),"_",LOWER(B17),"""") -> "G17":"_" | D17: G17
C18: =CONCATENATE("""",D18,"""",":","""",LOWER(A18),"_",LOWER(B18),"""") -> "G18":"_" | D18: G18 | E18: DATSs DATA
C19: =CONCATENATE("""",D19,"""",":","""",LOWER(A19),"_",LOWER(B19),"""") -> "G19":"_" | D19: G19 | E19: Question | F19: Unit of measure | G19: Value
A20: datsInformation | B20: datsInitialInvestmentCosts | C20: =CONCATENATE("""",D20,"""",":","""",LOWER(A20),"_",LOWER(B20),"""") -> "G20":"datsinformation_datsinitialinvestmentcosts" | D20: G20 | E20: Initial investment for DATSs (the total for all the solutions assessed in the project) | F20: € | G20: 1
A21: datsInformation | B21: datsExpectedLifespan | C21: =CONCATENATE("""",D21,"""",":","""",LOWER(A21),"_",LOWER(B21),"""") -> "G21":"datsinformation_datsexpectedlifespan" | D21: G21 | E21: Expected life span of each DATSs | F21: y | G21: 1
A22: datsInformation | B22: datsInstallationTime | C22: =CONCATENATE("""",D22,"""",":","""",LOWER(A22),"_",LOWER(B22),"""") -> "G22":"datsinformation_datsinstallationtime" | D22: G22 | E22: Time to install and make DATSs operational | F22: h | G22: 1
A23: datsInformation | B23: datsMaintenanceCosts | C23: =CONCATENATE("""",D23,"""",":","""",LOWER(A23),"_",LOWER(B23),"""") -> "G23":"datsinformation_datsmaintenancecosts" | D23: G23 | E23: DATs maintenance costs | F23: €/y | G23: 1
A24: datsInformation | B24: datsAnnualFees | C24: =CONCATENATE("""",D24,"""",":","""",LOWER(A24),"_",LOWER(B24),"""") -> "G24":"datsinformation_datsannualfees" | D24: G24 | E24: DATS annual fees | F24: €/y | G24: 1
A25: datsInformation | B25: datsTrainingTime | C25: =CONCATENATE("""",D25,"""",":","""",LOWER(A25),"_",LOWER(B25),"""") -> "G25":"datsinformation_datstrainingtime" | D25: G25 | E25: Training hours for the use of the DATSs in a year | F25: h | G25: 1
A26: datsInformation | B26: datsTrainers | C26: =CONCATENATE("""",D26,"""",":","""",LOWER(A26),"_",LOWER(B26),"""") -> "G26":"datsinformation_datstrainers" | D26: G26 | E26: Number of people involved in the training | F26: n | G26: 1
A27: datsInformation | B27: datsTrainingCosts | C27: =CONCATENATE("""",D27,"""",":","""",LOWER(A27),"_",LOWER(B27),"""") -> "G27":"datsinformation_datstrainingcosts" | D27: G27 | E27: Cost of training service by external people (advisor, DATS providers, ...) | F27: €/y | G27: 1
A28: datsInformation | B28: datsName | C28: =CONCATENATE("""",D28,"""",":","""",LOWER(A28),"_",LOWER(B28),"""") -> "G28":"datsinformation_datsname" | D28: G28 | E28: DATSs name | F28: - | G28: 1
C29: =CONCATENATE("""",D29,"""",":","""",LOWER(A29),"_",LOWER(B29),"""") -> "G29":"_" | D29: G29
C30: =CONCATENATE("""",D30,"""",":","""",LOWER(A30),"_",LOWER(B30),"""") -> "G30":"_" | D30: G30 | E30: MARKET DATA FOR DATSs USER
C31: =CONCATENATE("""",D31,"""",":","""",LOWER(A31),"_",LOWER(B31),"""") -> "G31":"_" | D31: G31 | E31: Question | F31: Unit of measure | G31: Value
A32: marketinformation | B32: waterPrice | C32: =CONCATENATE("""",D32,"""",":","""","parcelassessmentwithdats_",LOWER(A32),"_",LOWER(B32),"""") -> "G32":"parcelassessmentwithdats_marketinformation_waterprice" | D32: G32 | E32: Water price | F32: €/m3 | G32: 1
A33: marketinformation | B33: fuelPrice | C33: =CONCATENATE("""",D33,"""",":","""","parcelassessmentwithdats_",LOWER(A33),"_",LOWER(B33),"""") -> "G33":"parcelassessmentwithdats_marketinformation_fuelprice" | D33: G33 | E33: Fuel price | F33: €/l | G33: 1
A34: marketinformation | B34: n_fuel_for_greenhouse | C34: =CONCATENATE("""",D34,"""",":","""","parcelassessmentwithdats_",LOWER(A34),"_",LOWER(B34),"""") -> "G34":"parcelassessmentwithdats_marketinformation_n_fuel_for_greenhouse" | D34: G34 | E34: Number of fuel for greehnouse temperature control price | F34: n | G34: 1
A35: fuelfortemperaturecontrolinformation | B35: productPrice_0 | C35: =CONCATENATE("""",D35,"""",":","""","parcelassessmentwithdats_",LOWER(A35),"_",LOWER(B35),"""") -> "G35":"parcelassessmentwithdats_fuelfortemperaturecontrolinformation_productprice_0" | D35: G35 | E35: Fuel 1 for greehnouse temperature control price | F35: €/m3 | G35: 1
A36: fuelfortemperaturecontrolinformation | B36: productPrice_1 | C36: =CONCATENATE("""",D36,"""",":","""","parcelassessmentwithdats_",LOWER(A36),"_",LOWER(B36),"""") -> "G36":"parcelassessmentwithdats_fuelfortemperaturecontrolinformation_productprice_1" | D36: G36 | E36: Fuel 2 for greehnouse temperature control price | F36: €/m3 | G36: 1
A37: fuelfortemperaturecontrolinformation | B37: productPrice_2 | C37: =CONCATENATE("""",D37,"""",":","""","parcelassessmentwithdats_",LOWER(A37),"_",LOWER(B37),"""") -> "G37":"parcelassessmentwithdats_fuelfortemperaturecontrolinformation_productprice_2" | D37: G37 | E37: Fuel 3 for greehnouse temperature control price | F37: €/m3 | G37: 1
A38: fuelfortemperaturecontrolinformation | B38: productPrice_3 | C38: =CONCATENATE("""",D38,"""",":","""","parcelassessmentwithdats_",LOWER(A38),"_",LOWER(B38),"""") -> "G38":"parcelassessmentwithdats_fuelfortemperaturecontrolinformation_productprice_3" | D38: G38 | E38: Fuel 1 for greehnouse temperature control price | F38: €/m3 | G38: 1
A39: fuelfortemperaturecontrolinformation | B39: productPrice_4 | C39: =CONCATENATE("""",D39,"""",":","""","parcelassessmentwithdats_",LOWER(A39),"_",LOWER(B39),"""") -> "G39":"parcelassessmentwithdats_fuelfortemperaturecontrolinformation_productprice_4" | D39: G39 | E39: Fuel 1 for greehnouse temperature control price | F39: €/m3 | G39: 1
A40: fuelfortemperaturecontrolinformation | B40: productPrice_5 | C40: =CONCATENATE("""",D40,"""",":","""","parcelassessmentwithdats_",LOWER(A40),"_",LOWER(B40),"""") -> "G40":"parcelassessmentwithdats_fuelfortemperaturecontrolinformation_productprice_5" | D40: G40 | E40: Fuel 2 for greehnouse temperature control price | F40: €/m3 | G40: 1
A41: fuelfortemperaturecontrolinformation | B41: productPrice_6 | C41: =CONCATENATE("""",D41,"""",":","""","parcelassessmentwithdats_",LOWER(A41),"_",LOWER(B41),"""") -> "G41":"parcelassessmentwithdats_fuelfortemperaturecontrolinformation_productprice_6" | D41: G41 | E41: Fuel 3 for greehnouse temperature control price | F41: €/m3 | G41: 1
...

Sheet Parcel 1 with DATSs
BJ1: yes
K2: PARCEL WITH DATSs | BJ2: no
G4: Identification | H4: Parcel Name
A9: Ivaylo Parent | B9: Jack Naming | G9: data | H9: u.m. | K9: value | L9: value
A10: parcelInformation | B10: parcelDimension | C10: =CONCATENATE("""",D10,"""",":","""","parcelassessmentwithdats_",LOWER($A10),"_",LOWER($B10),"""") -> "J10":"parcelassessmentwithdats_parcelinformation_parceldimension" | D10: J10 | E10: =CONCATENATE("""",F10,"""",":","""","parcelassessmentwithdats_",LOWER(A10),"_",LOWER(B10),"""") -> "K10":"parcelassessmentwithdats_parcelinformation_parceldimension" | F10: K10 | G10: Parcel dimension | H10: ha | I10: =CONCATENATE("""",J10,"""",":","""","parcelassessmentwithoutdats_",LOWER($A10),"_",LOWER($B10),"""") -> "L10":"parcelassessmentwithoutdats_parcelinformation_parceldimension" | J10: L10 | K10: 1 | L10: 1
A11: parcelInformation | B11: numberOfPlants | C11: =CONCATENATE("""",D11,"""",":","""","parcelassessmentwithdats_",LOWER($A11),"_",LOWER($B11),"""") -> "J11":"parcelassessmentwithdats_parcelinformation_numberofplants" | D11: J11 | E11: =CONCATENATE("""",F11,"""",":","""","parcelassessmentwithdats_",LOWER(A11),"_",LOWER(B11),"""") -> "K11":"parcelassessmentwithdats_parcelinformation_numberofplants" | F11: K11 | G11: Number of plants/trees | H11: n | I11: =CONCATENATE("""",J11,"""",":","""","parcelassessmentwithoutdats_",LOWER($A11),"_",LOWER($B11),"""") -> "L11":"parcelassessmentwithoutdats_parcelinformation_numberofplants" | J11: L11 | K11: 1 | L11: 1
A12: parcelInformation | B12: soilFractionSand | C12: =CONCATENATE("""",D12,"""",":","""","parcelassessmentwithdats_",LOWER($A12),"_",LOWER($B12),"""") -> "J12":"parcelassessmentwithdats_parcelinformation_soilfractionsand" | D12: J12 | E12: =CONCATENATE("""",F12,"""",":","""","parcelassessmentwithdats_",LOWER(A12),"_",LOWER(B12),"""") -> "K12":"parcelassessmentwithdats_parcelinformation_soilfractionsand" | F12: K12 | G12: Sand content in the soil | H12: % | I12: =CONCATENATE("""",J12,"""",":","""","parcelassessmentwithoutdats_",LOWER($A12),"_",LOWER($B12),"""") -> "L12":"parcelassessmentwithoutdats_parcelinformation_soilfractionsand" | J12: L12 | K12: 1 | L12: 1
A13: parcelInformation | B13: soilFractionClay | C13: =CONCATENATE("""",D13,"""",":","""","parcelassessmentwithdats_",LOWER($A13),"_",LOWER($B13),"""") -> "J13":"parcelassessmentwithdats_parcelinformation_soilfractionclay" | D13: J13 | E13: =CONCATENATE("""",F13,"""",":","""","parcelassessmentwithdats_",LOWER(A13),"_",LOWER(B13),"""") -> "K13":"parcelassessmentwithdats_parcelinformation_soilfractionclay" | F13: K13 | G13: Clay content in the soil | H13: % | I13: =CONCATENATE("""",J13,"""",":","""","parcelassessmentwithoutdats_",LOWER($A13),"_",LOWER($B13),"""") -> "L13":"parcelassessmentwithoutdats_parcelinformation_soilfractionclay" | J13: L13 | K13: 1 | L13: 1
A14: parcelInformation | B14: soilFractionSilt | C14: =CONCATENATE("""",D14,"""",":","""","parcelassessmentwithdats_",LOWER($A14),"_",LOWER($B14),"""") -> "J14":"parcelassessmentwithdats_parcelinformation_soilfractionsilt" | D14: J14 | E14: =CONCATENATE("""",F14,"""",":","""","parcelassessmentwithdats_",LOWER(A14),"_",LOWER(B14),"""") -> "K14":"parcelassessmentwithdats_parcelinformation_soilfractionsilt" | F14: K14 | G14: Silt content in the soil | H14: % | I14: =CONCATENATE("""",J14,"""",":","""","parcelassessmentwithoutdats_",LOWER($A14),"_",LOWER($B14),"""") -> "L14":"parcelassessmentwithoutdats_parcelinformation_soilfractionsilt" | J14: L14 | K14: 1 | L14: 1
A15: parcelInformation | B15: bulkDensity | C15: =CONCATENATE("""",D15,"""",":","""","parcelassessmentwithdats_",LOWER($A15),"_",LOWER($B15),"""") -> "J15":"parcelassessmentwithdats_parcelinformation_bulkdensity" | D15: J15 | E15: =CONCATENATE("""",F15,"""",":","""","parcelassessmentwithdats_",LOWER(A15),"_",LOWER(B15),"""") -> "K15":"parcelassessmentwithdats_parcelinformation_bulkdensity" | F15: K15 | G15: Soil Bulk Density | H15: g/cm3 | I15: =CONCATENATE("""",J15,"""",":","""","parcelassessmentwithoutdats_",LOWER($A15),"_",LOWER($B15),"""") -> "L15":"parcelassessmentwithoutdats_parcelinformation_bulkdensity" | J15: L15 | K15: 1 | L15: 1
A16: parcelInformation | B16: soilOrganicCarbon | C16: =CONCATENATE("""",D16,"""",":","""","parcelassessmentwithdats_",LOWER($A16),"_",LOWER($B16),"""") -> "J16":"parcelassessmentwithdats_parcelinformation_soilorganiccarbon" | D16: J16 | E16: =CONCATENATE("""",F16,"""",":","""","parcelassessmentwithdats_",LOWER(A16),"_",LOWER(B16),"""") -> "K16":"parcelassessmentwithdats_parcelinformation_soilorganiccarbon" | F16: K16 | G16: Soil Organic Carbon | H16: % | I16: =CONCATENATE("""",J16,"""",":","""","parcelassessmentwithoutdats_",LOWER($A16),"_",LOWER($B16),"""") -> "L16":"parcelassessmentwithoutdats_parcelinformation_soilorganiccarbon" | J16: L16 | K16: 1 | L16: 1
A17: parcelInformation | B17: numberOfAnimals | C17: =CONCATENATE("""",D17,"""",":","""","parcelassessmentwithdats_",LOWER($A17),"_",LOWER($B17),"""") -> "J17":"parcelassessmentwithdats_parcelinformation_numberofanimals" | D17: J17 | E17: =CONCATENATE("""",F17,"""",":","""","parcelassessmentwithdats_",LOWER(A17),"_",LOWER(B17),"""") -> "K17":"parcelassessmentwithdats_parcelinformation_numberofanimals" | F17: K17 | G17: Number of animals | H17: n | I17: =CONCATENATE("""",J17,"""",":","""","parcelassessmentwithoutdats_",LOWER($A17),"_",LOWER($B17),"""") -> "L17":"parcelassessmentwithoutdats_parcelinformation_numberofanimals" | J17: L17 | K17: 1 | L17: 1
A18: parcelInformation | B18: livestockUnits | C18: =CONCATENATE("""",D18,"""",":","""","parcelassessmentwithdats_",LOWER($A18),"_",LOWER($B18),"""") -> "J18":"parcelassessmentwithdats_parcelinformation_livestockunits" | D18: J18 | E18: =CONCATENATE("""",F18,"""",":","""","parcelassessmentwithdats_",LOWER(A18),"_",LOWER(B18),"""") -> "K18":"parcelassessmentwithdats_parcelinformation_livestockunits" | F18: K18 | G18: Livestock units per hectare | H18: LSU/ha | I18: =CONCATENATE("""",J18,"""",":","""","parcelassessmentwithoutdats_",LOWER($A18),"_",LOWER($B18),"""") -> "L18":"parcelassessmentwithoutdats_parcelinformation_livestockunits" | J18: L18 | K18: 1 | L18: 1
A19: parcelInformation | B19: numberOfBeehives | C19: =CONCATENATE("""",D19,"""",":","""","parcelassessmentwithdats_",LOWER($A19),"_",LOWER($B19),"""") -> "J19":"parcelassessmentwithdats_parcelinformation_numberofbeehives" | D19: J19 | E19: =CONCATENATE("""",F19,"""",":","""","parcelassessmentwithdats_",LOWER(A19),"_",LOWER(B19),"""") -> "K19":"parcelassessmentwithdats_parcelinformation_numberofbeehives" | F19: K19 | G19: Number of beehives | H19: n | I19: =CONCATENATE("""",J19,"""",":","""","parcelassessmentwithoutdats_",LOWER($A19),"_",LOWER($B19),"""") -> "L19":"parcelassessmentwithoutdats_parcelinformation_numberofbeehives" | J19: L19 | K19: 1 | L19: 1
A20: parcelInformation | B20: aquacultureArea | C20: =CONCATENATE("""",D20,"""",":","""","parcelassessmentwithdats_",LOWER($A20),"_",LOWER($B20),"""") -> "J20":"parcelassessmentwithdats_parcelinformation_aquaculturearea" | D20: J20 | E20: =CONCATENATE("""",F20,"""",":","""","parcelassessmentwithdats_",LOWER(A20),"_",LOWER(B20),"""") -> "K20":"parcelassessmentwithdats_parcelinformation_aquaculturearea" | F20: K20 | G20: Area under aquaculture | H20: m2 | I20: =CONCATENATE("""",J20,"""",":","""","parcelassessmentwithoutdats_",LOWER($A20),"_",LOWER($B20),"""") -> "L20":"parcelassessmentwithoutdats_parcelinformation_aquaculturearea" | J20: L20 | K20: 1 | L20: 1
C21: =CONCATENATE("""",D21,"""",":","""","parcelassessmentwithdats_",LOWER($A21),"_",LOWER($B21),"""") -> "J21":"parcelassessmentwithdats__" | D21: J21 | E21: =CONCATENATE("""",F21,"""",":","""","parcelassessmentwithdats_",LOWER(A21),"_",LOWER(B21),"""") -> "K21":"parcelassessmentwithdats__" | F21: K21 | I21: =CONCATENATE("""",J21,"""",":","""","parcelassessmentwithoutdats_",LOWER($A21),"_",LOWER($B21),"""") -> "L21":"parcelassessmentwithoutdats__" | J21: L21
C22: =CONCATENATE("""",D22,"""",":","""","parcelassessmentwithdats_",LOWER($A22),"_",LOWER($B22),"""") -> "J22":"parcelassessmentwithdats__" | D22: J22 | E22: =CONCATENATE("""",F22,"""",":","""","parcelassessmentwithdats_",LOWER(A22),"_",LOWER(B22),"""") -> "K22":"parcelassessmentwithdats__" | F22: K22 | I22: =CONCATENATE("""",J22,"""",":","""","parcelassessmentwithoutdats_",LOWER($A22),"_",LOWER($B22),"""") -> "L22":"parcelassessmentwithoutdats__" | J22: L22 | K22: Year 1 | L22: Year 1 | N22: Year 2 | Q22: Year 3
C23: =CONCATENATE("""",D23,"""",":","""","parcelassessmentwithdats_",LOWER($A23),"_",LOWER($B23),"""") -> "J23":"parcelassessmentwithdats__" | D23: J23 | E23: =CONCATENATE("""",F23,"""",":","""","parcelassessmentwithdats_",LOWER(A23),"_",LOWER(B23),"""") -> "K23":"parcelassessmentwithdats__" | F23: K23 | G23: data | H23: u.m. | I23: =CONCATENATE("""",J23,"""",":","""","parcelassessmentwithoutdats_",LOWER($A23),"_",LOWER($B23),"""") -> "L23":"parcelassessmentwithoutdats__" | J23: L23 | K23: With DATSs | L23: With DATSs | N23: With DATSs | O23: Notes | Q23: With DATSs | R23: Notes
A24: waterUsageInformation | B24: waterUsageForIrrigation | C24: =CONCATENATE("""",D24,"""",":","""","parcelassessmentwithdats_",LOWER($A24),"_",LOWER($B24),"""") -> "J24":"parcelassessmentwithdats_waterusageinformation_waterusageforirrigation" | D24: J24 | E24: =CONCATENATE("""",F24,"""",":","""","parcelassessmentwithdats_",LOWER(A24),"_",LOWER(B24),"""") -> "K24":"parcelassessmentwithdats_waterusageinformation_waterusageforirrigation" | F24: K24 | G24: Irrigation | H24: m3 | I24: =CONCATENATE("""",J24,"""",":","""","parcelassessmentwithoutdats_",LOWER($A24),"_",LOWER($B24),"""") -> "L24":"parcelassessmentwithoutdats_waterusageinformation_waterusageforirrigation" | J24: L24 | K24: 1 | L24: 1
A25: waterUsageInformation | B25: waterUsageForFertigation | C25: =CONCATENATE("""",D25,"""",":","""","parcelassessmentwithdats_",LOWER($A25),"_",LOWER($B25),"""") -> "J25":"parcelassessmentwithdats_waterusageinformation_waterusageforfertigation" | D25: J25 | E25: =CONCATENATE("""",F25,"""",":","""","parcelassessmentwithdats_",LOWER(A25),"_",LOWER(B25),"""") -> "K25":"parcelassessmentwithdats_waterusageinformation_waterusageforfertigation" | F25: K25 | G25: Fertigation | H25: m3 | I25: =CONCATENATE("""",J25,"""",":","""","parcelassessmentwithoutdats_",LOWER($A25),"_",LOWER($B25),"""") -> "L25":"parcelassessmentwithoutdats_waterusageinformation_waterusageforfertigation" | J25: L25 | K25: 1 | L25: 1
A26: waterUsageInformation | B26: waterUsageForPestDilution | C26: =CONCATENATE("""",D26,"""",":","""","parcelassessmentwithdats_",LOWER($A26),"_",LOWER($B26),"""") -> "J26":"parcelassessmentwithdats_waterusageinformation_waterusageforpestdilution" | D26: J26 | E26: =CONCATENATE("""",F26,"""",":","""","parcelassessmentwithdats_",LOWER(A26),"_",LOWER(B26),"""") -> "K26":"parcelassessmentwithdats_waterusageinformation_waterusageforpestdilution" | F26: K26 | G26: Pest dilution | H26: m3 | I26: =CONCATENATE("""",J26,"""",":","""","parcelassessmentwithoutdats_",LOWER($A26),"_",LOWER($B26),"""") -> "L26":"parcelassessmentwithoutdats_waterusageinformation_waterusageforpestdilution" | J26: L26 | K26: 1 | L26: 1
A27: waterUsageInformation | B27: waterUsageForCleaning | C27: =CONCATENATE("""",D27,"""",":","""","parcelassessmentwithdats_",LOWER($A27),"_",LOWER($B27),"""") -> "J27":"parcelassessmentwithdats_waterusageinformation_waterusageforcleaning" | D27: J27 | E27: =CONCATENATE("""",F27,"""",":","""","parcelassessmentwithdats_",LOWER(A27),"_",LOWER(B27),"""") -> "K27":"parcelassessmentwithdats_waterusageinformation_waterusageforcleaning" | F27: K27 | G27: Cleaning | H27: m3 | I27: =CONCATENATE("""",J27,"""",":","""","parcelassessmentwithoutdats_",LOWER($A27),"_",LOWER($B27),"""") -> "L27":"parcelassessmentwithoutdats_waterusageinformation_waterusageforcleaning" | J27: L27 | K27: 1 | L27: 1
A28: waterUsageInformation | B28: waterUsageForDrinking | C28: =CONCATENATE("""",D28,"""",":","""","parcelassessmentwithdats_",LOWER($A28),"_",LOWER($B28),"""") -> "J28":"parcelassessmentwithdats_waterusageinformation_waterusagefordrinking" | D28: J28 | E28: =CONCATENATE("""",F28,"""",":","""","parcelassessmentwithdats_",LOWER(A28),"_",LOWER(B28),"""") -> "K28":"parcelassessmentwithdats_waterusageinformation_waterusagefordrinking" | F28: K28 | G28: Drinking | H28: m3 | I28: =CONCATENATE("""",J28,"""",":","""","parcelassessmentwithoutdats_",LOWER($A28),"_",LOWER($B28),"""") -> "L28":"parcelassessmentwithoutdats_waterusageinformation_waterusagefordrinking" | J28: L28 | K28: 1 | L28: 1
A29: waterUsageInformation | B29: totalWaterUsage | C29: =CONCATENATE("""",D29,"""",":","""","parcelassessmentwithdats_",LOWER($A29),"_",LOWER($B29),"""") -> "J29":"parcelassessmentwithdats_waterusageinformation_totalwaterusage" | D29: J29 | E29: =CONCATENATE("""",F29,"""",":","""","parcelassessmentwithdats_",LOWER(A29),"_",LOWER(B29),"""") -> "K29":"parcelassessmentwithdats_waterusageinformation_totalwaterusage" | F29: K29 | G29: Total water used | H29: m3 | I29: =CONCATENATE("""",J29,"""",":","""","parcelassessmentwithoutdats_",LOWER($A29),"_",LOWER($B29),"""") -> "L29":"parcelassessmentwithoutdats_waterusageinformation_totalwaterusage" | J29: L29 | K29: 1 | L29: 1
C30: =CONCATENATE("""",D30,"""",":","""","parcelassessmentwithdats_",LOWER($A30),"_",LOWER($B30),"""") -> "J30":"parcelassessmentwithdats__" | D30: J30 | E30: =CONCATENATE("""",F30,"""",":","""","parcelassessmentwithdats_",LOWER(A30),"_",LOWER(B30),"""") -> "K30":"parcelassessmentwithdats__" | F30: K30 | I30: =CONCATENATE("""",J30,"""",":","""","parcelassessmentwithoutdats_",LOWER($A30),"_",LOWER($B30),"""") -> "L30":"parcelassessmentwithoutdats__" | J30: L30
C31: =CONCATENATE("""",D31,"""",":","""","parcelassessmentwithdats_",LOWER($A31),"_",LOWER($B31),"""") -> "J31":"parcelassessmentwithdats__" | D31: J31 | E31: =CONCATENATE("""",F31,"""",":","""","parcelassessmentwithdats_",LOWER(A31),"_",LOWER(B31),"""") -> "K31":"parcelassessmentwithdats__" | F31: K31 | I31: =CONCATENATE("""",J31,"""",":","""","parcelassessmentwithoutdats_",LOWER($A31),"_",LOWER($B31),"""") -> "L31":"parcelassessmentwithoutdats__" | J31: L31 | K31: Year 1 | L31: Year 1 | N31: Year 2 | Q31: Year 3
C32: =CONCATENATE("""",D32,"""",":","""","parcelassessmentwithdats_",LOWER($A32),"_",LOWER($B32),"""") -> "J32":"parcelassessmentwithdats__" | D32: J32 | E32: =CONCATENATE("""",F32,"""",":","""","parcelassessmentwithdats_",LOWER(A32),"_",LOWER(B32),"""") -> "K32":"parcelassessmentwithdats__" | F32: K32 | G32: data | H32: u.m. | I32: =CONCATENATE("""",J32,"""",":","""","parcelassessmentwithoutdats_",LOWER($A32),"_",LOWER($B32),"""") -> "L32":"parcelassessmentwithoutdats__" | J32: L32 | K32: With DATSs | L32: Without DATSs | N32: With DATSs | O32: Notes | Q32: With DATSs | R32: Notes
A33: fuelUsageInformation | B33: fuelUsageForFertilisation | C33: =CONCATENATE("""",D33,"""",":","""","parcelassessmentwithdats_",LOWER($A33),"_",LOWER($B33),"""") -> "J33":"parcelassessmentwithdats_fuelusageinformation_fuelusageforfertilisation" | D33: J33 | E33: =CONCATENATE("""",F33,"""",":","""","parcelassessmentwithdats_",LOWER(A33),"_",LOWER(B33),"""") -> "K33":"parcelassessmentwithdats_fuelusageinformation_fuelusageforfertilisation" | F33: K33 | G33: Fertilisation | H33: l | I33: =CONCATENATE("""",J33,"""",":","""","parcelassessmentwithoutdats_",LOWER($A33),"_",LOWER($B33),"""") -> "L33":"parcelassessmentwithoutdats_fuelusageinformation_fuelusageforfertilisation" | J33: L33 | K33: 1 | L33: 1
A34: fuelUsageInformation | B34: fuelUsageForPesticides | C34: =CONCATENATE("""",D34,"""",":","""","parcelassessmentwithdats_",LOWER($A34),"_",LOWER($B34),"""") -> "J34":"parcelassessmentwithdats_fuelusageinformation_fuelusageforpesticides" | D34: J34 | E34: =CONCATENATE("""",F34,"""",":","""","parcelassessmentwithdats_",LOWER(A34),"_",LOWER(B34),"""") -> "K34":"parcelassessmentwithdats_fuelusageinformation_fuelusageforpesticides" | F34: K34 | G34: Pesticides | H34: l | I34: =CONCATENATE("""",J34,"""",":","""","parcelassessmentwithoutdats_",LOWER($A34),"_",LOWER($B34),"""") -> "L34":"parcelassessmentwithoutdats_fuelusageinformation_fuelusageforpesticides" | J34: L34 | K34: 1 | L34: 1
A35: fuelUsageInformation | B35: fuelUsageForIrrigation | C35: =CONCATENATE("""",D35,"""",":","""","parcelassessmentwithdats_",LOWER($A35),"_",LOWER($B35),"""") -> "J35":"parcelassessmentwithdats_fuelusageinformation_fuelusageforirrigation" | D35: J35 | E35: =CONCATENATE("""",F35,"""",":","""","parcelassessmentwithdats_",LOWER(A35),"_",LOWER(B35),"""") -> "K35":"parcelassessmentwithdats_fuelusageinformation_fuelusageforirrigation" | F35: K35 | G35: Irrigation | H35: l | I35: =CONCATENATE("""",J35,"""",":","""","parcelassessmentwithoutdats_",LOWER($A35),"_",LOWER($B35),"""") -> "L35":"parcelassessmentwithoutdats_fuelusageinformation_fuelusageforirrigation" | J35: L35 | K35: 1 | L35: 1
A36: fuelUsageInformation | B36: fuelUsageForSowing | C36: =CONCATENATE("""",D36,"""",":","""","parcelassessmentwithdats_",LOWER($A36),"_",LOWER($B36),"""") -> "J36":"parcelassessmentwithdats_fuelusageinformation_fuelusageforsowing" | D36: J36 | E36: =CONCATENATE("""",F36,"""",":","""","parcelassessmentwithdats_",LOWER(A36),"_",LOWER(B36),"""") -> "K36":"parcelassessmentwithdats_fuelusageinformation_fuelusageforsowing" | F36: K36 | G36: Sowing / Planting | H36: l | I36: =CONCATENATE("""",J36,"""",":","""","parcelassessmentwithoutdats_",LOWER($A36),"_",LOWER($B36),"""") -> "L36":"parcelassessmentwithoutdats_fuelusageinformation_fuelusageforsowing" | J36: L36 | K36: 1 | L36: 1
A37: fuelUsageInformation | B37: fuelUsageForPruning | C37: =CONCATENATE("""",D37,"""",":","""","parcelassessmentwithdats_",LOWER($A37),"_",LOWER($B37),"""") -> "J37":"parcelassessmentwithdats_fuelusageinformation_fuelusageforpruning" | D37: J37 | E37: =CONCATENATE("""",F37,"""",":","""","parcelassessmentwithdats_",LOWER(A37),"_",LOWER(B37),"""") -> "K37":"parcelassessmentwithdats_fuelusageinformation_fuelusageforpruning" | F37: K37 | G37: Temperature and Humidity Control | H37: l | I37: =CONCATENATE("""",J37,"""",":","""","parcelassessmentwithoutdats_",LOWER($A37),"_",LOWER($B37),"""") -> "L37":"parcelassessmentwithoutdats_fuelusageinformation_fuelusageforpruning" | J37: L37 | K37: 1 | L37: 1
A38: fuelUsageInformation | B38: fuelUsageForTemperatureHumidityControl | C38: =CONCATENATE("""",D38,"""",":","""","parcelassessmentwithdats_",LOWER($A38),"_",LOWER($B38),"""") -> "J38":"parcelassessmentwithdats_fuelusageinformation_fuelusagefortemperaturehumiditycontrol" | D38: J38 | E38: =CONCATENATE("""",F38,"""",":","""","parcelassessmentwithdats_",LOWER(A38),"_",LOWER(B38),"""") -> "K38":"parcelassessmentwithdats_fuelusageinformation_fuelusagefortemperaturehumiditycontrol" | F38: K38 | G38: Pruning | H38: l | I38: =CONCATENATE("""",J38,"""",":","""","parcelassessmentwithoutdats_",LOWER($A38),"_",LOWER($B38),"""") -> "L38":"parcelassessmentwithoutdats_fuelusageinformation_fuelusagefortemperaturehumiditycontrol" | J38: L38 | K38: 1 | L38: 1
A39: fuelUsageInformation | B39: fuelUsageForBeehivesVisits | C39: =CONCATENATE("""",D39,"""",":","""","parcelassessmentwithdats_",LOWER($A39),"_",LOWER($B39),"""") -> "J39":"parcelassessmentwithdats_fuelusageinformation_fuelusageforbeehivesvisits" | D39: J39 | E39: =CONCATENATE("""",F39,"""",":","""","parcelassessmentwithdats_",LOWER(A39),"_",LOWER(B39),"""") -> "K39":"parcelassessmentwithdats_fuelusageinformation_fuelusageforbeehivesvisits" | F39: K39 | G39: Beehives visits | H39: l | I39: =CONCATENATE("""",J39,"""",":","""","parcelassessmentwithoutdats_",LOWER($A39),"_",LOWER($B39),"""") -> "L39":"parcelassessmentwithoutdats_fuelusageinformation_fuelusageforbeehivesvisits" | J39: L39 | K39: 1 | L39: 1
A40: fuelUsageInformation | B40: fuelUsageForTransportingOysters | C40: =CONCATENATE("""",D40,"""",":","""","parcelassessmentwithdats_",LOWER($A40),"_",LOWER($B40),"""") -> "J40":"parcelassessmentwithdats_fuelusageinformation_fuelusagefortransportingoysters" | D40: J40 | E40: =CONCATENATE("""",F40,"""",":","""","parcelassessmentwithdats_",LOWER(A40),"_",LOWER(B40),"""") -> "K40":"parcelassessmentwithdats_fuelusageinformation_fuelusagefortransportingoysters" | F40: K40 | G40: Transporting oysters to the laboratory | H40: l | I40: =CONCATENATE("""",J40,"""",":","""","parcelassessmentwithoutdats_",LOWER($A40),"_",LOWER($B40),"""") -> "L40":"parcelassessmentwithoutdats_fuelusageinformation_fuelusagefortransportingoysters" | J40: L40 | K40: 1 | L40: 1
A41: fuelUsageInformation | B41: fuelUsageForMilking | C41: =CONCATENATE("""",D41,"""",":","""","parcelassessmentwithdats_",LOWER($A41),"_",LOWER($B41),"""") -> "J41":"parcelassessmentwithdats_fuelusageinformation_fuelusageformilking" | D41: J41 | E41: =CONCATENATE("""",F41,"""",":","""","parcelassessmentwithdats_",LOWER(A41),"_",LOWER(B41),"""") -> "K41":"parcelassessmentwithdats_fuelusageinformation_fuelusageformilking" | F41: K41 | G41: Milking | H41: l | I41: =CONCATENATE("""",J41,"""",":","""","parcelassessmentwithoutdats_",LOWER($A41),"_",LOWER($B41),"""") -> "L41":"parcelassessmentwithoutdats_fuelusageinformation_fuelusageformilking" | J41: L41 | K41: 1 | L41: 1
A42: fuelUsageInformation | B42: fuelUsageForFeeding | C42: =CONCATENATE("""",D42,"""",":","""","parcelassessmentwithdats_",LOWER($A42),"_",LOWER($B42),"""") -> "J42":"parcelassessmentwithdats_fuelusageinformation_fuelusageforfeeding" | D42: J42 | E42: =CONCATENATE("""",F42,"""",":","""","parcelassessmentwithdats_",LOWER(A42),"_",LOWER(B42),"""") -> "K42":"parcelassessmentwithdats_fuelusageinformation_fuelusageforfeeding" | F42: K42 | G42: Feeding | H42: l | I42: =CONCATENATE("""",J42,"""",":","""","parcelassessmentwithoutdats_",LOWER($A42),"_",LOWER($B42),"""") -> "L42":"parcelassessmentwithoutdats_fuelusageinformation_fuelusageforfeeding" | J42: L42 | K42: 1 | L42: 1
A43: fuelUsageInformation | B43: totalFuelUsage | C43: =CONCATENATE("""",D43,"""",":","""","parcelassessmentwithdats_",LOWER($A43),"_",LOWER($B43),"""") -> "J43":"parcelassessmentwithdats_fuelusageinformation_totalfuelusage" | D43: J43 | E43: =CONCATENATE("""",F43,"""",":","""","parcelassessmentwithdats_",LOWER(A43),"_",LOWER(B43),"""") -> "K43":"parcelassessmentwithdats_fuelusageinformation_totalfuelusage" | F43: K43 | G43: Total fuel used | H43: l | I43: =CONCATENATE("""",J43,"""",":","""","parcelassessmentwithoutdats_",LOWER($A43),"_",LOWER($B43),"""") -> "L43":"parcelassessmentwithoutdats_fuelusageinformation_totalfuelusage" | J43: L43 | K43: 1 | L43: 1
C44: =CONCATENATE("""",D44,"""",":","""","parcelassessmentwithdats_",LOWER($A44),"_",LOWER($B44),"""") -> "J44":"parcelassessmentwithdats__" | D44: J44 | E44: =CONCATENATE("""",F44,"""",":","""","parcelassessmentwithdats_",LOWER(A44),"_",LOWER(B44),"""") -> "K44":"parcelassessmentwithdats__" | F44: K44 | I44: =CONCATENATE("""",J44,"""",":","""","parcelassessmentwithoutdats_",LOWER($A44),"_",LOWER($B44),"""") -> "L44":"parcelassessmentwithoutdats__" | J44: L44
C45: =CONCATENATE("""",D45,"""",":","""","parcelassessmentwithdats_",LOWER($A45),"_",LOWER($B45),"""") -> "J45":"parcelassessmentwithdats__" | D45: J45 | E45: =CONCATENATE("""",F45,"""",":","""","parcelassessmentwithdats_",LOWER(A45),"_",LOWER(B45),"""") -> "K45":"parcelassessmentwithdats__" | F45: K45 | I45: =CONCATENATE("""",J45,"""",":","""","parcelassessmentwithoutdats_",LOWER($A45),"_",LOWER($B45),"""") -> "L45":"parcelassessmentwithoutdats__" | J45: L45 | K45: Year 1 | L45: Year 1 | N45: Year 2 | Q45: Year 3
...

Sheet Parcel 1 without DATSs
BA1: yes
G2: PARCEL WITHOUT DATSs | BA2: no
C4: Identification | D4: Parcel Name
B8: Information about the TC
B9: # | C9: data | D9: u.m. | E9: value | G9: Notes
B10: 1 | C10: Parcel dimension | D10: ha | E10: 1
B11: 2 | C11: Number of plants/trees | D11: n | E11: 1
B12: 3 | C12: Sand content in the soil | D12: % | E12: 1
B13: 4 | C13: Clay content in the soil | D13: % | E13: 1
B14: 5 | C14: Silt content in the soil | D14: % | E14: 1
B15: 6 | C15: Soil Bulk Density | D15: g/cm3 | E15: 1
B16: 7 | C16: Soil Organic Carbon | D16: % | E16: 1
B17: 8 | C17: Number of animals | D17: n | E17: 1
B18: 9 | C18: Livestock units per hectare | D18: LSU/ha | E18: 1
B19: 10 | C19: Number of beehives | D19: n | E19: 1
B20: 11 | C20: Area under aquaculture | D20: m2 | E20: 1
B22: WATER | G22: Year 1
B23: # | C23: data | D23: u.m. | G23: Without DATSs | H23: Notes
B24: 12 | C24: Irrigation | D24: m3 | G24: 1
B25: 13 | C25: Fertigation | D25: m3 | G25: 1
B26: 14 | C26: Pest dilution | D26: m3 | G26: 1
B27: 15 | C27: Cleaning | D27: m3 | G27: 1
B28: 16 | C28: Drinking | D28: m3 | G28: 1
B29: 17 | C29: or Total water used | D29: m3 | G29: 1
B31: FUEL | G31: Year 1
B32: # | C32: data | D32: u.m. | G32: Without DATSs | H32: Notes
B33: 18 | C33: Fertilisation | D33: l | G33: 1
B34: 19 | C34: Pesticides | D34: l | G34: 1
B35: 20 | C35: Irrigation | D35: l | G35: 1
B36: 21 | C36: Sowing / Planting | D36: l | G36: 1
B37: 22 | C37: Temperature and Humidity Control | D37: l | G37: 1
B38: 23 | C38: Pruning | D38: l | G38: 1
B39: 24 | C39: Beehives visits | D39: l | G39: 1
B40: 25 | C40: Transporting oysters to the laboratory | D40: l | G40: 1
B41: 26 | C41: Milking | D41: l | G41: 1
B42: 27 | C42: Feeding | D42: l | G42: 1
B43: 28 | C43: or Total fuel used | D43: l | G43: 1
B45: FUEL FOR GREENHOUSE TEMPERATURE CONTROL | G45: Year 1
B46: # | C46: data | E46: u.m. | G46: Without DATSs | H46: Notes
B47: 29 | C47: Fuel 1 | D47: Name fuel 1 | G47: 1
...

Sheet Cost-revenue DATS
A1: COST ANALYSIS
A2: INPUT | B2: INDICATOR | C2: SCENARIO | D2: UoM | E2: TOTAL | F2: FORMULAS
A3: WATER | B3: Cost of water | C3: With DATs | D3: =IFERROR(VLOOKUP('General Information'!$G$6, Convalide!$L$2:$M$8, 2,FALSE), "") -> €/l milk | E3: =('Parcel 1 with DATSs'!K29*'General Information'!G32)/(IF('General Information'!G6="crop",'Parcel 1 with DATSs'!K10,IF('General Information'!G6="milk",'Parcel 1 with DATSs'!K241,IF('General Information'!G6="meat",'Parcel 1 with DATSs'!K242,IF('General Information'!G6="animal",'Parcel 1 with DATSs'!K243,IF('General Information'!G6="oyster",'Parcel 1 with DATSs'!K244,IF('General Information'!G6="honey",'Parcel 1 with DATSs'!K245,'Parcel 1 with DATSs'!K246))))))) -> 1 | F3: IF(Total water used>0; (Total water used * water price)/Parcel dimension; Sum(water Irrigation+ water Fertigation + water Pest dilution + …) * water price) | G3: =CONCATENATE("cost revenue dats","_",$A$1,"_",A3,"_",B3) -> cost revenue dats_COST ANALYSIS_WATER _Cost of water | H3: E3
A4: FUEL | B4: Cost of fuel | C4: With DATs | D4: =IFERROR(VLOOKUP('General Information'!$G$6, Convalide!$L$2:$M$8, 2,FALSE), "") -> €/l milk | E4: ='Parcel 1 with DATSs'!K43*'General Information'!G33/(IF('General Information'!G6="crop",'Parcel 1 with DATSs'!K10,IF('General Information'!G6="milk",'Parcel 1 with DATSs'!K241,IF('General Information'!G6="meat",'Parcel 1 with DATSs'!K242,IF('General Information'!G6="animal",'Parcel 1 with DATSs'!K243,IF('General Information'!G6="oyster",'Parcel 1 with DATSs'!K244,IF('General Information'!G6="honey",'Parcel 1 with DATSs'!K245,'Parcel 1 with DATSs'!K246))))))) -> 1 | F4: IF(Total fuel used>0; (Total fuel used*fuel price)/Parcel dimension; sum(Fertilisation+Pesticides +Irrigation+Sowing_Planting+Pruning+…) * fuel price) | G4: =CONCATENATE("cost revenue dats","_",$A$1,"_",A4,"_",B4) -> cost revenue dats_COST ANALYSIS_FUEL _Cost of fuel | H4: E4
A5: GREENHOUSE FUEL | B5: Cost of fuel for greenhouse | C5: With DATs | D5: =IFERROR(VLOOKUP('General Information'!$G$6, Convalide!$L$2:$M$8, 2,FALSE), "") -> €/l milk | E5: =(('Parcel 1 with DATSs'!K54*'General Information'!G42)+('Parcel 1 with DATSs'!K56*'General Information'!G43)+('Parcel 1 with DATSs'!K58*'General Information'!G44))/'Parcel 1 with DATSs'!K10 -> 3 | G5: =CONCATENATE("cost revenue dats","_",$A$1,"_",A5,"_",B5) -> cost revenue dats_COST ANALYSIS_GREENHOUSE FUEL_Cost of fuel for greenhouse | H5: E5
A6: ELECTRICITY | B6: Cost of electricity | C6: With DATs | D6: =IFERROR(VLOOKUP('General Information'!$G$6, Convalide!$L$2:$M$8, 2,FALSE), "") -> €/l milk | E6: ='Parcel 1 with DATSs'!K68*'General Information'!G45/(IF('General Information'!G6="crop",'Parcel 1 with DATSs'!K10,IF('General Information'!G6="milk",'Parcel 1 with DATSs'!K241,IF('General Information'!G6="meat",'Parcel 1 with DATSs'!K242,IF('General Information'!G6="animal",'Parcel 1 with DATSs'!K243,IF('General Information'!G6="oyster",'Parcel 1 with DATSs'!K244,IF('General Information'!G6="honey",'Parcel 1 with DATSs'!K245,'Parcel 1 with DATSs'!K246))))))) -> 1 | F6: IF(Total electricity used > 0; (Total electricity used* electricity price)/Parcel dimension; Sum(irrigation,…) *electricity price) | G6: =CONCATENATE("cost revenue dats","_",$A$1,"_",A6,"_",B6) -> cost revenue dats_COST ANALYSIS_ELECTRICITY_Cost of electricity | H6: E6
A7: PESTICIDE | B7: Cost for pesticide | C7: With DATs | D7: =IFERROR(VLOOKUP('General Information'!$G$6, Convalide!$L$2:$M$8, 2,FALSE), "") -> €/l milk | E7: =('Parcel 1 with DATSs'!K82*'Parcel 1 with DATSs'!K83*'General Information'!G50)+('Parcel 1 with DATSs'!K85*'Parcel 1 with DATSs'!K86*'General Information'!G51)+('Parcel 1 with DATSs'!K88*'Parcel 1 with DATSs'!K89*'General Information'!G59) -> 3 | F7: [(N. of treatements of pesticide 1*Amount of pesticide 1*pesticide 1 price)+(N. of treatements of pesticide 2 *Amount of pesticide 2 used *pesticide 2 price) + (N. of treatements of pesticide 3 *Amount of pesticide 3 used *pesticide 3 price (€/kg)] | G7: =CONCATENATE("cost revenue dats","_",$A$1,"_",A7,"_",B7) -> cost revenue dats_COST ANALYSIS_PESTICIDE _Cost for pesticide | H7: E7
A8: FERTILISER | B8: Cost of fertiliser | C8: With DATs | D8: =IFERROR(VLOOKUP('General Information'!$G$6, Convalide!$L$2:$M$8, 2,FALSE), "") -> €/l milk | E8: =('Parcel 1 with DATSs'!K95*'Parcel 1 with DATSs'!K96*'General Information'!G68)+('Parcel 1 with DATSs'!K102*'Parcel 1 with DATSs'!K103*'General Information'!G69)+('Parcel 1 with DATSs'!K109*'Parcel 1 with DATSs'!K110*'General Information'!G70) -> 3 | F8: ((Amount of fertilisers 1 used *Number of fertilizer 1 applications *Fertilisers 1 price) + (Amount of fertilisers 2 used *Number of fertilizer 2 applications *Fertilisers 2 price) + (Amount of fertilisers 3 used *Number of fertilizer 3 applications *Fertilisers 3 price) | G8: =CONCATENATE("cost revenue dats","_",$A$1,"_",A8,"_",B8) -> cost revenue dats_COST ANALYSIS_FERTILISER_Cost of fertiliser | H8: E8
A9: FEED | B9: Cost of feed | C9: With DATs | D9: =IFERROR(VLOOKUP('General Information'!$G$6, Convalide!$L$2:$M$8, 2,FALSE), "") -> €/l milk | E9: =(('General Information'!G79*'Parcel 1 with DATSs'!K151)+('General Information'!G80*'Parcel 1 with DATSs'!K153)+('General Information'!G81*'Parcel 1 with DATSs'!K157))/(IF('General Information'!G6="crop",'Parcel 1 with DATSs'!K10,IF('General Information'!G6="milk",'Parcel 1 with DATSs'!K241,IF('General Information'!G6="meat",'Parcel 1 with DATSs'!K242,IF('General Information'!G6="animal",'Parcel 1 with DATSs'!K243,IF('General Information'!G6="oyster",'Parcel 1 with DATSs'!K244,IF('General Information'!G6="honey",'Parcel 1 with DATSs'!K245,'Parcel 1 with DATSs'!K246))))))) -> 3 | F9: (Amount of feed 1 * Feed 1 price) + (Amount of feed 2 * Feed 2 price) + … /animal | G9: =CONCATENATE("cost revenue dats","_",$A$1,"_",A9,"_",B9) -> cost revenue dats_COST ANALYSIS_FEED_Cost of feed | H9: E9
A10: DRUGS | B10: Cost of drugs | C10: With DATs | D10: =IFERROR(VLOOKUP('General Information'!$G$6, Convalide!$L$2:$M$8, 2,FALSE), "") -> €/l milk | E10: =(('General Information'!G90*'Parcel 1 with DATSs'!K174)+('General Information'!G91*'Parcel 1 with DATSs'!K176)+('General Information'!G92*'Parcel 1 with DATSs'!K178))/(IF('General Information'!G6="crop",'Parcel 1 with DATSs'!K10,IF('General Information'!G6="milk",'Parcel 1 with DATSs'!K241,IF('General Information'!G6="meat",'Parcel 1 with DATSs'!K242,IF('General Information'!G6="animal",'Parcel 1 with DATSs'!K243,IF('General Information'!G6="oyster",'Parcel 1 with DATSs'!K244,IF('General Information'!G6="honey",'Parcel 1 with DATSs'!K245,'Parcel 1 with DATSs'!K246))))))) -> 3 | F10: (Amount of drugs 1 * Feed 1 price) + (Amount of drugs 2 * Feed 2 price) + … /animal or beehives or pieces | G10: =CONCATENATE("cost revenue dats","_",$A$1,"_",A10,"_",B10) -> cost revenue dats_COST ANALYSIS_DRUGS _ Cost of drugs | H10: E10
A11: LABOUR | B11: Cost of labour for irrigation | C11: With DATs | D11: =IFERROR(VLOOKUP('General Information'!$G$6, Convalide!$L$2:$M$8, 2,FALSE), "") -> €/l milk | E11: ='Parcel 1 with DATSs'!K184*'General Information'!G46/'Parcel 1 with DATSs'!K10 -> 1 | F11: number of hours for irrigation activities*Average salary /Parcel dimension | G11: =CONCATENATE("cost revenue dats","_",$A$1,"_",A11,"_",B11) -> cost revenue dats_COST ANALYSIS_LABOUR_Cost of labour for irrigation | H11: E11
A12: LABOUR | B12: Cost of labour for pesticide application | C12: With DATs | D12: =IFERROR(VLOOKUP('General Information'!$G$6, Convalide!$L$2:$M$8, 2,FALSE), "") -> €/l milk | E12: ='Parcel 1 with DATSs'!K185*'General Information'!G46/'Parcel 1 with DATSs'!K10 -> 1 | F12: number of hours for pesticide activities *Average salary /Parcel dimension | G12: =CONCATENATE("cost revenue dats","_",$A$1,"_",A12,"_",B12) -> cost revenue dats_COST ANALYSIS_LABOUR_Cost of labour for pesticide application | H12: E12
A13: LABOUR | B13: Cost of labour for fertilisation | C13: With DATs | D13: =IFERROR(VLOOKUP('General Information'!$G$6, Convalide!$L$2:$M$8, 2,FALSE), "") -> €/l milk | E13: ='Parcel 1 with DATSs'!K186*'General Information'!G46/'Parcel 1 with DATSs'!K10 -> 1 | F13: number of hours for fertilisation activities * Average salary /Parcel dimension | G13: =CONCATENATE("cost revenue dats","_",$A$1,"_",A13,"_",B13) -> cost revenue dats_COST ANALYSIS_LABOUR_Cost of labour for fertilisation | H13: E13
A14: LABOUR | B14: Cost of labour for sowing_planting | C14: With DATs | D14: =IFERROR(VLOOKUP('General Information'!$G$6, Convalide!$L$2:$M$8, 2,FALSE), "") -> €/l milk | E14: ='Parcel 1 with DATSs'!K187*'General Information'!G46/'Parcel 1 with DATSs'!K10 -> 1 | F14: number of hours for sowing_planting activities * Average salary /Parcel dimension | G14: =CONCATENATE("cost revenue dats","_",$A$1,"_",A14,"_",B14) -> cost revenue dats_COST ANALYSIS_LABOUR_Cost of labour for sowing_planting | H14: E14
A15: LABOUR | B15: Cost of labour for pruning | C15: With DATs | D15: =IFERROR(VLOOKUP('General Information'!$G$6, Convalide!$L$2:$M$8, 2,FALSE), "") -> €/l milk | E15: ='Parcel 1 with DATSs'!K188*'General Information'!G46/'Parcel 1 with DATSs'!K10 -> 1 | F15: number of hours for pruning activities *Average salary /Parcel dimension | G15: =CONCATENATE("cost revenue dats","_",$A$1,"_",A15,"_",B15) -> cost revenue dats_COST ANALYSIS_LABOUR_Cost of labour for pruning | H15: E15
A16: LABOUR | B16: Cost of labour for field visits | C16: With DATs | D16: =IFERROR(VLOOKUP('General Information'!$G$6, Convalide!$L$2:$M$8, 2,FALSE), "") -> €/l milk | E16: ='Parcel 1 with DATSs'!K189*'General Information'!G46/'Parcel 1 with DATSs'!K10 -> 1 | F16: number of hours for field visits activities * Average professional salary /Parcel dimension | G16: =CONCATENATE("cost revenue dats","_",$A$1,"_",A16,"_",B16) -> cost revenue dats_COST ANALYSIS_LABOUR_Cost of labour for field visits | H16: E16
A17: LABOUR | B17: Cost of labour for greenhouse maintenance | C17: With DATs | D17: =IFERROR(VLOOKUP('General Information'!$G$6, Convalide!$L$2:$M$8, 2,FALSE), "") -> €/l milk | E17: ='Parcel 1 with DATSs'!K190*'General Information'!G46/'Parcel 1 with DATSs'!K10 -> 1 | F17: number of hours for greenhouse management *Average salary /Parcel dimension | G17: =CONCATENATE("cost revenue dats","_",$A$1,"_",A17,"_",B17) -> cost revenue dats_COST ANALYSIS_LABOUR_Cost of labour for greenhouse maintenance | H17: E17
A18: LABOUR | B18: Cost of labour for tracking the quantity of grain available in the silo | C18: With DATs | D18: =IFERROR(VLOOKUP('General Information'!$G$6, Convalide!$L$2:$M$8, 2,FALSE), "") -> €/l milk | E18: ='Parcel 1 with DATSs'!K191*'General Information'!G46/'Parcel 1 with DATSs'!K246 -> 1 | F18: number of hours for tracking the quantity of grain available in the silo *Average salary | G18: =CONCATENATE("cost revenue dats","_",$A$1,"_",A18,"_",B18) -> cost revenue dats_COST ANALYSIS_LABOUR_Cost of labour for tracking the quantity of grain available in the silo | H18: E18
A19: LABOUR | B19: Cost of labour for assessing product quality | C19: With DATs | D19: =IFERROR(VLOOKUP('General Information'!$G$6, Convalide!$L$2:$M$8, 2,FALSE), "") -> €/l milk | E19: ='Parcel 1 with DATSs'!K192*'General Information'!G46/(IF('General Information'!G6="crop",'Parcel 1 with DATSs'!K10,IF('General Information'!G6="milk",'Parcel 1 with DATSs'!K241,IF('General Information'!G6="meat",'Parcel 1 with DATSs'!K242,IF('General Information'!G6="animal",'Parcel 1 with DATSs'!K243,IF('General Information'!G6="oyster",'Parcel 1 with DATSs'!K244,IF('General Information'!G6="honey",'Parcel 1 with DATSs'!K245,'Parcel 1 with DATSs'!K246))))))) -> 1 | F19: number of hours for assessing grain quality *Average salary | G19: =CONCATENATE("cost revenue dats","_",$A$1,"_",A19,"_",B19) -> cost revenue dats_COST ANALYSIS_LABOUR_Cost of labour for assessing product quality | H19: E19
A20: LABOUR | B20: Cost of labour for controlling purchase and sale prices and quantities | C20: With DATs | D20: =IFERROR(VLOOKUP('General Information'!$G$6, Convalide!$L$2:$M$8, 2,FALSE), "") -> €/l milk | E20: ='Parcel 1 with DATSs'!K193*'General Information'!G46/(IF('General Information'!G6="crop",'Parcel 1 with DATSs'!K10,IF('General Information'!G6="milk",'Parcel 1 with DATSs'!K241,IF('General Information'!G6="meat",'Parcel 1 with DATSs'!K242,IF('General Information'!G6="animal",'Parcel 1 with DATSs'!K243, IF('General Information'!G6="oyster",'Parcel 1 with DATSs'!K244,IF('General Information'!G6="honey",'Parcel 1 with DATSs'!K245,'Parcel 1 with DATSs'!K246))))))) -> 1 | F20: number of hours for controlling purchase and sale prices and quantities *Average salary | G20: =CONCATENATE("cost revenue dats","_",$A$1,"_",A20,"_",B20) -> cost revenue dats_COST ANALYSIS_LABOUR_Cost of labour for controlling purchase and sale prices and quantities | H20: E20
A21: LABOUR | B21: Cost of labour for organise logistics | C21: With DATs | D21: =IFERROR(VLOOKUP('General Information'!$G$6, Convalide!$L$2:$M$8, 2,FALSE), "") -> €/l milk | E21: ='Parcel 1 with DATSs'!K194*'General Information'!G46/(IF('General Information'!G6="crop",'Parcel 1 with DATSs'!K10,IF('General Information'!G6="milk",'Parcel 1 with DATSs'!K241,IF('General Information'!G6="meat",'Parcel 1 with DATSs'!K242,IF('General Information'!G6="animal",'Parcel 1 with DATSs'!K243, IF('General Information'!G6="oyster",'Parcel 1 with DATSs'!K244,IF('General Information'!G6="honey",'Parcel 1 with DATSs'!K245,'Parcel 1 with DATSs'!K246))))))) -> 1 | F21: number of hours for organise logistics *Average salary | G21: =CONCATENATE("cost revenue dats","_",$A$1,"_",A21,"_",B21) -> cost revenue dats_COST ANALYSIS_LABOUR_Cost of labour for organise logistics | H21: E21
A22: LABOUR | B22: Cost of labour for cleaning | C22: With DATs | D22: =IFERROR(VLOOKUP('General Information'!$G$6, Convalide!$L$2:$M$8, 2,FALSE), "") -> €/l milk | E22: ='Parcel 1 with DATSs'!K195*'General Information'!G46/(IF('General Information'!G6="crop",'Parcel 1 with DATSs'!K10,IF('General Information'!G6="milk",'Parcel 1 with DATSs'!K241,IF('General Information'!G6="meat",'Parcel 1 with DATSs'!K242,IF('General Information'!G6="animal",'Parcel 1 with DATSs'!K243, IF('General Information'!G6="oyster",'Parcel 1 with DATSs'!K244,IF('General Information'!G6="honey",'Parcel 1 with DATSs'!K245,'Parcel 1 with DATSs'!K246))))))) -> 1 | F22: number of hours for cleaning *Average salary /animal | G22: =CONCATENATE("cost revenue dats","_",$A$1,"_",A22,"_",B22) -> cost revenue dats_COST ANALYSIS_LABOUR_Cost of labour for cleaning | H22: E22
A23: LABOUR | B23: Cost of labour for stable visits | C23: With DATs | D23: =IFERROR(VLOOKUP('General Information'!$G$6, Convalide!$L$2:$M$8, 2,FALSE), "") -> €/l milk | E23: ='Parcel 1 with DATSs'!K196*'General Information'!G46/(IF('General Information'!G6="crop",'Parcel 1 with DATSs'!K10,IF('General Information'!G6="milk",'Parcel 1 with DATSs'!K241,IF('General Information'!G6="meat",'Parcel 1 with DATSs'!K242,IF('General Information'!G6="animal",'Parcel 1 with DATSs'!K243, IF('General Information'!G6="oyster",'Parcel 1 with DATSs'!K244,IF('General Information'!G6="honey",'Parcel 1 with DATSs'!K245,'Parcel 1 with DATSs'!K246))))))) -> 1 | F23: number of hours for stable visits*Average professional salary /animal | G23: =CONCATENATE("cost revenue dats","_",$A$1,"_",A23,"_",B23) -> cost revenue dats_COST ANALYSIS_LABOUR_Cost of labour for stable visits | H23: E23
A24: LABOUR | B24: Cost of labour for heat detection | C24: With DATs | D24: =IFERROR(VLOOKUP('General Information'!$G$6, Convalide!$L$2:$M$8, 2,FALSE), "") -> €/l milk | E24: ='Parcel 1 with DATSs'!K197*'General Information'!G46/(IF('General Information'!G6="crop",'Parcel 1 with DATSs'!K10,IF('General Information'!G6="milk",'Parcel 1 with DATSs'!K241,IF('General Information'!G6="meat",'Parcel 1 with DATSs'!K242,IF('General Information'!G6="animal",'Parcel 1 with DATSs'!K243, IF('General Information'!G6="oyster",'Parcel 1 with DATSs'!K244,IF('General Information'!G6="honey",'Parcel 1 with DATSs'!K245,'Parcel 1 with DATSs'!K246))))))) -> 1 | F24: number of hours for heat detection *Average salary /animal | G24: =CONCATENATE("cost revenue dats","_",$A$1,"_",A24,"_",B24) -> cost revenue dats_COST ANALYSIS_LABOUR_Cost of labour for heat detection | H24: E24
A25: LABOUR | B25: Cost of labour for calving detection | C25: With DATs | D25: =IFERROR(VLOOKUP('General Information'!$G$6, Convalide!$L$2:$M$8, 2,FALSE), "") -> €/l milk | E25: ='Parcel 1 with DATSs'!K198*'General Information'!G46/(IF('General Information'!G6="crop",'Parcel 1 with DATSs'!K10,IF('General Information'!G6="milk",'Parcel 1 with DATSs'!K241,IF('General Information'!G6="meat",'Parcel 1 with DATSs'!K242,IF('General Information'!G6="animal",'Parcel 1 with DATSs'!K243, IF('General Information'!G6="oyster",'Parcel 1 with DATSs'!K244,IF('General Information'!G6="honey",'Parcel 1 with DATSs'!K245,'Parcel 1 with DATSs'!K246))))))) -> 1 | F25: number of hours for calving detection *Average salary /animal | G25: =CONCATENATE("cost revenue dats","_",$A$1,"_",A25,"_",B25) -> cost revenue dats_COST ANALYSIS_LABOUR_Cost of labour for calving detection | H25: E25
A26: LABOUR | B26: Cost of labour for pigsty management | C26: With DATs | D26: =IFERROR(VLOOKUP('General Information'!$G$6, Convalide!$L$2:$M$8, 2,FALSE), "") -> €/l milk | E26: ='Parcel 1 with DATSs'!K199*'General Information'!G46/(IF('General Information'!G6="crop",'Parcel 1 with DATSs'!K10,IF('General Information'!G6="milk",'Parcel 1 with DATSs'!K241,IF('General Information'!G6="meat",'Parcel 1 with DATSs'!K242,IF('General Information'!G6="animal",'Parcel 1 with DATSs'!K243, IF('General Information'!G6="oyster",'Parcel 1 with DATSs'!K244,IF('General Information'!G6="honey",'Parcel 1 with DATSs'!K245,'Parcel 1 with DATSs'!K246))))))) -> 1 | F26: number of hours for pigsty management*Average salary /animal | G26: =CONCATENATE("cost revenue dats","_",$A$1,"_",A26,"_",B26) -> cost revenue dats_COST ANALYSIS_LABOUR_Cost of labour for pigsty management | H26: E26
A27: LABOUR | B27: Cost of milking | C27: With DATs | D27: =IFERROR(VLOOKUP('General Information'!$G$6, Convalide!$L$2:$M$8, 2,FALSE), "") -> €/l milk | E27: ='Parcel 1 with DATSs'!K200*'General Information'!G46/(IF('General Information'!G6="crop",'Parcel 1 with DATSs'!K10,IF('General Information'!G6="milk",'Parcel 1 with DATSs'!K241,IF('General Information'!G6="meat",'Parcel 1 with DATSs'!K242,IF('General Information'!G6="animal",'Parcel 1 with DATSs'!K243, IF('General Information'!G6="oyster",'Parcel 1 with DATSs'!K244,IF('General Information'!G6="honey",'Parcel 1 with DATSs'!K245,'Parcel 1 with DATSs'!K246))))))) -> 1 | F27: number of hours for milking *Average salary /animal | G27: =CONCATENATE("cost revenue dats","_",$A$1,"_",A27,"_",B27) -> cost revenue dats_COST ANALYSIS_LABOUR_Cost of milking | H27: E27
A28: LABOUR | B28: Cost of labour for (milk) quality assessment | C28: With DATs | D28: =IFERROR(VLOOKUP('General Information'!$G$6, Convalide!$L$2:$M$8, 2,FALSE), "") -> €/l milk | E28: ='Parcel 1 with DATSs'!K201*'General Information'!G46/(IF('General Information'!G6="crop",'Parcel 1 with DATSs'!K10,IF('General Information'!G6="milk",'Parcel 1 with DATSs'!K241,IF('General Information'!G6="meat",'Parcel 1 with DATSs'!K242,IF('General Information'!G6="animal",'Parcel 1 with DATSs'!K243, IF('General Information'!G6="oyster",'Parcel 1 with DATSs'!K244,IF('General Information'!G6="honey",'Parcel 1 with DATSs'!K245,'Parcel 1 with DATSs'!K246))))))) -> 1 | F28: number of hours for (milk) quality assessment*Average salary /animal | G28: =CONCATENATE("cost revenue dats","_",$A$1,"_",A28,"_",B28) -> cost revenue dats_COST ANALYSIS_LABOUR_Cost of labour for (milk) quality assessment | H28: E28
A29: LABOUR | B29: Cost of labour for feeding | C29: With DATs | D29: =IFERROR(VLOOKUP('General Information'!$G$6, Convalide!$L$2:$M$8, 2,FALSE), "") -> €/l milk | E29: ='Parcel 1 with DATSs'!K202*'General Information'!G46/(IF('General Information'!G6="crop",'Parcel 1 with DATSs'!K10,IF('General Information'!G6="milk",'Parcel 1 with DATSs'!K241,IF('General Information'!G6="meat",'Parcel 1 with DATSs'!K242,IF('General Information'!G6="animal",'Parcel 1 with DATSs'!K243, IF('General Information'!G6="oyster",'Parcel 1 with DATSs'!K244,IF('General Information'!G6="honey",'Parcel 1 with DATSs'!K245,'Parcel 1 with DATSs'!K246))))))) -> 1 | F29: number of hours for feeding *Average salary /animal | G29: =CONCATENATE("cost revenue dats","_",$A$1,"_",A29,"_",B29) -> cost revenue dats_COST ANALYSIS_LABOUR_Cost of labour for feeding | H29: E29
A30: LABOUR | B30: Cost of labour for beehives visits | C30: With DATs | D30: =IFERROR(VLOOKUP('General Information'!$G$6, Convalide!$L$2:$M$8, 2,FALSE), "") -> €/l milk | E30: ='Parcel 1 with DATSs'!K203*'General Information'!G46/'Parcel 1 with DATSs'!K245 -> 1 | F30: number of hours for beehives visits *Average salary / beehive | G30: =CONCATENATE("cost revenue dats","_",$A$1,"_",A30,"_",B30) -> cost revenue dats_COST ANALYSIS_LABOUR_Cost of labour for beehives visits | H30: E30
A31: LABOUR | B31: Cost of labour for sampling of oysters | C31: With DATs | D31: =IFERROR(VLOOKUP('General Information'!$G$6, Convalide!$L$2:$M$8, 2,FALSE), "") -> €/l milk | E31: ='Parcel 1 with DATSs'!K204*'General Information'!G46/'Parcel 1 with DATSs'!K244 -> 1 | F31: number of hours for sampling of oysters* Average salary /piece | G31: =CONCATENATE("cost revenue dats","_",$A$1,"_",A31,"_",B31) -> cost revenue dats_COST ANALYSIS_LABOUR_Cost of labour for sampling of oysters | H31: E31
A32: LABOUR | B32: Cost of labour for transporting oysters to the laboratory | C32: With DATs | D32: =IFERROR(VLOOKUP('General Information'!$G$6, Convalide!$L$2:$M$8, 2,FALSE), "") -> €/l milk | E32: ='Parcel 1 with DATSs'!K205*'General Information'!G46/'Parcel 1 with DATSs'!K244 -> 1 | F32: number of hours for transporting oysters to the laboratory*Average salary /piece | G32: =CONCATENATE("cost revenue dats","_",$A$1,"_",A32,"_",B32) -> cost revenue dats_COST ANALYSIS_LABOUR_Cost of labour for transporting oysters to the laboratory | H32: E32
