Workbook

Sheet Instructions 
B2: Instructions to be followed to complete the Data Collection Template
B3: This form is intended to be filled out by each farmer involved in the Test Case (TC) and aims at collecting information that will be used for assessing the impacts of Digital agriculture technology solutions (DATSs). Please read carefully the following instructions. - We kindly ask you to be as accurate as possible in providing the data and monitor them periodically as these will be the input for performance assessment. - Please ensure you keep track of the data requested and regularly check its availability. It's crucial that these values align for both user and non-user parcels. If they differ, kindly notify us promptly via email at the provided contact details. - The data included in the template have been carefully chosen based on their link with the DATSs used in your TC and they were further customised following your feedback. If some of the data cannot be applicable/available to your TC, please enter ‘n.a.’ in the corresponding cell and provide a comment explaining why they are not applicable. Additionally, in case some of the data cannot be collected due to some problems you may encounter during the season, please inform us promptly by writing an e-mail to the contact details provided below. - In order to obtain the assessment of the impacts of DATS, it is necessary to provide data for the farm(s) using DATS and for the one without. According to the QuantiFarm project proposal, each parcel using DATSs is associated with a comparable non-DATs parcel (in terms of size, geographical area, production, etc.). - Recall that: - the term DATS refers to the combinations or set of technological solutions implemented within the TC; For any doubts or clarifications, please do not hesitate to contact us at the following email address: francesco.parigi@polimi.it and andrea.bianchi@polimi.it (cc: dmoniz@consulai.com) This form is intended to be filled out by each farmer involved in the Test Case (TC) and aims at collecting information that will be used for assessing the impacts of Digital agriculture technology solutions (DATSs).
B5: Table of abbreviations
B6: - | C6: number (1, 2, 3, …)
B7: € | C7: euro
C8: cubic centimetre
C9: cubic decimetre
B10: g | C10: grams
B11: h | C11: hour
B12: ha | C12: hectare
B13: K | C13: potassium
B14: k€ | C14: kiloeuro (€ 1,000)
B15: kg | C15: kilograms
B16: kWh | C16: kilowatt-hour
B17: l | C17: litre
B18: mg | C18: micrograms
B19: mo | C19: month
C20: square metre
C21: cubic metre
B22: N | C22: nitrogen
B23: P | C23: phosphorus
B24: ppm | C24: parts per million
B25: t | C25: tonnes
B26: w | C26: week
B27: y | C27: year

Sheet General Information
B2: Question | C2: Unit of measure | D2: Value
B3: TC Number | C3: n | D3: TC10
B4: TC Leader | C4: - | D4: Arable
B5: FARM DATA
B6: Type of output/product | C6: - | D6: Crop
B7: Crop | C7: - | D7: Wheat (T. aestivum)
B8: Animal
B9: Start of the growing/production season | C9: (gg/mm/yyyy) | D9: 45200
B10: End of the growing/production season | C10: (gg/mm/yyyy) | D10: 45474
B11: Biogeographical region | C11: -
B12: Total farm size | C12: ha
B13: Number of comparison(s) | C13: n
B14: Number of employees | C14: n | D14: 9
B15: Number of full-time employees | C15: n
B16: Number of seasonal employees | C16: n
B18: DATSs 1 DATA | F18: DATSs 2 DATA | J18: DATSs n DATA
B19: Question | C19: Unit of measure | D19: Value | F19: Question | G19: Unit of measure | H19: Value | J19: Question | K19: Unit of measure | L19: Value
B20: Initial investment for DATSs | C20: € | D20: 70396 | F20: Initial investment for DATSs | G20: € | J20: Initial investment for DATSs | K20: €
B21: Expected life span of each DATSs | C21: y | D21: 10 | F21: Expected life span of each DATSs | G21: y | J21: Expected life span of each DATSs | K21: y
B22: Time to install and make DATSs operational | C22: h | D22: 60 | F22: Time to install and make DATSs operational | G22: h | J22: Time to install and make DATSs operational | K22: h
B23: DATs maintenance costs | C23: €/y | D23: 500 | F23: DATs maintenance costs | G23: €/y | J23: DATs maintenance costs | K23: €/y
B24: DATS annual fees | C24: €/y | D24: 1100 | F24: DATS annual fees | G24: €/y | J24: DATS annual fees | K24: €/y
B25: Training hours for the use of the DATSs in a year | C25: h | D25: 40 | F25: Training hours for the use of the DATSs in a year | G25: h | J25: Training hours for the use of the DATSs in a year | K25: h
B26: Number of people involved in the training | C26: n | D26: 2 | F26: Number of people involved in the training | G26: n | J26: Number of people involved in the training | K26: n
B27: Cost of training service by external people (advisor, DATS providers, ...) | C27: €/y | D27: 1200 | F27: Cost of training service by external people (advisor, DATS providers, ...) | G27: €/y | J27: Cost of training service by external people (advisor, DATS providers, ...) | K27: €/y
B28: DATSs name | C28: - | F28: DATSs name | G28: - | J28: DATSs name | K28: -
B30: MARKET DATA FOR DATSs USER | F30: MARKET DATA FOR NON-DATSs USER
B31: Question | C31: Unit of measure | D31: Value | F31: Question | G31: Unit of measure | H31: Value
B32: Water price | D32: 0 | F32: Water price | H32: 0
B33: Fuel price | C33: €/l | D33: 1.15 | F33: Fuel price | G33: €/l | H33: 1.15
B34: Number of fuel for greehnouse temperature control price | C34: n | F34: Number of fuel for greehnouse temperature control price | G34: n
B35: Fuel 1 for greehnouse temperature control price | F35: Fuel 1 for greehnouse temperature control price
B36: Fuel 2 for greehnouse temperature control price | F36: Fuel 2 for greehnouse temperature control price
B37: Fuel 3 for greehnouse temperature control price | F37: Fuel 3 for greehnouse temperature control price
B38: Electricity price | C38: €/kWh | D38: 0.148 | F38: Electricity price | G38: €/kWh | H38: 0.148
B39: Average salary (farmer and emloyees) | C39: €/h | D39: 7.2 | F39: Average salary (farmer and emloyees) | G39: €/h | H39: 7.2
B40: Average professional salary (agronomist, veterinary, ...) | C40: €/h | D40: 8.6 | F40: Average professional salary (agronomist, veterinary, ...) | G40: €/h | H40: 8.6
B41: Sold product market price | C41: €/t | D41: 192 | F41: Sold product market price | G41: €/t | H41: 192
B42: Number of pesticide used (herbicides, fungicides, insecticides) | C42: n | D42: 4 | F42: Number of pesticide used (herbicides, fungicides, insecticides) | G42: n | H42: 6
B43: Pesticide 1 price | C43: €/kg | D43: 8 | F43: Pesticide 1 price | G43: €/kg | H43: 14.4
...

Sheet Parcel 1 with DATSs
BF1: yes
G2: PARCEL WITH DATSs | BF2: no
C4: Identification | D4: Parcel Name
B8: Information about the TC
B9: # | C9: data | D9: u.m. | E9: value | G9: Notes
B10: 1 | C10: Parcel dimension | D10: ha | E10: 898
B11: 2 | C11: Number of plants/trees | D11: n
B12: 3 | C12: Sand content in the soil | D12: % | E12: 7.2
B13: 4 | C13: Clay content in the soil | D13: % | E13: 22.2
B14: 5 | C14: Silt content in the soil | D14: % | E14: 63.7
B15: 6 | C15: Soil Bulk Density | E15: 1.2
B16: 7 | C16: Soil Organic Carbon | D16: % | E16: 3.24
B17: 8 | C17: Number of animals | D17: n
B18: 9 | C18: Livestock units per hectare | D18: LSU/ha
B19: 10 | C19: Number of beehives | D19: n
B20: 11 | C20: Area under aquaculture
B22: WATER | G22: Year 1 | J22: Year 2 | M22: Year 3
B23: # | C23: data | D23: u.m. | G23: With DATSs | H23: Notes | J23: With DATSs | K23: Notes | M23: With DATSs | N23: Notes
B24: 12 | C24: Irrigation | G24: 360
B25: 13 | C25: Fertigation
B26: 14 | C26: Pest dilution
B27: 15 | C27: Cleaning
B28: 16 | C28: Drinking
B29: 17 | C29: Total water used | G29: 360
B31: FUEL | G31: Year 1 | J31: Year 2 | M31: Year 3
B32: # | C32: data | D32: u.m. | G32: With DATSs | H32: Notes | J32: With DATSs | K32: Notes | M32: With DATSs | N32: Notes
B33: 18 | C33: Fertilisation | D33: l | G33: 3560
B34: 19 | C34: Pesticides | D34: l | G34: 4450
B35: 20 | C35: Irrigation | D35: l
B36: 21 | C36: Sowing / Planting | D36: l | G36: 9345
B37: 22 | C37: Temperature and Humidity Control | D37: l
B38: 23 | C38: Pruning | D38: l | G38: 4005
B39: 24 | C39: Beehives visits | D39: l
B40: 25 | C40: Transporting oysters to the laboratory | D40: l
B41: 26 | C41: Milking | D41: l
B42: 27 | C42: Feeding | D42: l
B43: 28 | C43: Total fuel used | D43: l | G43: 44500
B45: FUEL FOR GREENHOUSE TEMPERATURE CONTROL | G45: Year 1 | J45: Year 2 | M45: Year 3
B46: # | C46: data | E46: u.m. | G46: With DATSs | H46: Notes | J46: With DATSs | K46: Notes | M46: With DATSs | N46: Notes
B47: 29 | C47: Fuel 1 | D47: Name fuel 1
...

Sheet Parcel 1 without DATSs
BG1: yes
G2: PARCEL WITHOUT DATSs | BG2: no
C4: Identification | D4: Parcel Name
B8: Information about the TC
B9: # | C9: data | D9: u.m. | E9: value | G9: Notes
B10: 1 | C10: Parcel dimension | D10: ha | E10: 208
B11: 2 | C11: Number of plants/trees | D11: n
B12: 3 | C12: Sand content in the soil | D12: % | E12: 6.4
B13: 4 | C13: Clay content in the soil | D13: % | E13: 27.8
B14: 5 | C14: Silt content in the soil | D14: % | E14: 59.9
B15: 6 | C15: Soil Bulk Density | E15: 1.22
B16: 7 | C16: Soil Organic Carbon | D16: % | E16: 3.6
B17: 8 | C17: Number of animals | D17: n
B18: 9 | C18: Livestock units per hectare | D18: LSU/ha
B19: 10 | C19: Number of beehives | D19: n
B20: 11 | C20: Area under aquaculture
B22: WATER | G22: Year 1 | J22: Year 2 | M22: Year 3
B23: # | C23: data | D23: u.m. | G23: Without DATSs | H23: Notes | J23: Without DATSs | K23: Notes | M23: Without DATSs | N23: Without DAT
B24: 12 | C24: Irrigation | G24: 166
B25: 13 | C25: Fertigation
B26: 14 | C26: Pest dilution
B27: 15 | C27: Cleaning
B28: 16 | C28: Drinking
B29: 17 | C29: or Total water used | G29: 166
B31: FUEL | G31: Year 1 | J31: Year 2 | M31: Year 3
B32: # | C32: data | D32: u.m. | G32: Without DATSs | H32: Notes | J32: Without DATSs | K32: Notes | M32: Without DATSs | N32: Without DAT
B33: 18 | C33: Fertilisation | D33: l | G33: 784
B34: 19 | C34: Pesticides | D34: l | G34: 1004
B35: 20 | C35: Irrigation | D35: l | G35: 0
B36: 21 | C36: Sowing / Planting | D36: l | G36: 3568
B37: 22 | C37: Temperature and Humidity Control | D37: l
B38: 23 | C38: Pruning | D38: l
B39: 24 | C39: Beehives visits | D39: l
B40: 25 | C40: Transporting oysters to the laboratory | D40: l
B41: 26 | C41: Milking | D41: l
B42: 27 | C42: Feeding | D42: l
B43: 28 | C43: or Total fuel used | D43: l | G43: 11150
B45: FUEL FOR GREENHOUSE TEMPERATURE CONTROL | G45: Year 1 | J45: Year 2 | M45: Year 3
B46: # | C46: data | E46: u.m. | G46: Without DATSs | H46: Notes | J46: Without DATSs | K46: Notes | M46: Without DATSs | N46: Without DAT
B47: 29 | C47: Fuel 1 | D47: Name fuel 1
...

Sheet Cost-revenue DATS
A1: COST ANALYSIS
A2: INPUT | B2: INDICATOR | C2: SCENARIO | D2: UoM | E2: TOTAL | F2: FORMULAS
A3: WATER | B3: Cost of water | C3: With DATs | D3: =IFERROR(VLOOKUP('General Information'!$D$6, Validations!$L$2:$M$8, 2,FALSE), "") -> €/ha | E3: =('Parcel 1 with DATSs'!G29*'General Information'!D32)/(IF('General Information'!D6="crop",'Parcel 1 with DATSs'!E10,IF('General Information'!D6="milk",'Parcel 1 with DATSs'!G251,IF('General Information'!D6="meat",'Parcel 1 with DATSs'!G252,IF('General Information'!D6="animal",'Parcel 1 with DATSs'!G253,IF('General Information'!D6="oyster",'Parcel 1 with DATSs'!G254,IF('General Information'!D6="honey",'Parcel 1 with DATSs'!G255,'Parcel 1 with DATSs'!G256))))))) -> 0 | F3: IF(Total water used>0; (Total water used * water price)/Parcel dimension; Sum(water Irrigation+ water Fertigation + water Pest dilution + …) * water price)
A4: FUEL | B4: Cost of fuel | C4: With DATs | D4: =IFERROR(VLOOKUP('General Information'!$D$6, Validations!$L$2:$M$8, 2,FALSE), "") -> €/ha | E4: ='Parcel 1 with DATSs'!G43*'General Information'!D33/(IF('General Information'!D6="crop",'Parcel 1 with DATSs'!E10,IF('General Information'!D6="milk",'Parcel 1 with DATSs'!G251,IF('General Information'!D6="meat",'Parcel 1 with DATSs'!G252,IF('General Information'!D6="animal",'Parcel 1 with DATSs'!G253,IF('General Information'!D6="oyster",'Parcel 1 with DATSs'!G254,IF('General Information'!D6="honey",'Parcel 1 with DATSs'!G255,'Parcel 1 with DATSs'!G256))))))) -> 56.987751 | F4: IF(Total fuel used>0; (Total fuel used*fuel price)/Parcel dimension; sum(Fertilisation+Pesticides +Irrigation+Sowing_Planting+Pruning+…) * fuel price)
A5: ELECTRICITY | B5: Cost of electricity | C5: With DATs | D5: =IFERROR(VLOOKUP('General Information'!$D$6, Validations!$L$2:$M$8, 2,FALSE), "") -> €/ha | E5: ='Parcel 1 with DATSs'!G62*'General Information'!D38/(IF('General Information'!D6="crop",'Parcel 1 with DATSs'!E10,IF('General Information'!D6="milk",'Parcel 1 with DATSs'!G251,IF('General Information'!D6="meat",'Parcel 1 with DATSs'!G252,IF('General Information'!D6="animal",'Parcel 1 with DATSs'!G253,IF('General Information'!D6="oyster",'Parcel 1 with DATSs'!G254,IF('General Information'!D6="honey",'Parcel 1 with DATSs'!G255,'Parcel 1 with DATSs'!G256))))))) -> 0.45751448 | F5: IF(Total electricity used > 0; (Total electricity used* electricity price)/Parcel dimension; Sum(irrigation,…) *electricity price)
A6: PESTICIDE | B6: Cost for pesticide | C6: With DATs | D6: =IFERROR(VLOOKUP('General Information'!$D$6, Validations!$L$2:$M$8, 2,FALSE), "") -> €/ha | E6: =('Parcel 1 with DATSs'!G67*'Parcel 1 with DATSs'!G68*'General Information'!D43)+ ('Parcel 1 with DATSs'!G70*'Parcel 1 with DATSs'!G71*'General Information'!D44)+ ('Parcel 1 with DATSs'!G73*'Parcel 1 with DATSs'!G74*'General Information'!D45)+ ('Parcel 1 with DATSs'!G76*'Parcel 1 with DATSs'!G77*'General Information'!D46)+ ('Parcel 1 with DATSs'!G79*'Parcel 1 with DATSs'!G80*'General Information'!D47)+ ('Parcel 1 with DATSs'!G82*'Parcel 1 with DATSs'!G83*'General Information'!D48)+ ('Parcel 1 with DATSs'!G85*'Parcel 1 with DATSs'!G86*'General Information'!D49)+ ('Parcel 1 with DATSs'!G88*'Parcel 1 with DATSs'!G89*'General Information'!D50)+ ('Parcel 1 with DATSs'!G91*'Parcel 1 with DATSs'!G92*'General Information'!D51)+ ('Parcel 1 with DATSs'!G94*'Parcel 1 with DATSs'!G95*'General Information'!D52) -> 51.1 | F6: [(N. of treatements of pesticide 1*Amount of pesticide 1*pesticide 1 price)+(N. of treatements of pesticide 2 *Amount of pesticide 2 used *pesticide 2 price) + (N. of treatements of pesticide 3 *Amount of pesticide 3 used *pesticide 3 price (€/kg)]
A7: FERTILISER | B7: Cost of fertiliser | C7: With DATs | D7: =IFERROR(VLOOKUP('General Information'!$D$6, Validations!$L$2:$M$8, 2,FALSE), "") -> €/ha | E7: =('Parcel 1 with DATSs'!G101*'Parcel 1 with DATSs'!G102*'General Information'!D54)+ ('Parcel 1 with DATSs'!G108*'Parcel 1 with DATSs'!G109*'General Information'!D55)+ ('Parcel 1 with DATSs'!G115*'Parcel 1 with DATSs'!G116*'General Information'!D56)+ ('Parcel 1 with DATSs'!G122*'Parcel 1 with DATSs'!G123*'General Information'!D57)+ ('Parcel 1 with DATSs'!G129*'Parcel 1 with DATSs'!G130*'General Information'!D58)+ ('Parcel 1 with DATSs'!G136*'Parcel 1 with DATSs'!G137*'General Information'!D59)+ ('Parcel 1 with DATSs'!G143*'Parcel 1 with DATSs'!G144*'General Information'!D60)+ ('Parcel 1 with DATSs'!G150*'Parcel 1 with DATSs'!G151*'General Information'!D61)+ ('Parcel 1 with DATSs'!G157*'Parcel 1 with DATSs'!G158*'General Information'!D62)+ ('Parcel 1 with DATSs'!G164*'Parcel 1 with DATSs'!G165*'General Information'!D63) -> 303 | F7: ((Amount of fertilisers 1 used *Number of fertilizer 1 applications *Fertilisers 1 price) + (Amount of fertilisers 2 used *Number of fertilizer 2 applications *Fertilisers 2 price) + (Amount of fertilisers 3 used *Number of fertilizer 3 applications *Fertilisers 3 price)
A8: FEED | B8: Cost of feed | C8: With DATs | D8: =IFERROR(VLOOKUP('General Information'!$D$6, Validations!$L$2:$M$8, 2,FALSE), "") -> €/ha | E8: =(('General Information'!D65*'Parcel 1 with DATSs'!G173)+('General Information'!D66*'Parcel 1 with DATSs'!G175)+('General Information'!D69*'Parcel 1 with DATSs'!G177))/(IF('General Information'!D6="crop",'Parcel 1 with DATSs'!E10,IF('General Information'!D6="milk",'Parcel 1 with DATSs'!G251,IF('General Information'!D6="meat",'Parcel 1 with DATSs'!G252,IF('General Information'!D6="animal",'Parcel 1 with DATSs'!G253,IF('General Information'!D6="oyster",'Parcel 1 with DATSs'!G254,IF('General Information'!D6="honey",'Parcel 1 with DATSs'!G255,'Parcel 1 with DATSs'!G256))))))) -> 0 | F8: (Amount of feed 1 * Feed 1 price) + (Amount of feed 2 * Feed 2 price) + … /animal
A9: DRUGS | B9: Cost of drugs | C9: With DATs | D9: =IFERROR(VLOOKUP('General Information'!$D$6, Validations!$L$2:$M$8, 2,FALSE), "") -> €/ha | E9: =(('General Information'!D71*'Parcel 1 with DATSs'!G186)+('General Information'!D72*'Parcel 1 with DATSs'!G188)+('General Information'!D73*'Parcel 1 with DATSs'!G190))/(IF('General Information'!D6="crop",'Parcel 1 with DATSs'!E10,IF('General Information'!D6="milk",'Parcel 1 with DATSs'!G251,IF('General Information'!D6="meat",'Parcel 1 with DATSs'!G252,IF('General Information'!D6="animal",'Parcel 1 with DATSs'!G253,IF('General Information'!D6="oyster",'Parcel 1 with DATSs'!G254,IF('General Information'!D6="honey",'Parcel 1 with DATSs'!G255,'Parcel 1 with DATSs'!G256))))))) -> 0 | F9: (Amount of drugs 1 * Feed 1 price) + (Amount of drugs 2 * Feed 2 price) + … /animal or beehives or pieces
A10: LABOUR | B10: Cost of labour for irrigation | C10: With DATs | D10: =IFERROR(VLOOKUP('General Information'!$D$6, Validations!$L$2:$M$8, 2,FALSE), "") -> €/ha | E10: ='Parcel 1 with DATSs'!G194*'General Information'!D39/'Parcel 1 with DATSs'!E10 -> 0 | F10: number of hours for irrigation activities*Average salary /Parcel dimension
A11: LABOUR | B11: Cost of labour for pesticide application | C11: With DATs | D11: =IFERROR(VLOOKUP('General Information'!$D$6, Validations!$L$2:$M$8, 2,FALSE), "") -> €/ha | E11: ='Parcel 1 with DATSs'!G195*'General Information'!D39/'Parcel 1 with DATSs'!E10 -> 19.699777 | F11: number of hours for pesticide activities *Average salary /Parcel dimension
A12: LABOUR | B12: Cost of labour for fertilisation | C12: With DATs | D12: =IFERROR(VLOOKUP('General Information'!$D$6, Validations!$L$2:$M$8, 2,FALSE), "") -> €/ha | E12: ='Parcel 1 with DATSs'!G196*'General Information'!D39/'Parcel 1 with DATSs'!E10 -> 9.8538976 | F12: number of hours for fertilisation activities * Average salary /Parcel dimension
A13: LABOUR | B13: Cost of labour for sowing_planting | C13: With DATs | D13: =IFERROR(VLOOKUP('General Information'!$D$6, Validations!$L$2:$M$8, 2,FALSE), "") -> €/ha | E13: ='Parcel 1 with DATSs'!G197*'General Information'!D39/'Parcel 1 with DATSs'!E10 -> 9.8538976 | F13: number of hours for sowing_planting activities * Average salary /Parcel dimension
A14: LABOUR | B14: Cost of labour for pruning | C14: With DATs | D14: =IFERROR(VLOOKUP('General Information'!$D$6, Validations!$L$2:$M$8, 2,FALSE), "") -> €/ha | E14: ='Parcel 1 with DATSs'!G198*'General Information'!D39/'Parcel 1 with DATSs'!E10 -> 4.9229399 | F14: number of hours for pruning activities *Average salary /Parcel dimension
A15: LABOUR | B15: Cost of labour for field visits | C15: With DATs | D15: =IFERROR(VLOOKUP('General Information'!$D$6, Validations!$L$2:$M$8, 2,FALSE), "") -> €/ha | E15: ='Parcel 1 with DATSs'!G199*'General Information'!D39/'Parcel 1 with DATSs'!E10 -> 8.4427617 | F15: number of hours for field visits activities * Average professional salary /Parcel dimension
A16: LABOUR | B16: Cost of labour for greenhouse maintenance | C16: With DATs | D16: =IFERROR(VLOOKUP('General Information'!$D$6, Validations!$L$2:$M$8, 2,FALSE), "") -> €/ha | E16: ='Parcel 1 with DATSs'!G200*'General Information'!D39/'Parcel 1 with DATSs'!E10 -> 0 | F16: number of hours for greenhouse management *Average salary /Parcel dimension
A17: LABOUR | B17: Cost of labour for tracking the quantity of grain available in the silo | C17: With DATs | D17: =IFERROR(VLOOKUP('General Information'!$D$6, Validations!$L$2:$M$8, 2,FALSE), "") -> €/ha | E17: ='Parcel 1 with DATSs'!G201*'General Information'!D39/'Parcel 1 with DATSs'!G256 -> #DIV/0! | F17: number of hours for tracking the quantity of grain available in the silo *Average salary
A18: LABOUR | B18: Cost of labour for assessing product quality | C18: With DATs | D18: =IFERROR(VLOOKUP('General Information'!$D$6, Validations!$L$2:$M$8, 2,FALSE), "") -> €/ha | E18: ='Parcel 1 with DATSs'!G202*'General Information'!D39/(IF('General Information'!D6="crop",'Parcel 1 with DATSs'!E10,IF('General Information'!D6="milk",'Parcel 1 with DATSs'!G251,IF('General Information'!D6="meat",'Parcel 1 with DATSs'!G252,IF('General Information'!D6="animal",'Parcel 1 with DATSs'!G253,IF('General Information'!D6="oyster",'Parcel 1 with DATSs'!G254,IF('General Information'!D6="honey",'Parcel 1 with DATSs'!G255,'Parcel 1 with DATSs'!G256))))))) -> 0 | F18: number of hours for assessing grain quality *Average salary
A19: LABOUR | B19: Cost of labour for controlling purchase and sale prices and quantities | C19: With DATs | D19: =IFERROR(VLOOKUP('General Information'!$D$6, Validations!$L$2:$M$8, 2,FALSE), "") -> €/ha | E19: ='Parcel 1 with DATSs'!G203*'General Information'!D39/(IF('General Information'!D6="crop",'Parcel 1 with DATSs'!E10,IF('General Information'!D6="milk",'Parcel 1 with DATSs'!G251,IF('General Information'!D6="meat",'Parcel 1 with DATSs'!G252,IF('General Information'!D6="animal",'Parcel 1 with DATSs'!G253, IF('General Information'!D6="oyster",'Parcel 1 with DATSs'!G254,IF('General Information'!D6="honey",'Parcel 1 with DATSs'!G255,'Parcel 1 with DATSs'!G256))))))) -> 0 | F19: number of hours for controlling purchase and sale prices and quantities *Average salary
A20: LABOUR | B20: Cost of labour for organise logistics | C20: With DATs | D20: =IFERROR(VLOOKUP('General Information'!$D$6, Validations!$L$2:$M$8, 2,FALSE), "") -> €/ha | E20: ='Parcel 1 with DATSs'!G204*'General Information'!D39/(IF('General Information'!D6="crop",'Parcel 1 with DATSs'!E10,IF('General Information'!D6="milk",'Parcel 1 with DATSs'!G251,IF('General Information'!D6="meat",'Parcel 1 with DATSs'!G252,IF('General Information'!D6="animal",'Parcel 1 with DATSs'!G253, IF('General Information'!D6="oyster",'Parcel 1 with DATSs'!G254,IF('General Information'!D6="honey",'Parcel 1 with DATSs'!G255,'Parcel 1 with DATSs'!G256))))))) -> 0 | F20: number of hours for organise logistics *Average salary
A21: LABOUR | B21: Cost of labour for cleaning | C21: With DATs | D21: =IFERROR(VLOOKUP('General Information'!$D$6, Validations!$L$2:$M$8, 2,FALSE), "") -> €/ha | E21: ='Parcel 1 with DATSs'!G205*'General Information'!D39/(IF('General Information'!D6="crop",'Parcel 1 with DATSs'!E10,IF('General Information'!D6="milk",'Parcel 1 with DATSs'!G251,IF('General Information'!D6="meat",'Parcel 1 with DATSs'!G252,IF('General Information'!D6="animal",'Parcel 1 with DATSs'!G253, IF('General Information'!D6="oyster",'Parcel 1 with DATSs'!G254,IF('General Information'!D6="honey",'Parcel 1 with DATSs'!G255,'Parcel 1 with DATSs'!G256))))))) -> 0 | F21: number of hours for cleaning *Average salary /animal
A22: LABOUR | B22: Cost of labour for stable visits | C22: With DATs | D22: =IFERROR(VLOOKUP('General Information'!$D$6, Validations!$L$2:$M$8, 2,FALSE), "") -> €/ha | E22: ='Parcel 1 with DATSs'!G206*'General Information'!D39/(IF('General Information'!D6="crop",'Parcel 1 with DATSs'!E10,IF('General Information'!D6="milk",'Parcel 1 with DATSs'!G251,IF('General Information'!D6="meat",'Parcel 1 with DATSs'!G252,IF('General Information'!D6="animal",'Parcel 1 with DATSs'!G253, IF('General Information'!D6="oyster",'Parcel 1 with DATSs'!G254,IF('General Information'!D6="honey",'Parcel 1 with DATSs'!G255,'Parcel 1 with DATSs'!G256))))))) -> 0 | F22: number of hours for stable visits*Average professional salary /animal
A23: LABOUR | B23: Cost of labour for heat detection | C23: With DATs | D23: =IFERROR(VLOOKUP('General Information'!$D$6, Validations!$L$2:$M$8, 2,FALSE), "") -> €/ha | E23: ='Parcel 1 with DATSs'!G207*'General Information'!D39/(IF('General Information'!D6="crop",'Parcel 1 with DATSs'!E10,IF('General Information'!D6="milk",'Parcel 1 with DATSs'!G251,IF('General Information'!D6="meat",'Parcel 1 with DATSs'!G252,IF('General Information'!D6="animal",'Parcel 1 with DATSs'!G253, IF('General Information'!D6="oyster",'Parcel 1 with DATSs'!G254,IF('General Information'!D6="honey",'Parcel 1 with DATSs'!G255,'Parcel 1 with DATSs'!G256))))))) -> 0 | F23: number of hours for heat detection *Average salary /animal
A24: LABOUR | B24: Cost of labour for calving detection | C24: With DATs | D24: =IFERROR(VLOOKUP('General Information'!$D$6, Validations!$L$2:$M$8, 2,FALSE), "") -> €/ha | E24: ='Parcel 1 with DATSs'!G208*'General Information'!D39/(IF('General Information'!D6="crop",'Parcel 1 with DATSs'!E10,IF('General Information'!D6="milk",'Parcel 1 with DATSs'!G251,IF('General Information'!D6="meat",'Parcel 1 with DATSs'!G252,IF('General Information'!D6="animal",'Parcel 1 with DATSs'!G253, IF('General Information'!D6="oyster",'Parcel 1 with DATSs'!G254,IF('General Information'!D6="honey",'Parcel 1 with DATSs'!G255,'Parcel 1 with DATSs'!G256))))))) -> 0 | F24: number of hours for calving detection *Average salary /animal
A25: LABOUR | B25: Cost of labour for pigsty management | C25: With DATs | D25: =IFERROR(VLOOKUP('General Information'!$D$6, Validations!$L$2:$M$8, 2,FALSE), "") -> €/ha | E25: ='Parcel 1 with DATSs'!G209*'General Information'!D39/(IF('General Information'!D6="crop",'Parcel 1 with DATSs'!E10,IF('General Information'!D6="milk",'Parcel 1 with DATSs'!G251,IF('General Information'!D6="meat",'Parcel 1 with DATSs'!G252,IF('General Information'!D6="animal",'Parcel 1 with DATSs'!G253, IF('General Information'!D6="oyster",'Parcel 1 with DATSs'!G254,IF('General Information'!D6="honey",'Parcel 1 with DATSs'!G255,'Parcel 1 with DATSs'!G256))))))) -> 0 | F25: number of hours for pigsty management*Average salary /animal
A26: LABOUR | B26: Cost of milking | C26: With DATs | D26: =IFERROR(VLOOKUP('General Information'!$D$6, Validations!$L$2:$M$8, 2,FALSE), "") -> €/ha | E26: ='Parcel 1 with DATSs'!G210*'General Information'!D39/(IF('General Information'!D6="crop",'Parcel 1 with DATSs'!E10,IF('General Information'!D6="milk",'Parcel 1 with DATSs'!G251,IF('General Information'!D6="meat",'Parcel 1 with DATSs'!G252,IF('General Information'!D6="animal",'Parcel 1 with DATSs'!G253, IF('General Information'!D6="oyster",'Parcel 1 with DATSs'!G254,IF('General Information'!D6="honey",'Parcel 1 with DATSs'!G255,'Parcel 1 with DATSs'!G256))))))) -> 0 | F26: number of hours for milking *Average salary /animal
A27: LABOUR | B27: Cost of labour for (milk) quality assessment | C27: With DATs | D27: =IFERROR(VLOOKUP('General Information'!$D$6, Validations!$L$2:$M$8, 2,FALSE), "") -> €/ha | E27: ='Parcel 1 with DATSs'!G211*'General Information'!D39/(IF('General Information'!D6="crop",'Parcel 1 with DATSs'!E10,IF('General Information'!D6="milk",'Parcel 1 with DATSs'!G251,IF('General Information'!D6="meat",'Parcel 1 with DATSs'!G252,IF('General Information'!D6="animal",'Parcel 1 with DATSs'!G253, IF('General Information'!D6="oyster",'Parcel 1 with DATSs'!G254,IF('General Information'!D6="honey",'Parcel 1 with DATSs'!G255,'Parcel 1 with DATSs'!G256))))))) -> 0 | F27: number of hours for (milk) quality assessment*Average salary /animal
A28: LABOUR | B28: Cost of labour for feeding | C28: With DATs | D28: =IFERROR(VLOOKUP('General Information'!$D$6, Validations!$L$2:$M$8, 2,FALSE), "") -> €/ha | E28: ='Parcel 1 with DATSs'!G212*'General Information'!D39/(IF('General Information'!D6="crop",'Parcel 1 with DATSs'!E10,IF('General Information'!D6="milk",'Parcel 1 with DATSs'!G251,IF('General Information'!D6="meat",'Parcel 1 with DATSs'!G252,IF('General Information'!D6="animal",'Parcel 1 with DATSs'!G253, IF('General Information'!D6="oyster",'Parcel 1 with DATSs'!G254,IF('General Information'!D6="honey",'Parcel 1 with DATSs'!G255,'Parcel 1 with DATSs'!G256))))))) -> 0 | F28: number of hours for feeding *Average salary /animal
A29: LABOUR | B29: Cost of labour for beehives visits | C29: With DATs | D29: =IFERROR(VLOOKUP('General Information'!$D$6, Validations!$L$2:$M$8, 2,FALSE), "") -> €/ha | E29: ='Parcel 1 with DATSs'!G213*'General Information'!D39/'Parcel 1 with DATSs'!G255 -> #DIV/0! | F29: number of hours for beehives visits *Average salary / beehive
A30: LABOUR | B30: Cost of labour for sampling of oysters | C30: With DATs | D30: =IFERROR(VLOOKUP('General Information'!$D$6, Validations!$L$2:$M$8, 2,FALSE), "") -> €/ha | E30: ='Parcel 1 with DATSs'!G214*'General Information'!D39/'Parcel 1 with DATSs'!G254 -> #DIV/0! | F30: number of hours for sampling of oysters* Average salary /piece
A31: LABOUR | B31: Cost of labour for transporting oysters to the laboratory | C31: With DATs | D31: =IFERROR(VLOOKUP('General Information'!$D$6, Validations!$L$2:$M$8, 2,FALSE), "") -> €/ha | E31: ='Parcel 1 with DATSs'!G215*'General Information'!D39/'Parcel 1 with DATSs'!G254 -> #DIV/0! | F31: number of hours for transporting oysters to the laboratory*Average salary /piece
A32: LABOUR | B32: Cost of labour for harvesting | C32: With DATs | D32: =IFERROR(VLOOKUP('General Information'!$D$6, Validations!$L$2:$M$8, 2,FALSE), "") -> €/ha | E32: ='Parcel 1 with DATSs'!G216*'General Information'!$D$39/(IF('General Information'!D6="crop",'Parcel 1 with DATSs'!E10,IF('General Information'!D6="milk",'Parcel 1 with DATSs'!G251,IF('General Information'!D6="meat",'Parcel 1 with DATSs'!G252,IF('General Information'!D6="animal",'Parcel 1 with DATSs'!G253, IF('General Information'!D6="oyster",'Parcel 1 with DATSs'!G254,IF('General Information'!D6="honey",'Parcel 1 with DATSs'!G255,'Parcel 1 with DATSs'!G256))))))) -> 14.776837 | F32: number of hours for harvesting oyster*Average salary /piece
A33: LABOUR | B33: Cost of labour for storage | C33: With DATs | D33: =IFERROR(VLOOKUP('General Information'!$D$6, Validations!$L$2:$M$8, 2,FALSE), "") -> €/ha | E33: ='Parcel 1 with DATSs'!G217*'General Information'!D39/(IF('General Information'!D6="crop",'Parcel 1 with DATSs'!E10,IF('General Information'!D6="milk",'Parcel 1 with DATSs'!G251,IF('General Information'!D6="meat",'Parcel 1 with DATSs'!G252,IF('General Information'!D6="animal",'Parcel 1 with DATSs'!G253, IF('General Information'!D6="oyster",'Parcel 1 with DATSs'!G254,IF('General Information'!D6="honey",'Parcel 1 with DATSs'!G255,'Parcel 1 with DATSs'!G256))))))) -> 0 | F33: number of hours for storage *Average salary /piece
A34: LABOUR | B34: Cost of administrative activities, data collection, etc. | C34: With DATs | D34: =IFERROR(VLOOKUP('General Information'!$D$6, Validations!$L$2:$M$8, 2,FALSE), "") -> €/ha | E34: ='Parcel 1 with DATSs'!G218*'General Information'!$D$39/(IF('General Information'!D6="crop",'Parcel 1 with DATSs'!E10,IF('General Information'!D6="milk",'Parcel 1 with DATSs'!G251,IF('General Information'!D6="meat",'Parcel 1 with DATSs'!G252,IF('General Information'!D6="animal",'Parcel 1 with DATSs'!G253, IF('General Information'!D6="oyster",'Parcel 1 with DATSs'!G254,IF('General Information'!D6="honey",'Parcel 1 with DATSs'!G255,'Parcel 1 with DATSs'!G256))))))) -> 8.4427617 | F34: number of hours foradministrative activities *Average salary /parcel dimension or animal or beehives or pieces
A35: COST | B35: TOT Cost | C35: With DATs | D35: =IFERROR(VLOOKUP('General Information'!$D$6, Validations!$L$2:$M$8, 2,FALSE), "") -> €/ha | E35: =_xlfn.AGGREGATE(9,6,E3:E34) -> 487.53814 | F35: Sum(Cost of labour for irrigation + Cost of labour for fertilisation + … /parcel dimension or animal or beehives or pieces
A36: DATSs | B36: Cost of DATSs | C36: With DATs | D36: =IFERROR(VLOOKUP('General Information'!$D$6, Validations!$L$2:$M$8, 2,FALSE), "") -> €/ha | E36: =(('General Information'!D23+'General Information'!D24)+('General Information'!H23+'General Information'!H24)+('General Information'!L23+'General Information'!L24))/(IF('General Information'!D6="crop",'Parcel 1 with DATSs'!E10,IF('General Information'!D6="milk",'Parcel 1 with DATSs'!G251,IF('General Information'!D6="meat",'Parcel 1 with DATSs'!G252,IF('General Information'!D6="animal",'Parcel 1 with DATSs'!G253, IF('General Information'!D6="oyster",'Parcel 1 with DATSs'!G254,IF('General Information'!D6="honey",'Parcel 1 with DATSs'!G255,'Parcel 1 with DATSs'!G256))))))) -> 1.7817372 | F36: DAT maintenance + (Training hours*salary) /parcel dimension or animal or beehives or pieces
A37: DATSs | B37: Cost of Training | C37: With DATs | D37: =IFERROR(VLOOKUP('General Information'!$D$6, Validations!$L$2:$M$8, 2,FALSE), "") -> €/ha | E37: ='General Information'!D27/(IF('General Information'!D6="crop",'Parcel 1 with DATSs'!E10,IF('General Information'!D6="milk",'Parcel 1 with DATSs'!G251,IF('General Information'!D6="meat",'Parcel 1 with DATSs'!G252,IF('General Information'!D6="animal",'Parcel 1 with DATSs'!G253, IF('General Information'!D6="oyster",'Parcel 1 with DATSs'!G254,IF('General Information'!D6="honey",'Parcel 1 with DATSs'!G255,'Parcel 1 with DATSs'!G256))))))) -> 1.3363029 | F37: Costs of external persons being paid to train employees on the use of DAT /parcel dimension or animal or beehives or pieces
A39: REVENUES ANALYSIS
A40: CATEGORY | B40: INDICATOR | C40: SCENARIO | D40: UoM | E40: TOTAL | F40: FORMULAS
A41: OUTPUT | B41: Crop revenue | C41: With DATs | D41: €/ha | E41: ='Parcel 1 with DATSs'!G250/'Parcel 1 with DATSs'!E10*'General Information'!$D$41 -> 1217.4254 | F41: Yield*Product market price
...

Sheet Cost-revenue NO DATS
A1: COST ANALYSIS
A2: INPUT | B2: INDICATOR | C2: SCENARIO | D2: UoM | E2: TOTAL | F2: FORMULAS
A3: WATER | B3: Cost of water | C3: Without DATs | D3: =IFERROR(VLOOKUP('General Information'!$D$6, Validations!$L$2:$M$8, 2,FALSE), "") -> €/ha | E3: =('Parcel 1 without DATSs'!G29*'General Information'!H32)/(IF('General Information'!D6="crop",'Parcel 1 without DATSs'!E10,IF('General Information'!D6="milk",'Parcel 1 without DATSs'!G251,IF('General Information'!D6="meat",'Parcel 1 without DATSs'!G252,IF('General Information'!D6="animal",'Parcel 1 without DATSs'!G253,IF('General Information'!D6="oyster",'Parcel 1 without DATSs'!G254,IF('General Information'!D6="honey",'Parcel 1 without DATSs'!G255,'Parcel 1 without DATSs'!G256))))))) -> 0 | F3: IF(Total water used>0; (Total water used * water price)/Parcel dimension; Sum(water Irrigation+ water Fertigation + water Pest dilution + …) * water price)
A4: FUEL | B4: Cost of fuel | C4: Without DATs | D4: =IFERROR(VLOOKUP('General Information'!$D$6, Validations!$L$2:$M$8, 2,FALSE), "") -> €/ha | E4: ='Parcel 1 without DATSs'!G43*'General Information'!H33/(IF('General Information'!D6="crop",'Parcel 1 without DATSs'!E10,IF('General Information'!D6="milk",'Parcel 1 without DATSs'!G251,IF('General Information'!D6="meat",'Parcel 1 without DATSs'!G252,IF('General Information'!D6="animal",'Parcel 1 without DATSs'!G253,IF('General Information'!D6="oyster",'Parcel 1 without DATSs'!G254,IF('General Information'!D6="honey",'Parcel 1 without DATSs'!G255,'Parcel 1 without DATSs'!G256))))))) -> 61.646635 | F4: IF(Total fuel used>0; (Total fuel used*fuel price)/Parcel dimension; sum(Fertilisation+Pesticides +Irrigation+Sowing_Planting+Pruning+…) * fuel price)
A5: ELECTRICITY | B5: Cost of electricity | C5: Without DATs | D5: =IFERROR(VLOOKUP('General Information'!$D$6, Validations!$L$2:$M$8, 2,FALSE), "") -> €/ha | E5: ='Parcel 1 without DATSs'!G62*'General Information'!H38/(IF('General Information'!D6="crop",'Parcel 1 without DATSs'!E10,IF('General Information'!D6="milk",'Parcel 1 without DATSs'!G251,IF('General Information'!D6="meat",'Parcel 1 without DATSs'!G252,IF('General Information'!D6="animal",'Parcel 1 without DATSs'!G253,IF('General Information'!D6="oyster",'Parcel 1 without DATSs'!G254,IF('General Information'!D6="honey",'Parcel 1 without DATSs'!G255,'Parcel 1 without DATSs'!G256))))))) -> 0.76632692 | F5: IF(Total electricity used > 0; (Total electricity used* electricity price)/Parcel dimension; Sum(irrigation,…) *electricity price)
A6: PESTICIDE | B6: Cost for pesticide | C6: Without DATs | D6: =IFERROR(VLOOKUP('General Information'!$D$6, Validations!$L$2:$M$8, 2,FALSE), "") -> €/ha | E6: =('Parcel 1 without DATSs'!G67*'Parcel 1 without DATSs'!G68*'General Information'!H43)+ ('Parcel 1 without DATSs'!G70*'Parcel 1 without DATSs'!G71*'General Information'!H44)+ ('Parcel 1 without DATSs'!G73*'Parcel 1 without DATSs'!G74*'General Information'!H45)+ ('Parcel 1 without DATSs'!G76*'Parcel 1 without DATSs'!G77*'General Information'!H46)+ ('Parcel 1 without DATSs'!G79*'Parcel 1 without DATSs'!G80*'General Information'!H47)+ ('Parcel 1 without DATSs'!G82*'Parcel 1 without DATSs'!G83*'General Information'!H48)+ ('Parcel 1 without DATSs'!G85*'Parcel 1 without DATSs'!G86*'General Information'!H49)+ ('Parcel 1 without DATSs'!G88*'Parcel 1 without DATSs'!G89*'General Information'!H50)+ ('Parcel 1 without DATSs'!G91*'Parcel 1 without DATSs'!G92*'General Information'!H51)+ ('Parcel 1 without DATSs'!G94*'Parcel 1 without DATSs'!G95*'General Information'!H52) -> 115.792 | F6: [(N. of treatements of pesticide 1*Amount of pesticide 1*pesticide 1 price)+(N. of treatements of pesticide 2 *Amount of pesticide 2 used *pesticide 2 price) + (N. of treatements of pesticide 3 *Amount of pesticide 3 used *pesticide 3 price (€/kg)]
A7: FERTILISER | B7: Cost of fertiliser | C7: Without DATs | D7: =IFERROR(VLOOKUP('General Information'!$D$6, Validations!$L$2:$M$8, 2,FALSE), "") -> €/ha | E7: =('Parcel 1 without DATSs'!G101*'Parcel 1 without DATSs'!G102*'General Information'!H54)+ ('Parcel 1 without DATSs'!G108*'Parcel 1 without DATSs'!G109*'General Information'!H55)+ ('Parcel 1 without DATSs'!G115*'Parcel 1 without DATSs'!G116*'General Information'!H56)+ ('Parcel 1 without DATSs'!G122*'Parcel 1 without DATSs'!G123*'General Information'!H57)+ ('Parcel 1 without DATSs'!G129*'Parcel 1 without DATSs'!G130*'General Information'!H58)+ ('Parcel 1 without DATSs'!G136*'Parcel 1 without DATSs'!G137*'General Information'!H59)+ ('Parcel 1 without DATSs'!G143*'Parcel 1 without DATSs'!G144*'General Information'!H60)+ ('Parcel 1 without DATSs'!G150*'Parcel 1 without DATSs'!G151*'General Information'!H61)+ ('Parcel 1 without DATSs'!G157*'Parcel 1 without DATSs'!G158*'General Information'!H62)+ ('Parcel 1 without DATSs'!G164*'Parcel 1 without DATSs'!G165*'General Information'!H63) -> 247.545 | F7: ((Amount of fertilisers 1 used *Number of fertilizer 1 applications *Fertilisers 1 price) + (Amount of fertilisers 2 used *Number of fertilizer 2 applications *Fertilisers 2 price) + (Amount of fertilisers 3 used *Number of fertilizer 3 applications *Fertilisers 3 price)
A8: FEED | B8: Cost of feed | C8: Without DATs | D8: =IFERROR(VLOOKUP('General Information'!$D$6, Validations!$L$2:$M$8, 2,FALSE), "") -> €/ha | E8: =('General Information'!H65*'Parcel 1 without DATSs'!G173+'General Information'!H66*'Parcel 1 without DATSs'!G175+'General Information'!H69*'Parcel 1 without DATSs'!G177)/(IF('General Information'!D6="crop",'Parcel 1 without DATSs'!E10,IF('General Information'!D6="milk",'Parcel 1 without DATSs'!G251,IF('General Information'!D6="meat",'Parcel 1 without DATSs'!G252,IF('General Information'!D6="animal",'Parcel 1 without DATSs'!G253,IF('General Information'!D6="oyster",'Parcel 1 without DATSs'!G254,IF('General Information'!D6="honey",'Parcel 1 without DATSs'!G255,'Parcel 1 without DATSs'!G256))))))) -> 0 | F8: (Amount of feed 1 * Feed 1 price) + (Amount of feed 2 * Feed 2 price) + … /animal
A9: DRUGS | B9: Cost of drugs | C9: Without DATs | D9: =IFERROR(VLOOKUP('General Information'!$D$6, Validations!$L$2:$M$8, 2,FALSE), "") -> €/ha | E9: =('General Information'!H71*'Parcel 1 without DATSs'!G186+'General Information'!H72*'Parcel 1 without DATSs'!G188+'General Information'!H73*'Parcel 1 without DATSs'!G190)/(IF('General Information'!D6="crop",'Parcel 1 without DATSs'!E10,IF('General Information'!D6="milk",'Parcel 1 without DATSs'!G251,IF('General Information'!D6="meat",'Parcel 1 without DATSs'!G252,IF('General Information'!D6="animal",'Parcel 1 without DATSs'!G253,IF('General Information'!D6="oyster",'Parcel 1 without DATSs'!G254,IF('General Information'!D6="honey",'Parcel 1 without DATSs'!G255,'Parcel 1 without DATSs'!G256))))))) -> 0 | F9: (Amount of drugs 1 * Feed 1 price) + (Amount of drugs 2 * Feed 2 price) + … /animal or beehives or pieces
A10: LABOUR | B10: Cost of labour for irrigation | C10: Without DATs | D10: =IFERROR(VLOOKUP('General Information'!$D$6, Validations!$L$2:$M$8, 2,FALSE), "") -> €/ha | E10: ='Parcel 1 without DATSs'!G194*'General Information'!H39/'Parcel 1 without DATSs'!E10 -> 0 | F10: number of hours for irrigation activities*Average salary /Parcel dimension
A11: LABOUR | B11: Cost of labour for pesticide | C11: Without DATs | D11: =IFERROR(VLOOKUP('General Information'!$D$6, Validations!$L$2:$M$8, 2,FALSE), "") -> €/ha | E11: ='Parcel 1 without DATSs'!G195*'General Information'!H39/'Parcel 1 without DATSs'!E10 -> 22.707692 | F11: number of hours for pesticide activities *Average salary /Parcel dimension
A12: LABOUR | B12: Cost of labour for fertilisation | C12: Without DATs | D12: =IFERROR(VLOOKUP('General Information'!$D$6, Validations!$L$2:$M$8, 2,FALSE), "") -> €/ha | E12: ='Parcel 1 without DATSs'!G196*'General Information'!H39/'Parcel 1 without DATSs'!E10 -> 13.430769 | F12: number of hours for fertilisation activities * Average salary /Parcel dimension
A13: LABOUR | B13: Cost of labour for sowing_planting | C13: Without DATs | D13: =IFERROR(VLOOKUP('General Information'!$D$6, Validations!$L$2:$M$8, 2,FALSE), "") -> €/ha | E13: ='Parcel 1 without DATSs'!G197*'General Information'!H39/'Parcel 1 without DATSs'!E10 -> 20.665385 | F13: number of hours for sowing_planting activities * Average salary /Parcel dimension
A14: LABOUR | B14: Cost of labour for pruning | C14: Without DATs | D14: =IFERROR(VLOOKUP('General Information'!$D$6, Validations!$L$2:$M$8, 2,FALSE), "") -> €/ha | E14: ='Parcel 1 without DATSs'!G198*'General Information'!H39/'Parcel 1 without DATSs'!E10 -> 5.1576923 | F14: number of hours for pruning activities *Average salary /Parcel dimension
A15: LABOUR | B15: Cost of labour for field visits | C15: Without DATs | D15: =IFERROR(VLOOKUP('General Information'!$D$6, Validations!$L$2:$M$8, 2,FALSE), "") -> €/ha | E15: ='Parcel 1 without DATSs'!G199*'General Information'!H39/'Parcel 1 without DATSs'!E10 -> 13.673077 | F15: number of hours for field visits activities * Average professional salary /Parcel dimension
A16: LABOUR | B16: Cost of labour for greenhouse management | C16: Without DATs | D16: =IFERROR(VLOOKUP('General Information'!$D$6, Validations!$L$2:$M$8, 2,FALSE), "") -> €/ha | E16: ='Parcel 1 without DATSs'!G200*'General Information'!H39/'Parcel 1 without DATSs'!E10 -> 0 | F16: number of hours for greenhouse management *Average salary /Parcel dimension
A17: LABOUR | B17: Cost of labour for tracking the quantity of grain available in the silo | C17: Without DATs | D17: =IFERROR(VLOOKUP('General Information'!$D$6, Validations!$L$2:$M$8, 2,FALSE), "") -> €/ha | E17: ='Parcel 1 without DATSs'!G201*'General Information'!H39/'Parcel 1 without DATSs'!E10 -> 0 | F17: number of hours for tracking the quantity of grain available in the silo *Average salary
A18: LABOUR | B18: Cost of labour for assessing product quality | C18: Without DATs | D18: =IFERROR(VLOOKUP('General Information'!$D$6, Validations!$L$2:$M$8, 2,FALSE), "") -> €/ha | E18: ='Parcel 1 without DATSs'!G202*'General Information'!H39/(IF('General Information'!D6="crop",'Parcel 1 without DATSs'!E10,IF('General Information'!D6="milk",'Parcel 1 without DATSs'!G251,IF('General Information'!D6="meat",'Parcel 1 without DATSs'!G252,IF('General Information'!D6="animal",'Parcel 1 without DATSs'!G253,IF('General Information'!D6="oyster",'Parcel 1 without DATSs'!G254,IF('General Information'!D6="honey",'Parcel 1 without DATSs'!G255,'Parcel 1 without DATSs'!G256))))))) -> 0 | F18: number of hours for assessing grain quality *Average salary
A19: LABOUR | B19: Cost of labour for controlling purchase and sale prices and quantities | C19: Without DATs | D19: =IFERROR(VLOOKUP('General Information'!$D$6, Validations!$L$2:$M$8, 2,FALSE), "") -> €/ha | E19: ='Parcel 1 without DATSs'!G203*'General Information'!H39/(IF('General Information'!D6="crop",'Parcel 1 without DATSs'!E10,IF('General Information'!D6="milk",'Parcel 1 without DATSs'!G251,IF('General Information'!D6="meat",'Parcel 1 without DATSs'!G252,IF('General Information'!D6="animal",'Parcel 1 without DATSs'!G253,IF('General Information'!D6="oyster",'Parcel 1 without DATSs'!G254,IF('General Information'!D6="honey",'Parcel 1 without DATSs'!G255,'Parcel 1 without DATSs'!G256))))))) -> 0 | F19: number of hours for controlling purchase and sale prices and quantities *Average salary
A20: LABOUR | B20: Cost of labour for organising logistics | C20: Without DATs | D20: =IFERROR(VLOOKUP('General Information'!$D$6, Validations!$L$2:$M$8, 2,FALSE), "") -> €/ha | E20: ='Parcel 1 without DATSs'!G204*'General Information'!H39/(IF('General Information'!D6="crop",'Parcel 1 without DATSs'!E10,IF('General Information'!D6="milk",'Parcel 1 without DATSs'!G251,IF('General Information'!D6="meat",'Parcel 1 without DATSs'!G252,IF('General Information'!D6="animal",'Parcel 1 without DATSs'!G253,IF('General Information'!D6="oyster",'Parcel 1 without DATSs'!G254,IF('General Information'!D6="honey",'Parcel 1 without DATSs'!G255,'Parcel 1 without DATSs'!G256))))))) -> 0 | F20: number of hours for organise logistics *Average salary
A21: LABOUR | B21: Cost of labour for cleaning | C21: Without DATs | D21: =IFERROR(VLOOKUP('General Information'!$D$6, Validations!$L$2:$M$8, 2,FALSE), "") -> €/ha | E21: ='Parcel 1 without DATSs'!G205*'General Information'!H39/(IF('General Information'!D6="crop",'Parcel 1 without DATSs'!E10,IF('General Information'!D6="milk",'Parcel 1 without DATSs'!G251,IF('General Information'!D6="meat",'Parcel 1 without DATSs'!G252,IF('General Information'!D6="animal",'Parcel 1 without DATSs'!G253,IF('General Information'!D6="oyster",'Parcel 1 without DATSs'!G254,IF('General Information'!D6="honey",'Parcel 1 without DATSs'!G255,'Parcel 1 without DATSs'!G256))))))) -> 0 | F21: number of hours for cleaning *Average salary /animal
A22: LABOUR | B22: Cost of labour for stable visits | C22: Without DATs | D22: =IFERROR(VLOOKUP('General Information'!$D$6, Validations!$L$2:$M$8, 2,FALSE), "") -> €/ha | E22: ='Parcel 1 without DATSs'!G206*'General Information'!H39/(IF('General Information'!D6="crop",'Parcel 1 without DATSs'!E10,IF('General Information'!D6="milk",'Parcel 1 without DATSs'!G251,IF('General Information'!D6="meat",'Parcel 1 without DATSs'!G252,IF('General Information'!D6="animal",'Parcel 1 without DATSs'!G253,IF('General Information'!D6="oyster",'Parcel 1 without DATSs'!G254,IF('General Information'!D6="honey",'Parcel 1 without DATSs'!G255,'Parcel 1 without DATSs'!G256))))))) -> 0 | F22: number of hours for stable visits*Average professional salary /animal
A23: LABOUR | B23: Cost of labour for heat detection | C23: Without DATs | D23: =IFERROR(VLOOKUP('General Information'!$D$6, Validations!$L$2:$M$8, 2,FALSE), "") -> €/ha | E23: ='Parcel 1 without DATSs'!G207*'General Information'!H39/(IF('General Information'!D6="crop",'Parcel 1 without DATSs'!E10,IF('General Information'!D6="milk",'Parcel 1 without DATSs'!G251,IF('General Information'!D6="meat",'Parcel 1 without DATSs'!G252,IF('General Information'!D6="animal",'Parcel 1 without DATSs'!G253,IF('General Information'!D6="oyster",'Parcel 1 without DATSs'!G254,IF('General Information'!D6="honey",'Parcel 1 without DATSs'!G255,'Parcel 1 without DATSs'!G256))))))) -> 0 | F23: number of hours for heat detection *Average salary /animal
A24: LABOUR | B24: Cost of labour for calving detection | C24: Without DATs | D24: =IFERROR(VLOOKUP('General Information'!$D$6, Validations!$L$2:$M$8, 2,FALSE), "") -> €/ha | E24: ='Parcel 1 without DATSs'!G208*'General Information'!H39/(IF('General Information'!D6="crop",'Parcel 1 without DATSs'!E10,IF('General Information'!D6="milk",'Parcel 1 without DATSs'!G251,IF('General Information'!D6="meat",'Parcel 1 without DATSs'!G252,IF('General Information'!D6="animal",'Parcel 1 without DATSs'!G253,IF('General Information'!D6="oyster",'Parcel 1 without DATSs'!G254,IF('General Information'!D6="honey",'Parcel 1 without DATSs'!G255,'Parcel 1 without DATSs'!G256))))))) -> 0 | F24: number of hours for calving detection *Average salary /animal
A25: LABOUR | B25: Cost of labour for pigsty management | C25: Without DATs | D25: =IFERROR(VLOOKUP('General Information'!$D$6, Validations!$L$2:$M$8, 2,FALSE), "") -> €/ha | E25: ='Parcel 1 without DATSs'!G209*'General Information'!H39/(IF('General Information'!D6="crop",'Parcel 1 without DATSs'!E10,IF('General Information'!D6="milk",'Parcel 1 without DATSs'!G251,IF('General Information'!D6="meat",'Parcel 1 without DATSs'!G252,IF('General Information'!D6="animal",'Parcel 1 without DATSs'!G253,IF('General Information'!D6="oyster",'Parcel 1 without DATSs'!G254,IF('General Information'!D6="honey",'Parcel 1 without DATSs'!G255,'Parcel 1 without DATSs'!G256))))))) -> 0 | F25: number of hours for pigsty management*Average salary /animal
A26: LABOUR | B26: Cost of milking | C26: Without DATs | D26: =IFERROR(VLOOKUP('General Information'!$D$6, Validations!$L$2:$M$8, 2,FALSE), "") -> €/ha | E26: ='Parcel 1 without DATSs'!G210*'General Information'!H39/(IF('General Information'!D6="crop",'Parcel 1 without DATSs'!E10,IF('General Information'!D6="milk",'Parcel 1 without DATSs'!G251,IF('General Information'!D6="meat",'Parcel 1 without DATSs'!G252,IF('General Information'!D6="animal",'Parcel 1 without DATSs'!G253,IF('General Information'!D6="oyster",'Parcel 1 without DATSs'!G254,IF('General Information'!D6="honey",'Parcel 1 without DATSs'!G255,'Parcel 1 without DATSs'!G256))))))) -> 0 | F26: number of hours for milking *Average salary /animal
A27: LABOUR | B27: Cost of labour for (milk) quality assessment | C27: Without DATs | D27: =IFERROR(VLOOKUP('General Information'!$D$6, Validations!$L$2:$M$8, 2,FALSE), "") -> €/ha | E27: ='Parcel 1 without DATSs'!G211*'General Information'!H39/(IF('General Information'!D6="crop",'Parcel 1 without DATSs'!E10,IF('General Information'!D6="milk",'Parcel 1 without DATSs'!G251,IF('General Information'!D6="meat",'Parcel 1 without DATSs'!G252,IF('General Information'!D6="animal",'Parcel 1 without DATSs'!G253,IF('General Information'!D6="oyster",'Parcel 1 without DATSs'!G254,IF('General Information'!D6="honey",'Parcel 1 without DATSs'!G255,'Parcel 1 without DATSs'!G256))))))) -> 0 | F27: number of hours for (milk) quality assessment*Average salary /animal
A28: LABOUR | B28: Cost of labour for feeding | C28: Without DATs | D28: =IFERROR(VLOOKUP('General Information'!$D$6, Validations!$L$2:$M$8, 2,FALSE), "") -> €/ha | E28: ='Parcel 1 without DATSs'!G212*'General Information'!H39/(IF('General Information'!D6="crop",'Parcel 1 without DATSs'!E10,IF('General Information'!D6="milk",'Parcel 1 without DATSs'!G251,IF('General Information'!D6="meat",'Parcel 1 without DATSs'!G252,IF('General Information'!D6="animal",'Parcel 1 without DATSs'!G253,IF('General Information'!D6="oyster",'Parcel 1 without DATSs'!G254,IF('General Information'!D6="honey",'Parcel 1 without DATSs'!G255,'Parcel 1 without DATSs'!G256))))))) -> 0 | F28: number of hours for feeding *Average salary /animal
A29: LABOUR | B29: Cost of labour for beehives visits | C29: Without DATs | D29: =IFERROR(VLOOKUP('General Information'!$D$6, Validations!$L$2:$M$8, 2,FALSE), "") -> €/ha | E29: ='Parcel 1 without DATSs'!G213*'General Information'!H39/'Parcel 1 without DATSs'!E19 -> #DIV/0! | F29: number of hours for beehives visits *Average salary / beehive
A30: LABOUR | B30: Cost of labour for sampling of oysters | C30: Without DATs | D30: =IFERROR(VLOOKUP('General Information'!$D$6, Validations!$L$2:$M$8, 2,FALSE), "") -> €/ha | E30: ='Parcel 1 without DATSs'!G214*'General Information'!H39/'Parcel 1 without DATSs'!G254 -> #DIV/0! | F30: number of hours for sampling of oysters* Average salary /piece
A31: LABOUR | B31: Cost of labour for transporting oysters to the laboratory | C31: Without DATs | D31: =IFERROR(VLOOKUP('General Information'!$D$6, Validations!$L$2:$M$8, 2,FALSE), "") -> €/ha | E31: ='Parcel 1 without DATSs'!G215*'General Information'!H39/'Parcel 1 without DATSs'!G254 -> #DIV/0! | F31: number of hours for transporting oysters to the laboratory*Average salary /piece
A32: LABOUR | B32: Cost of labour for harvesting | C32: Without DATs | D32: =IFERROR(VLOOKUP('General Information'!$D$6, Validations!$L$2:$M$8, 2,FALSE), "") -> €/ha | E32: ='Parcel 1 without DATSs'!G216*'General Information'!H39/(IF('General Information'!D6="crop",'Parcel 1 without DATSs'!E10,IF('General Information'!D6="milk",'Parcel 1 without DATSs'!G251,IF('General Information'!D6="meat",'Parcel 1 without DATSs'!G252,IF('General Information'!D6="animal",'Parcel 1 without DATSs'!G253,IF('General Information'!D6="oyster",'Parcel 1 without DATSs'!G254,IF('General Information'!D6="honey",'Parcel 1 without DATSs'!G255,'Parcel 1 without DATSs'!G256))))))) -> 30.980769 | F32: number of hours for harvesting oyster*Average salary /piece
A33: LABOUR | B33: Cost of labour for storage | C33: Without DATs | D33: =IFERROR(VLOOKUP('General Information'!$D$6, Validations!$L$2:$M$8, 2,FALSE), "") -> €/ha | E33: ='Parcel 1 without DATSs'!G217*'General Information'!H39/(IF('General Information'!D6="crop",'Parcel 1 without DATSs'!E10,IF('General Information'!D6="milk",'Parcel 1 without DATSs'!G251,IF('General Information'!D6="meat",'Parcel 1 without DATSs'!G252,IF('General Information'!D6="animal",'Parcel 1 without DATSs'!G253,IF('General Information'!D6="oyster",'Parcel 1 without DATSs'!G254,IF('General Information'!D6="honey",'Parcel 1 without DATSs'!G255,'Parcel 1 without DATSs'!G256))))))) -> 0 | F33: number of hours for storage *Average salary /piece
A34: LABOUR | B34: Cost of administrative activities, data collection, etc. | C34: Without DATs | D34: =IFERROR(VLOOKUP('General Information'!$D$6, Validations!$L$2:$M$8, 2,FALSE), "") -> €/ha | E34: ='Parcel 1 without DATSs'!G218*'General Information'!H39/(IF('General Information'!D6="crop",'Parcel 1 without DATSs'!E10,IF('General Information'!D6="milk",'Parcel 1 without DATSs'!G251,IF('General Information'!D6="meat",'Parcel 1 without DATSs'!G252,IF('General Information'!D6="animal",'Parcel 1 without DATSs'!G253,IF('General Information'!D6="oyster",'Parcel 1 without DATSs'!G254,IF('General Information'!D6="honey",'Parcel 1 without DATSs'!G255,'Parcel 1 without DATSs'!G256))))))) -> 13.673077 | F34: number of hours foradministrative activities *Average salary /parcel dimension or animal or beehives or pieces
A35: COST | B35: TOT Cost | C35: Without DATs | D35: =IFERROR(VLOOKUP('General Information'!$D$6, Validations!$L$2:$M$8, 2,FALSE), "") -> €/ha | E35: =_xlfn.AGGREGATE(9,6,E3:E34) -> 546.03842 | F35: Sum(Cost of labour for irrigation + Cost of labour for fertilisation + … /parcel dimension or animal or beehives or pieces
A36: DAT | B36: Cost of DAT | C36: Without DATs | E36: 0
A37: DAT | B37: Cost of Training | C37: Without DATs | E37: 0
A39: REVENUES ANALYSIS
A40: CATEGORY | B40: INDICATOR | C40: SCENARIO | D40: UoM | E40: TOTAL | F40: FORMULAS
A41: OUTPUT | B41: Crop revenue | C41: Without DATs | D41: €/ha | E41: ='Parcel 1 without DATSs'!G250/'Parcel 1 without DATSs'!E10*'General Information'!H41 -> 1070.7692 | F41: Yield*Product market price
...

Sheet sust. impact KPIs DATS
A1: Economic - PRODUCTIVITY
B2: INDICATOR | C2: SCENARIO | D2: UoM | E2: TOTAL | F2: FORMULAS
B3: Yield | C3: With DATs | D3: t / ha | E3: ='Parcel 1 with DATSs'!G250/'Parcel 1 with DATSs'!E10 -> 6.3407572 | F3: total production / parcel area
B4: Labour productivity (arable and horticulture) | C4: With DATs | D4: t / h | E4: ='Parcel 1 with DATSs'!G250/SUM('Parcel 1 with DATSs'!G194:G218) -> 0.60075965 | F4: total production / hours of labour employed
B5: Labour productivity (dairy livestock) | C5: With DATs | D5: l milk/h | E5: ='Parcel 1 with DATSs'!G251/SUM('Parcel 1 with DATSs'!G194:G218) -> 0 | F5: total production / hours of labour employed
B6: Labour productivity (meat livestock) | C6: With DATs | D6: kg meat/h | E6: ='Parcel 1 with DATSs'!G252/SUM('Parcel 1 with DATSs'!G194:G218) -> 0 | F6: total production / hours of labour employed
B7: Labour productivity (aquaculture) | C7: With DATs | D7: pieces/h | E7: ='Parcel 1 with DATSs'!G254/SUM('Parcel 1 with DATSs'!G194:G218) -> 0 | F7: total production / hours of labour employed
B8: Labour productivity (apiculture) | C8: With DATs | D8: kg honey/h | E8: ='Parcel 1 with DATSs'!G255/SUM('Parcel 1 with DATSs'!G194:G218) -> 0 | F8: total production / hours of labour employed
B9: Labour productivity (silos) | C9: With DATs | D9: t/h | E9: ='Parcel 1 with DATSs'!G256/SUM('Parcel 1 with DATSs'!G194:G218) -> 0
B10: Milk productivity | C10: With DATs | D10: l milk/cow/day | E10: ='Parcel 1 with DATSs'!G251/'Parcel 1 with DATSs'!E17/365 -> #DIV/0! | F10: total milk production / total number of cows
B11: Meat productivity | C11: With DATs | D11: kg meat/animal/day | E11: ='Parcel 1 with DATSs'!G252/'Parcel 1 with DATSs'!E17/365 -> #DIV/0! | F11: total production / animals
B12: Bees productivity | C12: With DATs | D12: kg honey/beehive | E12: ='Parcel 1 with DATSs'!G255/'Parcel 1 with DATSs'!E19 -> #DIV/0! | F12: total production / beehives
B13: Oyster productivity | C13: With DATs | D13: number of oysters/m2 | E13: ='Parcel 1 with DATSs'!G254/'Parcel 1 with DATSs'!E20 -> #DIV/0! | F13: production / area used
A15: Economic - EFFICIENCY
B16: INDICATOR | C16: SCENARIO | D16: UoM | E16: TOTAL | F16: FORMULAS
B17: Rate of time for quality analysis | C17: With DATs | D17: % | E17: =('Parcel 1 with DATSs'!G202/SUM('Parcel 1 with DATSs'!G201:G204))*100 -> #DIV/0! | F17: (hours spent for quality analysis / total number of working hours) *100
B18: Rate of on-time fulfilled orders | C18: With DATs | D18: % | E18: =('Parcel 1 with DATSs'!G222/'Parcel 1 with DATSs'!G223)*100 -> #DIV/0! | F18: (number of on-time fulfilled orders / number of orders received) * 100
B19: Number of wrong orders | C19: With DATs | D19: n | E19: ='Parcel 1 with DATSs'!G224 -> 0 | F19: Number of wrong orders
A21: PRODUCT QUALITY
A22: INPUT | B22: INDICATOR | C22: SCENARIO | D22: UoM | E22: TOTAL | F22: FORMULAS
B23: Intrinsic product quality | C23: With DATs
B24: Protein % DRY MATTER | C24: With DATs | D24: % | E24: ='Parcel 1 with DATSs'!G226 -> 12.5
B25: Humidity | C25: With DATs | D25: % | E25: ='Parcel 1 with DATSs'!G227 -> 14.1
B26: Test Weight | C26: With DATs | D26: kg/hl | E26: ='Parcel 1 with DATSs'!G228 -> 76.6
A28: ENVIRONMENTAL KPIs
A29: INPUT | B29: INDICATOR | C29: SCENARIO | D29: UoM | E29: TOTAL | F29: Formula
